Workbook

Sheet 人物卡
B1: 电脑推荐使用excel2010及以后版本或WPS打开本卡，使用横轴滚动条可以看见更多东西，手机推荐使用WPS
B2: 调查员信息 | S2: 年龄补正： | V2: =附表!D37 -> 教育进步*1 | AA2: 属性 | AC2: 已用点数: | AG2: =U3+U5+U7+AA3+AA5+AA7+AG3+AG5+AG7 -> 605 | AL2: #VALUE! | AU2: 您的角色可能（只是可能！）
B3: 姓名 | E3: 艾迪安·多雷 | S3: 力量 STR | U3: 90 | W3: =INT(U3/2) -> 45 | Y3: 敏捷 DEX | AA3: 40 | AC3: =INT(AA3/2) -> 20 | AE3: 意志 POW | AG3: 75 | AI3: =INT(AG3/2) -> 37 | AU3: =IF(U3=0,"",IF(U3<=15,"虚弱，孱弱",IF(U3<=40,"力量弱小",IF(U3<=60,"有正常人的力量",IF(U3<=80,"超乎常人的力量",IF(U3<100,"超乎超乎常人的力量")))))) -> 超乎超乎常人的力量 | BC3: =IF(AA3=0,"",IF(AA3<=20,"很不灵活",IF(AA3<=40,"不是很灵活",IF(AA3<=60,"普通人水平",IF(AA3<=80,"是一位运动健将",IF(AA3<100,"高速而灵活,可以达成超凡的技艺")))))) -> 不是很灵活 | BK3: =IF(AG3=0,"",IF(AG3<=20,"尔不过玩物",IF(AG3<=40,"痴愚盲目",IF(AG3<=60,"如常人一般会有一定自制力",IF(AG3<=80,"我心如铁，心坚石穿",IF(AG3<100,"泰山崩于面而色不变",IF(AG3<140,"钢铁之心，还能看见鬼","你怕是个假人吧"))))))) -> 我心如铁，心坚石穿
B4: 玩家 | E4: Kanra | J4: 时代 | M4: 1920s | W4: =INT(U3/5) -> 18 | AC4: =INT(AA3/5) -> 8 | AI4: =INT(AG3/5) -> 15
B5: 职业 | E5: 探险家 | J5: 职业序号 | M5: 218 | S5: 体质 CON | U5: 50 | W5: =INT(U5/2) -> 25 | Y5: 外貌 APP | AA5: 65 | AC5: =INT(AA5/2) -> 32 | AE5: 教育 知识 | AG5: 65 | AI5: =INT(AG5/2) -> 32 | AU5: =IF(U5=0,"",IF(U5<=20,"常年患病在身",IF(U5<=40,"体弱多病",IF(U5<=60,"不会生什么大毛病",IF(U5<=80,"健硕，浑身湿透也不会感冒",IF(U5<100,"身体素质极好，精神抖擞")))))) -> 不会生什么大毛病 | BC5: =IF(AA5=0,"",IF(AA5<=20,"用脸就能恐惧敌人。。或队友",IF(AA5<=40,"有些难看",IF(AA5<=60,"人群之中谁也不会看你一眼之后就忘不掉你容颜",IF(AA5<=80,"五官端正，仪表堂堂",IF(AA5<100,"沉鱼落雁，闭月羞花")))))) -> 五官端正，仪表堂堂 | BK5: =IF(AG5=0,"",IF(AG5<=20,"目不识丁",IF(AG5<=40,"小学毕业",IF(AG5<=60,"高中毕业",IF(AG5<=80,"是重点大学的学生，或是普通大学的研究生",IF(AG5<100,"饱读诗书，满腹经纶")))))) -> 是重点大学的学生，或是普通大学的研究生
B6: 年龄 | E6: 31 | J6: 性别 | M6: 男 | W6: =INT(U5/5) -> 10 | AC6: =INT(AA5/5) -> 13 | AI6: =INT(AG5/5) -> 13
B7: 住地 | E7: 法国 里昂 | J7: 故乡 | M7: 法国 格勒诺布尔 | S7: 体型 SIZ | U7: 70 | W7: =INT(U7/2) -> 35 | Y7: 智力 灵感 | AA7: 80 | AC7: =INT(AA7/2) -> 40 | AE7: 幸运 Luck | AG7: 70 | AI7: =INT(AG7/2) -> 35 | AU7: =IF(U7=0,"",IF(U7<=20,"孩童，身短体瘦",IF(U7<=40,"乙女身材",IF(U7<=60,"普遍身高155-175",IF(U7<=80,"不是高就是胖",IF(U7<=100,"大号的人",IF(U7<150,"听说你正在申请身高世界记录？",IF(U7<180,"你可能是一头牛",IF(U7<200,"你已经是历史上最重的人类了","过分了喂！"))))))))) -> 不是高就是胖 | BC7: =IF(AA7=0,"",IF(AA7<=20,"脑子是个好东西，可惜。。。",IF(AA7<=40,"宛如智障",IF(AA7<=60,"有着普通人的灵光一现",IF(AA7<=80,"可以自主进行发明创造",IF(AA7<100,"天才级水准")))))) -> 可以自主进行发明创造 | BK7: =IF(AG7=0,"",IF(AG7<=20,"克夫克妻",IF(AG7<=40,"霉运连连",IF(AG7<=60,"命格平庸",IF(AG7<=80,"在马路边捡到100块",IF(AG7<100,"被幸运女神所眷顾")))))) -> 在马路边捡到100块
B8: 现时间 | G8: 1980 | J8: 1月 | L8: 1日 | N8: 0：00 | W8: =INT(U7/5) -> 14 | AC8: =INT(AA7/5) -> 16 | AI8: =INT(AG7/5) -> 14
B9: =IF(F9=0,"","任意特长数：") | F9: =INDEX(本职技能!$A$2:$HX$69,MATCH("任意特长",本职技能!$A$2:$A$75,0),MATCH($M$5,本职技能!$A$1:$HX$1,0)) -> 0 | K9: =INDEX(本职技能!$A$2:$HX$69,MATCH("☆",本职技能!$A$2:$A$75,0),MATCH($M$5,本职技能!$A$1:$HX$1,0)) -> 0 | T9: =INDEX(本职技能!$A$2:$HX$69,MATCH("⊙",本职技能!$A$2:$A$75,0),MATCH($M$5,本职技能!$A$1:$HX$1,0)) -> 0 | AC9: =INDEX(本职技能!$A$2:$HX$69,MATCH("☯",本职技能!$A$2:$A$75,0),MATCH($M$5,本职技能!$A$1:$HX$1,0)) -> 0 | AL9: =INDEX(本职技能!$A$2:$HX$69,MATCH("※",本职技能!$A$2:$A$75,0),MATCH($M$5,本职技能!$A$1:$HX$1,0)) -> 0
B10: 生命值 Hit Points | E10: =G10 -> 12 | G10: =INT((U5+U7)/10) -> 12 | I10: 状态: | K10: 理智 Sanity | N10: =AG3 -> 75 | P10: =99-R27 -> 99 | R10: 状态: | T10: 魔法 Magic Points | W10: =Y10 -> 15 | Y10: =INT(AG3/5) -> 15 | AA10: 每h恢复 | AC10: 移动力 MOV | AF10: =AI11+8 -> 8 | AI10: 调整值 | AK10: 护甲 Armor | AN10: =IF($AN12=0,"0",VLOOKUP($AN12,'防具表 载具表'!B2:J82,2,FALSE)) -> 0 | AR10: 覆盖部位 | AT10: =IF($AN12=0,"",VLOOKUP($AN12,'防具表 载具表'!B2:I101,4,FALSE)) -> 0
I11: 健康 | R11: 清醒 | AA11: =IF(AG3="","",INT(AG3/100+1)) -> 1 | AI11: =附表!C9 -> 0
B12: 重伤值: | D12: =CEILING(G10/2,1) -> 6 | F12: 临时生命值： | I12: 0 | K12: 今日损失 : | N12: 0 | P12: 剩余： | R12: =N10-N12 -> 75 | T12: 使用过的魔法： | AC12: 移动方式 | AE12: 步式 | AG12: 护甲减值 | AI12: 关 | AK12: 护甲类型 : | AN12: 请看【防具表】
B13: =IF(M5=0," ","["&LOOKUP(M5,职业列表!A2:A232,职业列表!B2:B232)&"]的本职技能："&LOOKUP(M5,职业列表!A2:A232,职业列表!G2:G232)) -> [探险家]的本职技能：人类学，考古学，估价，科学（生物学），攀爬，急救，射击（手枪、来复枪），格斗（斗殴），博物学，导航，其他语言（任意），驾驶（小艇，船，热气球），骑术，潜行，侦查，游泳，追踪
B14: 技能表
B15: 成功标 | D15: 本职 | F15: 技能名称 | J15: 初始 | L15: 成长 | N15: 职业 | P15: 兴趣 | R15: 成功率 普通/困难/极难 | X15: 成功标 | Z15: 本职 | AB15: 技能名称 | AF15: 初始 | AH15: 成长 | AJ15: 职业 | AL15: 兴趣 | AN15: 成功率 普通/困难/极难
B16: ☐ | D16: =IF(ISTEXT(IFERROR(VLOOKUP(人物卡!F16,人物卡!BJ18:BR22,1,FALSE),IFERROR(VLOOKUP(人物卡!F16,人物卡!BA18:BC22,1,FALSE),0))),"★",INDEX(本职技能!$A$2:$HX$76,MATCH(人物卡!F16,本职技能!$A$2:$A$75,0),MATCH(人物卡!$M$5,本职技能!$A$1:$HX$1,0))) -> 0 | F16: 会计 | J16: 5 | R16: =SUM(J16:P16) -> 5 | T16: =INT(R16/2) -> 2 | V16: =INT(R16/5) -> 1 | X16: ☐ | Z16: =IF(ISTEXT(IFERROR(VLOOKUP(人物卡!AB16,人物卡!BJ18:BR22,1,FALSE),IFERROR(VLOOKUP(人物卡!AB16,人物卡!BA18:BC22,1,FALSE),0))),"★",INDEX(本职技能!$A$2:$HX$76,MATCH(人物卡!AB16,本职技能!$A$2:$A$75,0),MATCH(人物卡!$M$5,本职技能!$A$1:$HX$1,0))) -> 0 | AB16: 法律 | AF16: 5 | AN16: =SUM(AF16:AL16) -> 5 | AP16: =INT(AN16/2) -> 2 | AR16: =INT(AN16/5) -> 1
B17: ☐ | D17: =IF(ISTEXT(IFERROR(VLOOKUP(人物卡!F17,人物卡!BJ18:BR22,1,FALSE),IFERROR(VLOOKUP(人物卡!F17,人物卡!BA18:BC22,1,FALSE),0))),"★",INDEX(本职技能!$A$2:$HX$76,MATCH(人物卡!F17,本职技能!$A$2:$A$75,0),MATCH(人物卡!$M$5,本职技能!$A$1:$HX$1,0))) -> ★ | F17: 人类学 | J17: 1 | R17: =SUM(J17:P17) -> 1 | T17: =INT(R17/2) -> 0 | V17: =INT(R17/5) -> 0 | X17: ☐ | Z17: =IF(ISTEXT(IFERROR(VLOOKUP(人物卡!AB17,人物卡!BJ18:BR22,1,FALSE),IFERROR(VLOOKUP(人物卡!AB17,人物卡!BA18:BC22,1,FALSE),0))),"★",INDEX(本职技能!$A$2:$HX$76,MATCH(人物卡!AB17,本职技能!$A$2:$A$75,0),MATCH(人物卡!$M$5,本职技能!$A$1:$HX$1,0))) -> 0 | AB17: 图书馆使用 | AF17: 20 | AN17: =SUM(AF17:AL17) -> 20 | AP17: =INT(AN17/2) -> 10 | AR17: =INT(AN17/5) -> 4 | AU17: 你现在有这么多 | BA17: 那么你分配到了哪里?
B18: ☐ | D18: =IF(ISTEXT(IFERROR(VLOOKUP(人物卡!F18,人物卡!BJ18:BR22,1,FALSE),IFERROR(VLOOKUP(人物卡!F18,人物卡!BA18:BC22,1,FALSE),0))),"★",INDEX(本职技能!$A$2:$HX$76,MATCH(人物卡!F18,本职技能!$A$2:$A$75,0),MATCH(人物卡!$M$5,本职技能!$A$1:$HX$1,0))) -> ★ | F18: 估价 | J18: 5 | R18: =SUM(J18:P18) -> 5 | T18: =INT(R18/2) -> 2 | V18: =INT(R18/5) -> 1 | X18: ☐ | Z18: =IF(ISTEXT(IFERROR(VLOOKUP(人物卡!AB18,人物卡!BJ18:BR22,1,FALSE),IFERROR(VLOOKUP(人物卡!AB18,人物卡!BA18:BC22,1,FALSE),0))),"★",INDEX(本职技能!$A$2:$HX$76,MATCH(人物卡!AB18,本职技能!$A$2:$A$75,0),MATCH(人物卡!$M$5,本职技能!$A$1:$HX$1,0))) -> 0 | AB18: 聆听 | AF18: 20 | AL18: 29 | AN18: =SUM(AF18:AL18) -> 49 | AP18: =INT(AN18/2) -> 24 | AR18: =INT(AN18/5) -> 9 | AU18: 任意特长
B19: ☐ | D19: =IF(ISTEXT(IFERROR(VLOOKUP(人物卡!F19,人物卡!BJ18:BR22,1,FALSE),IFERROR(VLOOKUP(人物卡!F19,人物卡!BA18:BC22,1,FALSE),0))),"★",INDEX(本职技能!$A$2:$HX$76,MATCH(人物卡!F19,本职技能!$A$2:$A$75,0),MATCH(人物卡!$M$5,本职技能!$A$1:$HX$1,0))) -> ★ | F19: 考古学 | J19: 1 | R19: =SUM(J19:P19) -> 1 | T19: =INT(R19/2) -> 0 | V19: =INT(R19/5) -> 0 | X19: ☐ | Z19: =IF(ISTEXT(IFERROR(VLOOKUP(人物卡!AB19,人物卡!BJ18:BR22,1,FALSE),IFERROR(VLOOKUP(人物卡!AB19,人物卡!BA18:BC22,1,FALSE),0))),"★",INDEX(本职技能!$A$2:$HX$76,MATCH(人物卡!AB19,本职技能!$A$2:$A$75,0),MATCH(人物卡!$M$5,本职技能!$A$1:$HX$1,0))) -> 0 | AB19: 锁匠 | AF19: 1 | AN19: =SUM(AF19:AL19) -> 1 | AP19: =INT(AN19/2) -> 0 | AR19: =INT(AN19/5) -> 0 | AU19: =附表!AD25 -> 无
B20: ☐ | D20: =IF(ISTEXT(IFERROR(VLOOKUP(人物卡!F20,人物卡!BJ18:BR22,1,FALSE),IFERROR(VLOOKUP(人物卡!F20,人物卡!BA18:BC22,1,FALSE),0))),"★",INDEX(本职技能!$A$2:$HX$76,MATCH(人物卡!F20,本职技能!$A$2:$A$75,0),MATCH(人物卡!$M$5,本职技能!$A$1:$HX$1,0))) -> 0 | F20: 技艺① | J20: =IF(ISBLANK(AU26),5,IF(H20=AU26,BA26,5)) -> 5 | R20: =J20+L20+N20+P20 -> 5 | T20: =INT(R20/2) -> 2 | V20: =INT(R20/5) -> 1 | X20: ☐ | Z20: =IF(ISTEXT(IFERROR(VLOOKUP(人物卡!AB20,人物卡!BJ18:BR22,1,FALSE),IFERROR(VLOOKUP(人物卡!AB20,人物卡!BA18:BC22,1,FALSE),0))),"★",INDEX(本职技能!$A$2:$HX$76,MATCH(人物卡!AB20,本职技能!$A$2:$A$75,0),MATCH(人物卡!$M$5,本职技能!$A$1:$HX$1,0))) -> 0 | AB20: 机械维修 | AF20: 10 | AN20: =SUM(AF20:AL20) -> 10 | AP20: =INT(AN20/2) -> 5 | AR20: =INT(AN20/5) -> 2
B21: ☐ | D21: =IF(ISTEXT(IFERROR(VLOOKUP(人物卡!F21,人物卡!BJ18:BR22,1,FALSE),IFERROR(VLOOKUP(人物卡!F21,人物卡!BA18:BC22,1,FALSE),0))),"★",INDEX(本职技能!$A$2:$HX$76,MATCH(人物卡!F21,本职技能!$A$2:$A$75,0),MATCH(人物卡!$M$5,本职技能!$A$1:$HX$1,0))) -> 0 | F21: 技艺② | J21: =IF(ISBLANK(AU26),5,IF(H21=AU26,BA26,5)) -> 5 | R21: =P21+N21+L21+J21 -> 5 | T21: =INT(R21/2) -> 2 | V21: =INT(R21/5) -> 1 | X21: ☐ | Z21: =IF(ISTEXT(IFERROR(VLOOKUP(人物卡!AB21,人物卡!BJ18:BR22,1,FALSE),IFERROR(VLOOKUP(人物卡!AB21,人物卡!BA18:BC22,1,FALSE),0))),"★",INDEX(本职技能!$A$2:$HX$76,MATCH(人物卡!AB21,本职技能!$A$2:$A$75,0),MATCH(人物卡!$M$5,本职技能!$A$1:$HX$1,0))) -> 0 | AB21: 医学 | AF21: 1 | AN21: =SUM(AF21:AL21) -> 1 | AP21: =INT(AN21/2) -> 0 | AR21: =INT(AN21/5) -> 0
B22: ☐ | D22: =IF(ISTEXT(IFERROR(VLOOKUP(人物卡!F22,人物卡!BJ18:BR22,1,FALSE),IFERROR(VLOOKUP(人物卡!F22,人物卡!BA18:BC22,1,FALSE),0))),"★",INDEX(本职技能!$A$2:$HX$76,MATCH(人物卡!F22,本职技能!$A$2:$A$75,0),MATCH(人物卡!$M$5,本职技能!$A$1:$HX$1,0))) -> 0 | F22: 技艺③ | J22: =IF(ISBLANK(AU26),5,IF(H22=AU26,BA26,5)) -> 5 | R22: =P22+N22+L22+J22 -> 5 | T22: =INT(R22/2) -> 2 | V22: =INT(R22/5) -> 1 | X22: ☐ | Z22: =IF(ISTEXT(IFERROR(VLOOKUP(人物卡!AB22,人物卡!BJ18:BR22,1,FALSE),IFERROR(VLOOKUP(人物卡!AB22,人物卡!BA18:BC22,1,FALSE),0))),"★",INDEX(本职技能!$A$2:$HX$76,MATCH(人物卡!AB22,本职技能!$A$2:$A$75,0),MATCH(人物卡!$M$5,本职技能!$A$1:$HX$1,0))) -> ★ | AB22: 博物学 | AF22: 10 | AJ22: 40 | AN22: =SUM(AF22:AL22) -> 50 | AP22: =INT(AN22/2) -> 25 | AR22: =INT(AN22/5) -> 10
B23: ☐ | D23: =IF(ISTEXT(IFERROR(VLOOKUP(人物卡!F23,人物卡!BJ18:BR22,1,FALSE),IFERROR(VLOOKUP(人物卡!F23,人物卡!BA18:BC22,1,FALSE),0))),"★",INDEX(本职技能!$A$2:$HX$76,MATCH(人物卡!F23,本职技能!$A$2:$A$75,0),MATCH(人物卡!$M$5,本职技能!$A$1:$HX$1,0))) -> 0 | F23: 取悦 | J23: 15 | N23: 5 | P23: 29 | R23: =SUM(J23:P23) -> 49 | T23: =INT(R23/2) -> 24 | V23: =INT(R23/5) -> 9 | X23: ☐ | Z23: =IF(ISTEXT(IFERROR(VLOOKUP(人物卡!AB23,人物卡!BJ18:BR22,1,FALSE),IFERROR(VLOOKUP(人物卡!AB23,人物卡!BA18:BC22,1,FALSE),0))),"★",INDEX(本职技能!$A$2:$HX$76,MATCH(人物卡!AB23,本职技能!$A$2:$A$75,0),MATCH(人物卡!$M$5,本职技能!$A$1:$HX$1,0))) -> ★ | AB23: 导航 | AF23: 10 | AN23: =SUM(AF23:AL23) -> 10 | AP23: =INT(AN23/2) -> 5 | AR23: =INT(AN23/5) -> 2 | AU23: 请将你选择的任意特长写在上方栏内，这样既方便你写卡又方便KP审卡
B24: ☐ | D24: =IF(ISTEXT(IFERROR(VLOOKUP(人物卡!F24,人物卡!BJ18:BR22,1,FALSE),IFERROR(VLOOKUP(人物卡!F24,人物卡!BA18:BC22,1,FALSE),0))),"★",INDEX(本职技能!$A$2:$HX$76,MATCH(人物卡!F24,本职技能!$A$2:$A$75,0),MATCH(人物卡!$M$5,本职技能!$A$1:$HX$1,0))) -> ★ | F24: 攀爬 | J24: 20 | R24: =SUM(J24:P24) -> 20 | T24: =INT(R24/2) -> 10 | V24: =INT(R24/5) -> 4 | X24: ☐ | Z24: =IF(ISTEXT(IFERROR(VLOOKUP(人物卡!AB24,人物卡!BJ18:BR22,1,FALSE),IFERROR(VLOOKUP(人物卡!AB24,人物卡!BA18:BC22,1,FALSE),0))),"★",INDEX(本职技能!$A$2:$HX$76,MATCH(人物卡!AB24,本职技能!$A$2:$A$75,0),MATCH(人物卡!$M$5,本职技能!$A$1:$HX$1,0))) -> 0 | AB24: 神秘学 | AF24: 5 | AN24: =SUM(AF24:AL24) -> 5 | AP24: =INT(AN24/2) -> 2 | AR24: =INT(AN24/5) -> 1 | AU24: 自定义子技能 | BC24: 自定义经历包 | BK24: 自定义状态
B25: ☐ | D25: =IF(ISTEXT(IFERROR(VLOOKUP(人物卡!F25,人物卡!BJ18:BR22,1,FALSE),IFERROR(VLOOKUP(人物卡!F25,人物卡!BA18:BC22,1,FALSE),0))),"★",INDEX(本职技能!$A$2:$HX$76,MATCH(人物卡!F25,本职技能!$A$2:$A$75,0),MATCH(人物卡!$M$5,本职技能!$A$1:$HX$1,0))) -> 0 | F25: 计算机使用 Ω | J25: 5 | R25: =SUM(J25:P25) -> 5 | T25: =INT(R25/2) -> 2 | V25: =INT(R25/5) -> 1 | X25: ☐ | Z25: =IF(ISTEXT(IFERROR(VLOOKUP(人物卡!AB25,人物卡!BJ18:BR22,1,FALSE),IFERROR(VLOOKUP(人物卡!AB25,人物卡!BA18:BC22,1,FALSE),0))),"★",INDEX(本职技能!$A$2:$HX$76,MATCH(人物卡!AB25,本职技能!$A$2:$A$75,0),MATCH(人物卡!$M$5,本职技能!$A$1:$HX$1,0))) -> 0 | AB25: 操作重型机械 | AF25: 1 | AN25: =SUM(AF25:AL25) -> 1 | AP25: =INT(AN25/2) -> 0 | AR25: =INT(AN25/5) -> 0 | AU25: 技艺技能名称 | BA25: 基础值 | BC25: 经历包名称 | BK25: 状态名称(例:生病、精神分裂)
B26: —— | D26: ★ | F26: 信用评级 | J26: 0 | N26: 50 | R26: =SUM(J26:P26) -> 50 | T26: =INT(R26/2) -> 25 | V26: =INT(R26/5) -> 10 | X26: ☐ | Z26: =IF(ISTEXT(IFERROR(VLOOKUP(人物卡!AB26,人物卡!BJ18:BR22,1,FALSE),IFERROR(VLOOKUP(人物卡!AB26,人物卡!BA18:BC22,1,FALSE),0))),"★",INDEX(本职技能!$A$2:$HX$76,MATCH(人物卡!AB26,本职技能!$A$2:$A$75,0),MATCH(人物卡!$M$5,本职技能!$A$1:$HX$1,0))) -> 0 | AB26: 说服 | AF26: 10 | AL26: 39 | AN26: =SUM(AF26:AL26) -> 49 | AP26: =INT(AN26/2) -> 24 | AR26: =INT(AN26/5) -> 9
B27: —— | D27: =IF(ISTEXT(IFERROR(VLOOKUP(F27,人物卡!BJ18:BR22,1,FALSE),IFERROR(VLOOKUP(F27,人物卡!BA18:BC22,1,FALSE),0))),"★",INDEX(本职技能!$A$2:$HX$76,MATCH(F27,本职技能!$A$2:$A$75,0),MATCH(人物卡!$M$5,本职技能!$A$1:$HX$1,0))) -> 0 | F27: 克苏鲁神话 | J27: 0 | N27: —— | P27: —— | R27: =SUM(J27:P27) -> 0 | T27: =INT(R27/2) -> 0 | V27: =INT(R27/5) -> 0 | X27: ☐ | Z27: =IF(ISTEXT(IFERROR(VLOOKUP(人物卡!AB27,人物卡!BJ18:BR22,1,FALSE),IFERROR(VLOOKUP(人物卡!AB27,人物卡!BA18:BC22,1,FALSE),0))),"★",INDEX(本职技能!$A$2:$HX$76,MATCH(人物卡!AB27,本职技能!$A$2:$A$75,0),MATCH(人物卡!$M$5,本职技能!$A$1:$HX$1,0))) -> 艇船球 | AB27: 驾驶： | AF27: =IF(ISBLANK(AU32),1,IF(AD27=AU32,BA32,1)) -> 1 | AN27: =SUM(AF27:AL27) -> 1 | AP27: =INT(AN27/2) -> 0 | AR27: =INT(AN27/5) -> 0 | AU27: 格斗技能名称 | BA27: 基础值 | BC27: san值减少 | BG27: 技能增长 | BK27: 身体状态 | BO27: 精神状态
B28: ☐ | D28: =IF(ISTEXT(IFERROR(VLOOKUP(人物卡!F28,人物卡!BJ18:BR22,1,FALSE),IFERROR(VLOOKUP(人物卡!F28,人物卡!BA18:BC22,1,FALSE),0))),"★",INDEX(本职技能!$A$2:$HX$76,MATCH(人物卡!F28,本职技能!$A$2:$A$75,0),MATCH(人物卡!$M$5,本职技能!$A$1:$HX$1,0))) -> 0 | F28: 乔装 | J28: 5 | R28: =SUM(J28:P28) -> 5 | T28: =INT(R28/2) -> 2 | V28: =INT(R28/5) -> 1 | X28: ☐ | Z28: =IF(ISTEXT(IFERROR(VLOOKUP(人物卡!AB28,人物卡!BJ18:BR22,1,FALSE),IFERROR(VLOOKUP(人物卡!AB28,人物卡!BA18:BC22,1,FALSE),0))),"★",INDEX(本职技能!$A$2:$HX$76,MATCH(人物卡!AB28,本职技能!$A$2:$A$75,0),MATCH(人物卡!$M$5,本职技能!$A$1:$HX$1,0))) -> 0 | AB28: 精神分析 | AF28: 1 | AN28: =SUM(AF28:AL28) -> 1 | AP28: =INT(AN28/2) -> 0 | AR28: =INT(AN28/5) -> 0
B29: ☐ | D29: =IF(ISTEXT(IFERROR(VLOOKUP(人物卡!F29,人物卡!BJ18:BR22,1,FALSE),IFERROR(VLOOKUP(人物卡!F29,人物卡!BA18:BC22,1,FALSE),0))),"★",INDEX(本职技能!$A$2:$HX$76,MATCH(人物卡!F29,本职技能!$A$2:$A$75,0),MATCH(人物卡!$M$5,本职技能!$A$1:$HX$1,0))) -> 0 | F29: 闪避 | J29: =INT(附表!J14/2) -> 20 | P29: 24 | R29: =SUM(J29:P29) -> 44 | T29: =INT(R29/2) -> 22 | V29: =INT(R29/5) -> 8 | X29: ☐ | Z29: =IF(ISTEXT(IFERROR(VLOOKUP(人物卡!AB29,人物卡!BJ18:BR22,1,FALSE),IFERROR(VLOOKUP(人物卡!AB29,人物卡!BA18:BC22,1,FALSE),0))),"★",INDEX(本职技能!$A$2:$HX$76,MATCH(人物卡!AB29,本职技能!$A$2:$A$75,0),MATCH(人物卡!$M$5,本职技能!$A$1:$HX$1,0))) -> 0 | AB29: 心理学 | AF29: 10 | AL29: 39 | AN29: =SUM(AF29:AL29) -> 49 | AP29: =INT(AN29/2) -> 24 | AR29: =INT(AN29/5) -> 9 | AU29: 射击技能名称 | BA29: 基础值 | BC29: 备注
B30: ☐ | D30: =IF(ISTEXT(IFERROR(VLOOKUP(人物卡!F30,人物卡!BJ18:BR22,1,FALSE),IFERROR(VLOOKUP(人物卡!F30,人物卡!BA18:BC22,1,FALSE),0))),"★",INDEX(本职技能!$A$2:$HX$76,MATCH(人物卡!F30,本职技能!$A$2:$A$75,0),MATCH(人物卡!$M$5,本职技能!$A$1:$HX$1,0))) -> 0 | F30: 汽车驾驶 | J30: 20 | R30: =SUM(J30:P30) -> 20 | T30: =INT(R30/2) -> 10 | V30: =INT(R30/5) -> 4 | X30: ☐ | Z30: =IF(ISTEXT(IFERROR(VLOOKUP(人物卡!AB30,人物卡!BJ18:BR22,1,FALSE),IFERROR(VLOOKUP(人物卡!AB30,人物卡!BA18:BC22,1,FALSE),0))),"★",INDEX(本职技能!$A$2:$HX$76,MATCH(人物卡!AB30,本职技能!$A$2:$A$75,0),MATCH(人物卡!$M$5,本职技能!$A$1:$HX$1,0))) -> ★ | AB30: 骑术 | AF30: 5 | AN30: =SUM(AF30:AL30) -> 5 | AP30: =INT(AN30/2) -> 2 | AR30: =INT(AN30/5) -> 1
B31: ☐ | D31: =IF(ISTEXT(IFERROR(VLOOKUP(人物卡!F31,人物卡!BJ18:BR22,1,FALSE),IFERROR(VLOOKUP(人物卡!F31,人物卡!BA18:BC22,1,FALSE),0))),"★",INDEX(本职技能!$A$2:$HX$76,MATCH(人物卡!F31,本职技能!$A$2:$A$75,0),MATCH(人物卡!$M$5,本职技能!$A$1:$HX$1,0))) -> 0 | F31: 电气维修 | J31: 10 | R31: =SUM(J31:P31) -> 10 | T31: =INT(R31/2) -> 5 | V31: =INT(R31/5) -> 2 | X31: ☐ | Z31: =IF(ISTEXT(IFERROR(VLOOKUP(人物卡!AB31,人物卡!BJ18:BR22,1,FALSE),IFERROR(VLOOKUP(人物卡!AB31,人物卡!BA18:BC22,1,FALSE),0))),"★",INDEX(本职技能!$A$2:$HX$76,MATCH(人物卡!AB31,本职技能!$A$2:$A$75,0),MATCH(人物卡!$M$5,本职技能!$A$1:$HX$1,0))) -> 生物 | AB31: 科学① | AF31: =IF(ISBLANK(AU34),IF(AD31="数学",10,1),IF(AD31=AU34,BA34,1)) -> 1 | AN31: =AF31+AH31+AL31+AJ31 -> 1 | AP31: =INT(AN31/2) -> 0 | AR31: =INT(AN31/5) -> 0 | AU31: 驾驶技能名称 | BA31: 基础值
B32: ☐ | D32: =IF(ISTEXT(IFERROR(VLOOKUP(人物卡!F32,人物卡!BJ18:BR22,1,FALSE),IFERROR(VLOOKUP(人物卡!F32,人物卡!BA18:BC22,1,FALSE),0))),"★",INDEX(本职技能!$A$2:$HX$76,MATCH(人物卡!F32,本职技能!$A$2:$A$75,0),MATCH(人物卡!$M$5,本职技能!$A$1:$HX$1,0))) -> 0 | F32: 电子学 Ω | J32: 1 | R32: =SUM(J32:P32) -> 1 | T32: =INT(R32/2) -> 0 | V32: =INT(R32/5) -> 0 | X32: ☐ | Z32: =IF(ISTEXT(IFERROR(VLOOKUP(人物卡!AB32,人物卡!BJ18:BR22,1,FALSE),IFERROR(VLOOKUP(人物卡!AB32,人物卡!BA18:BC22,1,FALSE),0))),"★",INDEX(本职技能!$A$2:$HX$76,MATCH(人物卡!AB32,本职技能!$A$2:$A$75,0),MATCH(人物卡!$M$5,本职技能!$A$1:$HX$1,0))) -> 0 | AB32: 科学② | AF32: =IF(ISBLANK(AU34),IF(AD32="数学",10,1),IF(AD32=AU34,BA34,1)) -> 1 | AN32: =AL32+AJ32+AF32+AH32 -> 1 | AP32: =INT(AN32/2) -> 0 | AR32: =INT(AN32/5) -> 0
B33: ☐ | D33: =IF(ISTEXT(IFERROR(VLOOKUP(人物卡!F33,人物卡!BJ18:BR22,1,FALSE),IFERROR(VLOOKUP(人物卡!F33,人物卡!BA18:BC22,1,FALSE),0))),"★",INDEX(本职技能!$A$2:$HX$76,MATCH(人物卡!F33,本职技能!$A$2:$A$75,0),MATCH(人物卡!$M$5,本职技能!$A$1:$HX$1,0))) -> 0 | F33: 话术 | J33: 5 | R33: =SUM(J33:P33) -> 5 | T33: =INT(R33/2) -> 2 | V33: =INT(R33/5) -> 1 | X33: ☐ | Z33: =IF(ISTEXT(IFERROR(VLOOKUP(人物卡!AB33,人物卡!BJ18:BR22,1,FALSE),IFERROR(VLOOKUP(人物卡!AB33,人物卡!BA18:BC22,1,FALSE),0))),"★",INDEX(本职技能!$A$2:$HX$76,MATCH(人物卡!AB33,本职技能!$A$2:$A$75,0),MATCH(人物卡!$M$5,本职技能!$A$1:$HX$1,0))) -> 0 | AB33: 科学③ | AF33: =IF(ISBLANK(AU34),IF(AD33="数学",10,1),IF(AD33=AU34,BA34,1)) -> 1 | AN33: =AF33+AH33+AJ33+AL33 -> 1 | AP33: =INT(AN33/2) -> 0 | AR33: =INT(AN33/5) -> 0 | AU33: 科学技能名称 | BA33: 基础值
B34: ☐ | D34: =IF(ISTEXT(IFERROR(VLOOKUP(人物卡!F34,人物卡!BJ18:BR22,1,FALSE),IFERROR(VLOOKUP(人物卡!F34,人物卡!BA18:BC22,1,FALSE),0))),"★",INDEX(本职技能!$A$2:$HX$76,MATCH(人物卡!F34,本职技能!$A$2:$A$75,0),MATCH(人物卡!$M$5,本职技能!$A$1:$HX$1,0))) -> ★ | F34: 格斗： | H34: 斗殴 | J34: 25 | N34: 40 | R34: =SUM(J34:P34) -> 65 | T34: =INT(R34/2) -> 32 | V34: =INT(R34/5) -> 13 | X34: ☐ | Z34: =IF(ISTEXT(IFERROR(VLOOKUP(人物卡!AB34,人物卡!BJ18:BR22,1,FALSE),IFERROR(VLOOKUP(人物卡!AB34,人物卡!BA18:BC22,1,FALSE),0))),"★",INDEX(本职技能!$A$2:$HX$76,MATCH(人物卡!AB34,本职技能!$A$2:$A$75,0),MATCH(人物卡!$M$5,本职技能!$A$1:$HX$1,0))) -> 0 | AB34: 妙手 | AF34: 10 | AN34: =SUM(AF34:AL34) -> 10 | AP34: =INT(AN34/2) -> 5 | AR34: =INT(AN34/5) -> 2
B35: ☐ | D35: =IF(ISTEXT(IFERROR(VLOOKUP(人物卡!F35,人物卡!BJ18:BR22,1,FALSE),IFERROR(VLOOKUP(人物卡!F35,人物卡!BA18:BC22,1,FALSE),0))),"★",INDEX(本职技能!$A$2:$HX$76,MATCH(人物卡!F35,本职技能!$A$2:$A$75,0),MATCH(人物卡!$M$5,本职技能!$A$1:$HX$1,0))) -> 0 | F35: 格斗① | J35: =附表!C11 -> 0 | R35: =J35+L35+N35+P35 -> 0 | T35: =INT(R35/2) -> 0 | V35: =INT(R35/5) -> 0 | X35: ☐ | Z35: =IF(ISTEXT(IFERROR(VLOOKUP(人物卡!AB35,人物卡!BJ18:BR22,1,FALSE),IFERROR(VLOOKUP(人物卡!AB35,人物卡!BA18:BC22,1,FALSE),0))),"★",INDEX(本职技能!$A$2:$HX$76,MATCH(人物卡!AB35,本职技能!$A$2:$A$75,0),MATCH(人物卡!$M$5,本职技能!$A$1:$HX$1,0))) -> ★ | AB35: 侦查 | AF35: 25 | AJ35: 45 | AN35: =SUM(AF35:AL35) -> 70 | AP35: =INT(AN35/2) -> 35 | AR35: =INT(AN35/5) -> 14 | AU35: 自定义年龄补正 | BK35: 自定义货币
B36: ☐ | D36: =IF(ISTEXT(IFERROR(VLOOKUP(F36,人物卡!BJ18:BR22,1,FALSE),IFERROR(VLOOKUP(F36,人物卡!BA18:BC22,1,FALSE),0))),"★",INDEX(本职技能!$A$2:$HX$76,MATCH(F36,本职技能!$A$2:$A$75,0),MATCH(人物卡!$M$5,本职技能!$A$1:$HX$1,0))) -> 0 | F36: 格斗② | J36: =附表!C12 -> 0 | R36: =J36+L36+P36+N36 -> 0 | T36: =INT(R36/2) -> 0 | V36: =INT(R36/5) -> 0 | X36: ☐ | Z36: =IF(ISTEXT(IFERROR(VLOOKUP(人物卡!AB36,人物卡!BJ18:BR22,1,FALSE),IFERROR(VLOOKUP(人物卡!AB36,人物卡!BA18:BC22,1,FALSE),0))),"★",INDEX(本职技能!$A$2:$HX$76,MATCH(人物卡!AB36,本职技能!$A$2:$A$75,0),MATCH(人物卡!$M$5,本职技能!$A$1:$HX$1,0))) -> ★ | AB36: 潜行 | AF36: 20 | AJ36: 40 | AN36: =SUM(AF36:AL36) -> 60 | AP36: =INT(AN36/2) -> 30 | AR36: =INT(AN36/5) -> 12 | AU36: 年龄补正 | BK36: 货币名称 | BO36: 与美元的汇率
B37: ☐ | D37: =IF(ISTEXT(IFERROR(VLOOKUP(F37,人物卡!BJ18:BR22,1,FALSE),IFERROR(VLOOKUP(F37,人物卡!BA18:BC22,1,FALSE),0))),"★",INDEX(本职技能!$A$2:$HX$76,MATCH(F37,本职技能!$A$2:$A$75,0),MATCH(人物卡!$M$5,本职技能!$A$1:$HX$1,0))) -> 0 | F37: 格斗③ | J37: =附表!C13 -> 0 | R37: =P37+N37+L37+J37 -> 0 | T37: =INT(R37/2) -> 0 | V37: =INT(R37/5) -> 0 | X37: ☐ | Z37: =IF(ISTEXT(IFERROR(VLOOKUP(人物卡!AB37,人物卡!BJ18:BR22,1,FALSE),IFERROR(VLOOKUP(人物卡!AB37,人物卡!BA18:BC22,1,FALSE),0))),"★",INDEX(本职技能!$A$2:$HX$76,MATCH(人物卡!AB37,本职技能!$A$2:$A$75,0),MATCH(人物卡!$M$5,本职技能!$A$1:$HX$1,0))) -> 0 | AB37: 生存： | AF37: 10 | AN37: =SUM(AF37:AL37) -> 10 | AP37: =INT(AN37/2) -> 5 | AR37: =INT(AN37/5) -> 2
B38: ☐ | D38: =IF(ISTEXT(IFERROR(VLOOKUP(人物卡!F38,人物卡!BJ18:BR22,1,FALSE),IFERROR(VLOOKUP(人物卡!F38,人物卡!BA18:BC22,1,FALSE),0))),"★",INDEX(本职技能!$A$2:$HX$76,MATCH(人物卡!F38,本职技能!$A$2:$A$75,0),MATCH(人物卡!$M$5,本职技能!$A$1:$HX$1,0))) -> ★ | F38: 射击： | H38: 手枪 | J38: 20 | N38: 50 | R38: =SUM(J38:P38) -> 70 | T38: =INT(R38/2) -> 35 | V38: =INT(R38/5) -> 14 | X38: ☐ | Z38: =IF(ISTEXT(IFERROR(VLOOKUP(人物卡!AB38,人物卡!BJ18:BR22,1,FALSE),IFERROR(VLOOKUP(人物卡!AB38,人物卡!BA18:BC22,1,FALSE),0))),"★",INDEX(本职技能!$A$2:$HX$76,MATCH(人物卡!AB38,本职技能!$A$2:$A$75,0),MATCH(人物卡!$M$5,本职技能!$A$1:$HX$1,0))) -> ★ | AB38: 游泳 | AF38: 20 | AN38: =SUM(AF38:AL38) -> 20 | AP38: =INT(AN38/2) -> 10 | AR38: =INT(AN38/5) -> 4 | AU38: 推 荐 关 系 人 | AV38: =IF(M5=0," ",""&LOOKUP(M5,职业列表!A2:A232,职业列表!K2:K232))
B39: ☐ | D39: =IF(ISTEXT(IFERROR(VLOOKUP(人物卡!F39,人物卡!BJ18:BR22,1,FALSE),IFERROR(VLOOKUP(人物卡!F39,人物卡!BA18:BC22,1,FALSE),0))),"★",INDEX(本职技能!$A$2:$HX$76,MATCH(人物卡!F39,本职技能!$A$2:$A$75,0),MATCH(人物卡!$M$5,本职技能!$A$1:$HX$1,0))) -> 来复 | F39: 射击① | J39: =附表!E11 -> 0 | R39: =P39+N39+L39+J39 -> 0 | T39: =INT(R39/2) -> 0 | V39: =INT(R39/5) -> 0 | X39: ☐ | Z39: =IF(ISTEXT(IFERROR(VLOOKUP(人物卡!AB39,人物卡!BJ18:BR22,1,FALSE),IFERROR(VLOOKUP(人物卡!AB39,人物卡!BA18:BC22,1,FALSE),0))),"★",INDEX(本职技能!$A$2:$HX$76,MATCH(人物卡!AB39,本职技能!$A$2:$A$75,0),MATCH(人物卡!$M$5,本职技能!$A$1:$HX$1,0))) -> 0 | AB39: 投掷 | AF39: 20 | AN39: =SUM(AF39:AL39) -> 20 | AP39: =INT(AN39/2) -> 10 | AR39: =INT(AN39/5) -> 4
B40: ☐ | D40: =IF(ISTEXT(IFERROR(VLOOKUP(F40,人物卡!BJ18:BR22,1,FALSE),IFERROR(VLOOKUP(F40,人物卡!BA18:BC22,1,FALSE),0))),"★",INDEX(本职技能!$A$2:$HX$76,MATCH(F40,本职技能!$A$2:$A$75,0),MATCH(人物卡!$M$5,本职技能!$A$1:$HX$1,0))) -> 0 | F40: 射击② | J40: =附表!E12 -> 0 | R40: =P40+N40+L40+J40 -> 0 | T40: =INT(R40/2) -> 0 | V40: =INT(R40/5) -> 0 | X40: ☐ | Z40: =IF(ISTEXT(IFERROR(VLOOKUP(人物卡!AB40,人物卡!BJ18:BR22,1,FALSE),IFERROR(VLOOKUP(人物卡!AB40,人物卡!BA18:BC22,1,FALSE),0))),"★",INDEX(本职技能!$A$2:$HX$76,MATCH(人物卡!AB40,本职技能!$A$2:$A$75,0),MATCH(人物卡!$M$5,本职技能!$A$1:$HX$1,0))) -> ★ | AB40: 追踪 | AF40: 10 | AJ40: 40 | AN40: =SUM(AF40:AL40) -> 50 | AP40: =INT(AN40/2) -> 25 | AR40: =INT(AN40/5) -> 10
...

Sheet 简化卡 骰娘导入
B2: =人物卡!E3&"，"&人物卡!M6&"，"&人物卡!E6&"岁"&"，"&人物卡!E5&"，"&人物卡!M4&"，"&"现居："&人物卡!E7&"，"&人物卡!M7&"人" -> 艾迪安·多雷，男，31岁，探险家，1920s，现居：法国 里昂，法国 格勒诺布尔人 | N2: 技能 | Z2: 当前时间
B3: STR | C3: =附表!G14 -> 90 | D3: =INT(C3/2) -> 45 | E3: DEX | F3: =附表!J14 -> 40 | G3: =INT(F3/2) -> 20 | H3: POW | I3: =附表!M14 -> 75 | J3: =INT(I3/2) -> 37 | K3: INT | L3: =附表!L14 -> 80 | M3: =INT(L3/2) -> 40 | N3: =IF(Q3=0,"",人物卡!F16) | Q3: =IF(人物卡!R16-人物卡!J16=0,0,人物卡!R16) -> 0 | R3: =INT(Q3/2) -> 0 | S3: =INT(Q3/5) -> 0 | T3: =IF(W3=0,"",人物卡!AB16) | W3: =IF(人物卡!AN16-人物卡!AF16=0,0,人物卡!AN16) -> 0 | X3: =INT(W3/2) -> 0 | Y3: =INT(W3/5) -> 0 | Z3: =人物卡!E8 -> 0 | AA3: =人物卡!G8 -> 1980 | AC3: =人物卡!J8 -> 1月 | AD3: =人物卡!N8 -> 0：00
D4: =INT(C3/5) -> 18 | G4: =INT(F3/5) -> 8 | J4: =INT(I3/5) -> 15 | M4: =INT(L3/5) -> 16 | N4: =IF(Q4=0,"",人物卡!F17) | Q4: =IF(人物卡!R17-人物卡!J17=0,0,人物卡!R17) -> 0 | R4: =INT(Q4/2) -> 0 | S4: =INT(Q4/5) -> 0 | T4: =IF(W4=0,"",人物卡!AB17) | W4: =IF(人物卡!AN17-人物卡!AF17=0,0,人物卡!AN17) -> 0 | X4: =INT(W4/2) -> 0 | Y4: =INT(W4/5) -> 0 | AC4: =人物卡!L8 -> 1日
B5: CON | C5: =附表!H14 -> 50 | D5: =INT(C5/2) -> 25 | E5: APP | F5: =附表!K14 -> 65 | G5: =INT(F5/2) -> 32 | H5: EDU | I5: =附表!N14 -> 65 | J5: =INT(I5/2) -> 32 | K5: SIZ | L5: =附表!I14 -> 70 | M5: =INT(L5/2) -> 35 | N5: =IF(Q5=0,"",人物卡!F18) | Q5: =IF(人物卡!R18-人物卡!J18=0,0,人物卡!R18) -> 0 | R5: =INT(Q5/2) -> 0 | S5: =INT(Q5/5) -> 0 | T5: =IF(W5=0,"",人物卡!AB18) -> 聆听 | W5: =IF(人物卡!AN18-人物卡!AF18=0,0,人物卡!AN18) -> 49 | X5: =INT(W5/2) -> 24 | Y5: =INT(W5/5) -> 9 | Z5: 调查员伙伴
D6: =INT(C5/5) -> 10 | G6: =INT(F5/5) -> 13 | J6: =INT(I5/5) -> 13 | M6: =INT(L5/5) -> 14 | N6: =IF(Q6=0,"",人物卡!F19) | Q6: =IF(人物卡!R19-人物卡!J19=0,0,人物卡!R19) -> 0 | R6: =INT(Q6/2) -> 0 | S6: =INT(Q6/5) -> 0 | T6: =IF(W6=0,"",人物卡!AB19) | W6: =IF(人物卡!AN19-人物卡!AF19=0,0,人物卡!AN19) -> 0 | X6: =INT(W6/2) -> 0 | Y6: =INT(W6/5) -> 0 | Z6: 姓名 | AB6: 注释
B7: HP | C7: =人物卡!E10 -> 12 | D7: =人物卡!G10 -> 12 | E7: SAN | F7: =人物卡!N10 -> 75 | G7: =人物卡!P10 -> 99 | H7: MP | I7: =人物卡!W10 -> 15 | J7: =INT(人物卡!AG3/5) -> 15 | K7: Armor | L7: =人物卡!AN10 -> 0 | N7: =IF(Q7=0,0,"技艺：") -> 0 | O7: =IF(N7=0,"",人物卡!H20) | Q7: =IF(人物卡!R20-人物卡!J20=0,0,人物卡!R20) -> 0 | R7: =INT(Q7/2) -> 0 | S7: =INT(Q7/5) -> 0 | T7: =IF(W7=0,"",人物卡!AB20) | W7: =IF(人物卡!AN20-人物卡!AF20=0,0,人物卡!AN20) -> 0 | X7: =INT(W7/2) -> 0 | Y7: =INT(W7/5) -> 0 | Z7: =人物卡!W130 -> 例：丛雨 | AB7: =人物卡!AD130 -> 一起出生入死的医生小姐
N8: =IF(Q8=0,0,"技艺：") -> 0 | O8: =IF(N8=0,"",人物卡!H21) | Q8: =IF(人物卡!R21-人物卡!J21=0,0,人物卡!R21) -> 0 | R8: =INT(Q8/2) -> 0 | S8: =INT(Q8/5) -> 0 | T8: =IF(W8=0,"",人物卡!AB21) | W8: =IF(人物卡!AN21-人物卡!AF21=0,0,人物卡!AN21) -> 0 | X8: =INT(W8/2) -> 0 | Y8: =INT(W8/5) -> 0 | Z8: =人物卡!W131 -> 0 | AB8: =人物卡!AD131 -> 0
B9: DB | C9: =人物卡!AP52 -> +1D4 | E9: Build | F9: =人物卡!AP55 -> 1 | H9: LUCK | I9: =附表!O14 -> 70 | K9: MOV | L9: =人物卡!AF10 -> 8 | N9: =IF(Q9=0,0,"技艺：") -> 0 | O9: =IF(N9=0,"",人物卡!H22) | Q9: =IF(人物卡!R22-人物卡!J22=0,0,人物卡!R22) -> 0 | R9: =INT(Q9/2) -> 0 | S9: =INT(Q9/5) -> 0 | T9: =IF(W9=0,"",人物卡!AB22) -> 博物学 | W9: =IF(人物卡!AN22-人物卡!AF22=0,0,人物卡!AN22) -> 50 | X9: =INT(W9/2) -> 25 | Y9: =INT(W9/5) -> 10 | Z9: =人物卡!W132 -> 0 | AB9: =人物卡!AD132 -> 0
N10: =IF(Q10=0,"",人物卡!F23) -> 取悦 | Q10: =IF(人物卡!R23-人物卡!J23=0,0,人物卡!R23) -> 49 | R10: =INT(Q10/2) -> 24 | S10: =INT(Q10/5) -> 9 | T10: =IF(W10=0,"",人物卡!AB23) | W10: =IF(人物卡!AN23-人物卡!AF23=0,0,人物卡!AN23) -> 0 | X10: =INT(W10/2) -> 0 | Y10: =INT(W10/5) -> 0 | Z10: =人物卡!W133 -> 0 | AB10: =人物卡!AD133 -> 0
B11: 武器表 | N11: =IF(Q11=0,"",人物卡!F24) | Q11: =IF(人物卡!R24-人物卡!J24=0,0,人物卡!R24) -> 0 | R11: =INT(Q11/2) -> 0 | S11: =INT(Q11/5) -> 0 | T11: =IF(W11=0,"",人物卡!AB24) | W11: =IF(人物卡!AN24-人物卡!AF24=0,0,人物卡!AN24) -> 0 | X11: =INT(W11/2) -> 0 | Y11: =INT(W11/5) -> 0 | Z11: =人物卡!W134 -> 0 | AB11: =人物卡!AD134 -> 0
B12: =人物卡!B53 -> 0 | C12: =人物卡!G53 -> 0 | D12: =人物卡!M53 -> 0 | E12: =人物卡!Q53 -> 0 | F12: =人物卡!S53 -> 0 | G12: =人物卡!U53 -> 0 | H12: =人物卡!W53 -> 0 | I12: =人物卡!AA53 -> 0 | J12: =人物卡!AC53 -> 0 | K12: =人物卡!AE53 -> 0 | L12: =人物卡!AG53 -> 0 | M12: =人物卡!AJ53 -> 0 | N12: =IF(Q12=0,"",人物卡!F25) | Q12: =IF(人物卡!R25-人物卡!J25=0,0,人物卡!R25) -> 0 | R12: =INT(Q12/2) -> 0 | S12: =INT(Q12/5) -> 0 | T12: =IF(W12=0,"",人物卡!AB25) | W12: =IF(人物卡!AN25-人物卡!AF25=0,0,人物卡!AN25) -> 0 | X12: =INT(W12/2) -> 0 | Y12: =INT(W12/5) -> 0 | Z12: =人物卡!W135 -> 0 | AB12: =人物卡!AD135 -> 0
B13: =人物卡!B54 -> 0 | C13: =人物卡!G54 -> 0 | D13: =IF(人物卡!M54="请选择类型","",人物卡!M54) -> 0 | E13: =人物卡!Q54 -> 0 | F13: =人物卡!S54 -> 0 | G13: =人物卡!U54 -> 0 | H13: =人物卡!W54 -> 0 | I13: =人物卡!AA54 -> 0 | J13: =人物卡!AC54 -> 0 | K13: =人物卡!AE54 -> 0 | L13: =人物卡!AG54 -> 0 | M13: =人物卡!AJ54 -> 0 | N13: =人物卡!F26 -> 信用评级 | Q13: =人物卡!R26 -> 50 | R13: =IF(Q13=0,32767,INT(Q13/2)) -> 25 | S13: =IF(Q13=0,32767,INT(Q13/5)) -> 10 | T13: =IF(W13=0,"",人物卡!AB26) -> 说服 | W13: =IF(人物卡!AN26-人物卡!AF26=0,0,人物卡!AN26) -> 49 | X13: =INT(W13/2) -> 24 | Y13: =INT(W13/5) -> 9 | Z13: =人物卡!W136 -> 0 | AB13: =人物卡!AD136 -> 0
B14: =人物卡!B55 -> 好用的刀 | C14: =人物卡!G55 -> 小型刀具(弹簧折叠刀等) | D14: =IF(人物卡!M55="请选择类型","",人物卡!M55) -> 斗殴 | E14: =人物卡!Q55 -> 65 | F14: =人物卡!S55 -> 32 | G14: =人物卡!U55 -> 13 | H14: =人物卡!W55 -> 1D4+DB | I14: =人物卡!AA55 -> 接触 | J14: =人物卡!AC55 -> √ | K14: =人物卡!AE55 -> 1 | L14: =人物卡!AG55 -> —— | M14: =人物卡!AJ55 -> —— | N14: =IF(Q14=0,"",人物卡!F27) | Q14: =IF(人物卡!R27-人物卡!J27=0,0,人物卡!R27) -> 0 | R14: =INT(Q14/2) -> 0 | S14: =INT(Q14/5) -> 0 | T14: =IF(W14=0,0,人物卡!AB27) -> 0 | U14: =IF(T14=0,"",人物卡!AD27) | W14: =IF(人物卡!AN27-人物卡!AF27=0,0,人物卡!AN27) -> 0 | X14: =INT(W14/2) -> 0 | Y14: =INT(W14/5) -> 0 | Z14: =人物卡!W137 -> 0 | AB14: =人物卡!AD137 -> 0
B15: =人物卡!B56 -> 好用的枪 | C15: =人物卡!G56 -> .357 马格南左轮 | D15: =IF(人物卡!M56="请选择类型","",人物卡!M56) -> 手枪 | E15: =人物卡!Q56 -> 70 | F15: =人物卡!S56 -> 35 | G15: =人物卡!U56 -> 14 | H15: =人物卡!W56 -> 1D8+1D4 | I15: =人物卡!AA56 -> 15 | J15: =人物卡!AC56 -> √ | K15: =人物卡!AE56 -> 1(3) | L15: =人物卡!AG56 -> 6 | M15: =人物卡!AJ56 -> 100 | N15: =IF(Q15=0,"",人物卡!F28) | Q15: =IF(人物卡!R28-人物卡!J28=0,0,人物卡!R28) -> 0 | R15: =INT(Q15/2) -> 0 | S15: =INT(Q15/5) -> 0 | T15: =IF(W15=0,"",人物卡!AB28) | W15: =IF(人物卡!AN28-人物卡!AF28=0,0,人物卡!AN28) -> 0 | X15: =INT(W15/2) -> 0 | Y15: =INT(W15/5) -> 0 | Z15: =人物卡!W138 -> 0 | AB15: =人物卡!AD138 -> 0
B16: =人物卡!B57 -> 0 | C16: =人物卡!G57 -> 0 | D16: =IF(人物卡!M57="请选择类型","",人物卡!M57) -> 0 | E16: =人物卡!Q57 -> 0 | F16: =人物卡!S57 -> 0 | G16: =人物卡!U57 -> 0 | H16: =人物卡!W57 -> 0 | I16: =人物卡!AA57 -> 0 | J16: =人物卡!AC57 -> 0 | K16: =人物卡!AE57 -> 0 | L16: =人物卡!AG57 -> 0 | M16: =人物卡!AJ57 -> 0 | N16: =人物卡!F29 -> 闪避 | Q16: =人物卡!R29 -> 44 | R16: =IF(Q16=0,32767,INT(Q16/2)) -> 22 | S16: =IF(Q16=0,32767,INT(Q16/5)) -> 8 | T16: =IF(W16=0,"",人物卡!AB29) -> 心理学 | W16: =IF(人物卡!AN29-人物卡!AF29=0,0,人物卡!AN29) -> 49 | X16: =INT(W16/2) -> 24 | Y16: =INT(W16/5) -> 9 | Z16: =人物卡!W139 -> 0 | AB16: =人物卡!AD139 -> 0
B17: 资产 | N17: =IF(Q17=0,"",人物卡!F30) | Q17: =IF(人物卡!R30-人物卡!J30=0,0,人物卡!R30) -> 0 | R17: =INT(Q17/2) -> 0 | S17: =INT(Q17/5) -> 0 | T17: =IF(W17=0,"",人物卡!AB30) | W17: =IF(人物卡!AN30-人物卡!AF30=0,0,人物卡!AN30) -> 0 | X17: =INT(W17/2) -> 0 | Y17: =INT(W17/5) -> 0 | Z17: =人物卡!W140 -> 0 | AB17: =人物卡!AD140 -> 0
B18: 信用评级 | E18: 生活水平 | G18: 消费水平 | I18: 其他资产 | K18: 当前现金($) | M18: 单位 | N18: =IF(Q18=0,"",人物卡!F31) | Q18: =IF(人物卡!R31-人物卡!J31=0,0,人物卡!R31) -> 0 | R18: =INT(Q18/2) -> 0 | S18: =INT(Q18/5) -> 0 | T18: =IF(W18=0,0,"科学：") -> 0 | U18: =IF(T18=0,"",人物卡!AD31) | W18: =IF(人物卡!AN31-人物卡!AF31=0,0,人物卡!AN31) -> 0 | X18: =INT(W18/2) -> 0 | Y18: =INT(W18/5) -> 0
B19: =人物卡!B62 -> 50%/25%/10% | E19: =人物卡!F62 -> 小康 | G19: =人物卡!I62 -> 50 | I19: =人物卡!L62 -> 2.5万 | K19: =人物卡!O62 -> 250 | M19: =人物卡!S62 -> 美元 | N19: =IF(Q19=0,"",人物卡!F32) | Q19: =IF(人物卡!R32-人物卡!J32=0,0,人物卡!R32) -> 0 | R19: =INT(Q19/2) -> 0 | S19: =INT(Q19/5) -> 0 | T19: =IF(W19=0,0,"科学：") -> 0 | U19: =IF(T19=0,"",人物卡!AD32) | W19: =IF(人物卡!AN32-人物卡!AF32=0,0,人物卡!AN32) -> 0 | X19: =INT(W19/2) -> 0 | Y19: =INT(W19/5) -> 0
B20: =人物卡!L63 -> 0 | N20: =IF(Q20=0,"",人物卡!F33) | Q20: =IF(人物卡!R33-人物卡!J33=0,0,人物卡!R33) -> 0 | R20: =INT(Q20/2) -> 0 | S20: =INT(Q20/5) -> 0 | T20: =IF(W20=0,0,"科学：") -> 0 | U20: =IF(T20=0,"",人物卡!AD33) | W20: =IF(人物卡!AN33-人物卡!AF33=0,0,人物卡!AN33) -> 0 | X20: =INT(W20/2) -> 0 | Y20: =INT(W20/5) -> 0
B21: 随身物品 | N21: =IF(Q21=0,0,"格斗：") -> 格斗： | O21: =IF(N21=0,"",人物卡!H34) -> 斗殴 | Q21: =IF(人物卡!R34-人物卡!J34=0,0,人物卡!R34) -> 65 | R21: =INT(Q21/2) -> 32 | S21: =INT(Q21/5) -> 13 | T21: =IF(W21=0,"",人物卡!AB34) | W21: =IF(人物卡!AN34-人物卡!AF34=0,0,人物卡!AN34) -> 0 | X21: =INT(W21/2) -> 0 | Y21: =INT(W21/5) -> 0 | Z21: 神话相关
B22: =人物卡!F79 -> 大衣 | E22: =人物卡!F80 -> 银质项链 | H22: =人物卡!F81 -> 护照、钱包 | K22: =人物卡!F82 -> 公路地图 | N22: =IF(Q22=0,0,"格斗：") -> 0 | O22: =IF(N22=0,"",人物卡!H35) | Q22: =IF(人物卡!R35-人物卡!J35=0,0,人物卡!R35) -> 0 | R22: =INT(Q22/2) -> 0 | S22: =INT(Q22/5) -> 0 | T22: =IF(W22=0,"",人物卡!AB35) -> 侦查 | W22: =IF(人物卡!AN35-人物卡!AF35=0,0,人物卡!AN35) -> 70 | X22: =INT(W22/2) -> 35 | Y22: =INT(W22/5) -> 14 | Z22: 遇到了 | AD22: 累计消耗
B23: =人物卡!F83 -> 打火机 | E23: =人物卡!F84 -> 车钥匙 | H23: =人物卡!F85 -> 烟盒 | K23: =人物卡!F90 -> 手枪 | N23: =IF(Q23=0,0,"格斗：") -> 0 | O23: =IF(N23=0,"",人物卡!H36) | Q23: =IF(人物卡!R36-人物卡!J36=0,0,人物卡!R36) -> 0 | R23: =INT(Q23/2) -> 0 | S23: =INT(Q23/5) -> 0 | T23: =IF(W23=0,"",人物卡!AB36) -> 潜行 | W23: =IF(人物卡!AN36-人物卡!AF36=0,0,人物卡!AN36) -> 60 | X23: =INT(W23/2) -> 30 | Y23: =INT(W23/5) -> 12 | Z23: =人物卡!W98 -> 例：米-戈 | AD23: =人物卡!AR98 -> 6
B24: =人物卡!F91 -> 指南针 | E24: =人物卡!F92 -> 0 | H24: =人物卡!N79 -> 0 | K24: =人物卡!N80 -> 0 | N24: =IF(Q24=0,0,"格斗：") -> 0 | O24: =IF(N24=0,"",人物卡!H37) | Q24: =IF(人物卡!R37-人物卡!J37=0,0,人物卡!R37) -> 0 | R24: =INT(Q24/2) -> 0 | S24: =INT(Q24/5) -> 0 | T24: =IF(W24=0,0,人物卡!AB37) -> 0 | U24: =IF(T24=0,"",人物卡!AD37) | W24: =IF(人物卡!AN37-人物卡!AF37=0,0,人物卡!AN37) -> 0 | X24: =INT(W24/2) -> 0 | Y24: =INT(W24/5) -> 0 | Z24: =人物卡!W99 -> 例：修格斯 | AD24: =人物卡!AR99 -> 5
B25: =人物卡!N81 -> 0 | E25: =人物卡!N82 -> 0 | H25: =人物卡!N83 -> 0 | K25: =人物卡!N84 -> 0 | N25: =IF(Q25=0,0,"射击：") -> 射击： | O25: =IF(N25=0,"",人物卡!H38) -> 手枪 | Q25: =IF(人物卡!R38-人物卡!J38=0,0,人物卡!R38) -> 70 | R25: =INT(Q25/2) -> 35 | S25: =INT(Q25/5) -> 14 | T25: =IF(W25=0,"",人物卡!AB38) | W25: =IF(人物卡!AN38-人物卡!AF38=0,0,人物卡!AN38) -> 0 | X25: =INT(W25/2) -> 0 | Y25: =INT(W25/5) -> 0 | Z25: =人物卡!W100 -> 0 | AD25: =人物卡!AR100 -> 0
B26: =人物卡!N85 -> 0 | E26: =人物卡!N90 -> 0 | H26: =人物卡!N91 -> 0 | K26: =人物卡!N92 -> 0 | N26: =IF(Q26=0,0,"射击：") -> 0 | O26: =IF(N26=0,"",人物卡!H39) | Q26: =IF(人物卡!R39-人物卡!J39=0,0,人物卡!R39) -> 0 | R26: =INT(Q26/2) -> 0 | S26: =INT(Q26/5) -> 0 | T26: =IF(W26=0,"",人物卡!AB39) | W26: =IF(人物卡!AN39-人物卡!AF39=0,0,人物卡!AN39) -> 0 | X26: =INT(W26/2) -> 0 | Y26: =INT(W26/5) -> 0 | Z26: =人物卡!W101 -> 0 | AD26: =人物卡!AR101 -> 0
B27: 背景故事 | N27: =IF(Q27=0,0,"射击：") -> 0 | O27: =IF(N27=0,"",人物卡!H40) | Q27: =IF(人物卡!R40-人物卡!J40=0,0,人物卡!R40) -> 0 | R27: =INT(Q27/2) -> 0 | S27: =INT(Q27/5) -> 0 | T27: =IF(W27=0,"",人物卡!AB40) -> 追踪 | W27: =IF(人物卡!AN40-人物卡!AF40=0,0,人物卡!AN40) -> 50 | X27: =INT(W27/2) -> 25 | Y27: =INT(W27/5) -> 10 | Z27: =人物卡!W102 -> 0 | AD27: =人物卡!AR102 -> 0
B28: 描述 | C28: =人物卡!AA61 -> 肩背宽阔的青年，体格健壮，深棕色头发，灰绿色眼睛，以相貌而言，乍一看，人们会认为他应当是流连于酒场的生意人，碰巧有些运动爱好。然而，他的手积满了厚茧 | G28: 关键 | H28: =人物卡!W77 -> 十四岁那年，艾迪安与朋友在韦科尔山徒步时失足滚下山崖。幸运的是，他最后只摔断了一根肋骨，外加满身擦伤。 获救后，父亲问他当时是不是吓坏了。艾迪安想了一会儿，发现自己并没怎么害怕。坠落时，他甚至还有心思判断该用哪里着地，停下来后的第一件事也是检查自己还能不能动。第二件事——噢，他那时候在想：这里的云真好看。 这让十四岁的艾迪安第一次意识到，自己似乎没什么恐惧心。后来，他开始主动寻找那些别人避之不及的地方：废弃矿洞、地下河、无人山区，以及地图上只有一片空白的角落。 成年后，艾迪安成为了一名探险家。家里对此颇有微词，他则认为这比坐办公室适合自己。 如今，他的探索版图从欧洲一路扩展到了另一块大陆。美国的阿巴拉契亚山脉是个不错的开始。 | N28: =IF(Q28=0,0,"射击：") -> 0 | O28: =IF(N28=0,"",人物卡!H41) | Q28: =IF(人物卡!R41-人物卡!J41=0,0,人物卡!R41) -> 0 | R28: =INT(Q28/2) -> 0 | S28: =INT(Q28/5) -> 0 | T28: =IF(W28=0,"",人物卡!AB41) | W28: =IF(人物卡!AN41-人物卡!AF41=0,0,人物卡!AN41) -> 0 | X28: =INT(W28/2) -> 0 | Y28: =INT(W28/5) -> 0 | Z28: =人物卡!W103 -> 0 | AD28: =人物卡!AR103 -> 0
B29: 信仰 | C29: =人物卡!AA63 -> 未知并不可怖——无知才是。 | G29: =人物卡!AR63 -> ☐ | N29: =IF(Q29=0,"",人物卡!F42) | Q29: =IF(人物卡!R42-人物卡!J42=0,0,人物卡!R42) -> 0 | R29: =INT(Q29/2) -> 0 | S29: =INT(Q29/5) -> 0 | T29: =IF(W29=0,"",人物卡!AB47) | W29: =IF(人物卡!AN42-人物卡!AF42=0,0,人物卡!AN42) -> 0 | X29: =INT(W29/2) -> 0 | Y29: =INT(W29/5) -> 0 | Z29: =人物卡!W104 -> 0 | AD29: =人物卡!AR104 -> 0
B30: 重要人 | C30: =人物卡!AA65 -> 父母。一对体面的中产家庭夫妇，对儿子常年探险这件事既骄傲又头疼。尽管他们支持他的旅行，仍然一直希望他“能找份真正的工作”。 | G30: =人物卡!AR65 -> ☐ | N30: =IF(Q30=0,"",人物卡!F43) | Q30: =IF(人物卡!R43-人物卡!J43=0,0,人物卡!R43) -> 0 | R30: =INT(Q30/2) -> 0 | S30: =INT(Q30/5) -> 0 | T30: =IF(W30=0,"",人物卡!AB43) | W30: =IF(人物卡!AN43-人物卡!AF43=0,0,人物卡!AN43) -> 0 | X30: =INT(W30/2) -> 0 | Y30: =INT(W30/5) -> 0 | Z30: =人物卡!W105 -> 0 | AD30: =人物卡!AR105 -> 0
B31: 重要地 | C31: =人物卡!AA67 -> 韦科尔山地，少年时代第一次独自探险的地方 | G31: =人物卡!AR67 -> ☐ | N31: =IF(Q31=0,"",人物卡!F44) | Q31: =IF(人物卡!R44-人物卡!J44=0,0,人物卡!R44) -> 0 | R31: =INT(Q31/2) -> 0 | S31: =INT(Q31/5) -> 0 | T31: =IF(W31=0,"",人物卡!AB44) | W31: =IF(人物卡!AN44-人物卡!AF44=0,0,人物卡!AN44) -> 0 | X31: =INT(W31/2) -> 0 | Y31: =INT(W31/5) -> 0 | Z31: =人物卡!W106 -> 0 | AD31: =人物卡!AR106 -> 0
B32: 宝物 | C32: =人物卡!AA69 -> 一枚老式机械腕表，父母的礼物，从不跑慢 | G32: =人物卡!AR69 -> ☐ | N32: =IF(Q32=0,"",人物卡!F45) | Q32: =IF(人物卡!R45-人物卡!J45=0,0,人物卡!R45) -> 0 | R32: =INT(Q32/2) -> 0 | S32: =INT(Q32/5) -> 0 | T32: =IF(W32=0,"",人物卡!AB45) | W32: =IF(人物卡!AN45-人物卡!AF45=0,0,人物卡!AN45) -> 0 | X32: =INT(W32/2) -> 0 | Y32: =INT(W32/5) -> 0 | Z32: =人物卡!W107 -> 0 | AD32: =人物卡!AR107 -> 0
B33: 特质 | C33: =人物卡!AA71 -> 好奇心胜过了自保意识 | G33: =人物卡!AR71 -> ☐ | N33: =IF(Q33=0,0,"外语：") -> 0 | O33: =IF(N33=0,"",人物卡!H46) | Q33: =IF(人物卡!R46-人物卡!J46=0,0,人物卡!R46) -> 0 | R33: =INT(Q33/2) -> 0 | S33: =INT(Q33/5) -> 0 | T33: =IF(W33=0,"",人物卡!AB46) | W33: =IF(人物卡!AN46-人物卡!AF46=0,0,人物卡!AN46) -> 0 | X33: =INT(W33/2) -> 0 | Y33: =INT(W33/5) -> 0 | Z33: =人物卡!W108 -> 0 | AD33: =人物卡!AR108 -> 0
B34: 小秘密 | C34: =人物卡!AA73 -> 左侧肋骨附近有一道不规则旧疤，一次攀岩事故留下的 | G34: =人物卡!AR73 -> ☐ | N34: =IF(Q34=0,0,"外语：") -> 0 | O34: =IF(N34=0,"",人物卡!H47) | Q34: =IF(人物卡!R47-人物卡!J47=0,0,人物卡!R47) -> 0 | R34: =INT(Q34/2) -> 0 | S34: =INT(Q34/5) -> 0 | T34: =IF(W34=0,"",#REF!) | W34: =IF(人物卡!AN47-人物卡!AF47=0,0,人物卡!AN47) -> 0 | X34: =INT(W34/2) -> 0 | Y34: =INT(W34/5) -> 0
B35: 伤疤 | C35: =人物卡!AA75 -> 极其不喜欢被困在无法自主离开的地方，却没有发展成幽闭恐惧。他可以进入极狭窄的洞穴，因为他确信自己知道出口在哪里。 | G35: =人物卡!AR75 -> ☐ | N35: =IF(Q35=0,0,"外语：") -> 0 | O35: =IF(N35=0,"",人物卡!H48) | Q35: =IF(人物卡!R48-人物卡!J48=0,0,人物卡!R48) -> 0 | R35: =INT(Q35/2) -> 0 | S35: =INT(Q35/5) -> 0 | T35: =IF(W35=0,"",人物卡!AB48) | W35: =IF(人物卡!AN48-人物卡!AF48=0,0,人物卡!AN48) -> 0 | X35: =INT(W35/2) -> 0 | Y35: =INT(W35/5) -> 0
B36: 恐惧 | C36: =人物卡!AA77 -> 0 | N36: 母语： | O36: =人物卡!H49 -> 0 | Q36: =人物卡!R49 -> 65 | R36: =IF(Q36=0,32767,INT(Q36/2)) -> 32 | S36: =IF(Q36=0,32767,INT(Q36/5)) -> 13 | T36: =IF(W36=0,"",人物卡!AB49) | W36: =IF(人物卡!AN49-人物卡!AF49=0,0,人物卡!AN49) -> 0 | X36: =INT(W36/2) -> 0 | Y36: =INT(W36/5) -> 0 | AF36: 电脑请先将快捷输入复制到下面的框中，再复制框中内容到QQ
B37: 下面就是快捷输入了，手机一般轻点两下就可以复制啦，电脑请先复制到右边的本文框 | P37: 不知道用什么导入看导入框右侧的说明～ | AF37: 电脑本文输入框
B38: 溯洄，shiki（除Exp10)，等大部分骰娘指令快捷输入
B39: 请“复制”下格，就可以导出文本，放进QQ发送给骰子娘啦 | Z39: → | AA39: 大部分骰娘 | AF39: 如果不能使用，请复制到txt文档，然后再复制到QQ
B40: =附表!S24 -> .st 力量90str90敏捷40dex40意志75pow75体质50con50外貌65app65教育65edu65体型70siz70智力80灵感80int80san75san值75理智75理智值75幸运70运气70mp15魔法15hp12体力12会计5人类学1估价5考古学1取悦49魅惑49攀爬20计算机5计算机使用5电脑5信用50信誉50信用评级50克苏鲁0克苏鲁神话0cm0乔装5闪避44汽车20驾驶20汽车驾驶20电气维修10电子学1话术5斗殴65手枪70急救30历史5恐吓15跳跃20母语65法律5图书馆20图书馆使用20聆听49开锁1撬锁1锁匠1机械维修10医学1博物学50自然学50领航10导航10神秘学5重型操作1重型机械1操作重型机械1重型1说服49精神分析1心理学49骑术5妙手10侦查70潜行60生存10游泳20投掷20追踪50驯兽5潜水1爆破1读唇1催眠1炮术1
B44: 塔系骰娘指令快捷输入
...

Sheet 职业列表
A1: 序号 | B1: 职业 | D1: 信用评级 | E1: 职业属性 | F1: 技能点 | G1: 本职技能 | K1: 推荐关系人 | M1: 职业介绍
A2: 0 | B2: 选择职业序号为0，则清除职业模板提示和点数计算器，供强迫症患者使用。 | H2: 右侧下拉框选择自定义职业技能与属性 （excel2007及以下不适用） | I2: 自定义职业本职技能
A3: 1 | B3: =IF(C3="","自定义职业",C3) -> 自定义职业 | E3: =附表!AA9 -> 教育×4 | F3: =SUM(附表!AF10:AF12) -> 260 | G3: =IF(I3<>"",I3&"，"&I4&"，"&I5&"，"&I6&"，"&I7&"，"&I8&"，"&I9&"，"&I10,"不多于8个本职技能。在职业属性中输入第二职业属性的数值（留空则视为EDU）并自行设置起始信誉。使用自定义职业前，请先咨询你的守秘人。") -> 不多于8个本职技能。在职业属性中输入第二职业属性的数值（留空则视为EDU）并自行设置起始信誉。使用自定义职业前，请先咨询你的守秘人。 | K3: 列出一些角色在职业工作中可能接触的个人或组织,它们也可以为调查员的个人背景提供灵感。 | M3: 不多于7个本职技能。 在职业属性中输入第二职业属性的名字（如外貌、意志、教育、敏捷、力量、体质、体型，留空则视为附表!N14）并自行设置起始信誉。使用自定义职业前，请先咨询你的KP
A4: 2 | B4: 会计师 | D4: 30-70 | E4: 教育×4 | F4: =附表!N14*4 -> 260 | G4: 会计，法律，图书馆，聆听，说服，侦查，任意其他两项个人或时代特长。 | K4: 生意伙伴，法律界，金融业界(银行，其他会计师)。 | M4: 会计师可能在企业工作或作为自由会计师，为个体经营者和企业客户担任顾问。 他们是优秀的研究者，既勤奋又关注细节，能够通过仔细分析个人和企业事务历史记录、财务报表和其他记录支持其他调查员。
A5: 3 | B5: 杂技演员 | D5: 9-20 | E5: 教育×2＋敏捷×2 | F5: =附表!N14*2+附表!J14*2 -> 210 | G5: 攀爬，闪避，跳跃，投掷，侦查，游泳，任意两项其他个人或时代特长。 | K5: 业余运动员圈，体育专栏作家，马戏团，嘉年华管理者。 | M5: 杂技演员可能是参加各级比赛(甚至奥运会)的业余运动员，也可能是专业的演员，在马戏团、嘉年华、歌舞团之类的地方作为娱乐业从业者工作。
A6: 4 | B6: 演员-戏剧演员 | D6: 9-40 | E6: 教育×2＋外貌×2 | F6: =附表!N14*2+附表!K14*2 -> 260 | G6: 技艺（表演），乔装，格斗，历史，两项社交技能（取悦、话术、恐吓、说服），心理学，任意一项其他个人或时代特长。 | K6: 戏剧产业，报刊艺术批评家，演员公会。 | M6: 一般指舞台剧演员和电影演员。许多演员有相当深厚的文化素养，认为自己才是“正统”的，倾向于轻视电影业的商业活动。直到20 世纪后期电影业的地位提高，电影演员的薪酬增加，这种情况才发生改变。 电影业和电影明星一直是世界人民关注的焦点。许多明星一夜成名，在媒体的聚光灯下过着光鲜亮丽的生活。 在1920 年代，虽然全国都有大型剧院，美国的戏剧中心仍然是纽约城。英国的情况与之相近，戏剧的中心在伦敦，其他的剧团则在各郡作巡回演出。巡回剧团乘火车旅行，演出内容既包括新编剧目，也包括莎士比亚和其他人的传统剧目。有些剧团也会花时间去国外采风，通常是去加拿大、夏威夷、澳大利亚和欧洲大陆。 20 年代后期出现了有声电影，不少默片时代的明星难以适应有声电影的冲击，挥舞手臂的夸张扮演从此让位给了细致入微的角色特写。这段时间前期的明星包括约翰·加菲尔德和弗兰西斯·布什曼，后期则是贾莱·库珀和琼·克劳馥。
A7: 5 | B7: 演员-电影演员 | D7: 20-90 | E7: 教育×2＋外貌×2 | F7: =附表!N14*2+附表!K14*2 -> 260 | G7: 技艺（表演），乔装，汽车驾驶，两项社交技能（取悦、话术、恐吓、说服），心理学，任意两项其他个人或时代特长（如骑乘或格斗）。 | K7: 电影工作室，媒体评论员，作家。 | M7: 一般指舞台剧演员和电影演员。许多演员有相当深厚的文化素养，认为自己才是“正统”的，倾向于轻视电影业的商业活动。直到20 世纪后期电影业的地位提高，电影演员的薪酬增加，这种情况才发生改变。 电影业和电影明星一直是世界人民关注的焦点。许多明星一夜成名，在媒体的聚光灯下过着光鲜亮丽的生活。 在1920 年代，虽然全国都有大型剧院，美国的戏剧中心仍然是纽约城。英国的情况与之相近，戏剧的中心在伦敦，其他的剧团则在各郡作巡回演出。巡回剧团乘火车旅行，演出内容既包括新编剧目，也包括莎士比亚和其他人的传统剧目。有些剧团也会花时间去国外采风，通常是去加拿大、夏威夷、澳大利亚和欧洲大陆。 20 年代后期出现了有声电影，不少默片时代的明星难以适应有声电影的冲击，挥舞手臂的夸张扮演从此让位给了细致入微的角色特写。这段时间前期的明星包括约翰·加菲尔德和弗兰西斯·布什曼，后期则是贾莱·库珀和琼·克劳馥。
A8: 6 | B8: 事务所侦探、保安 | D8: 20-45 | E8: 教育×2＋力量或敏捷×2 | F8: =附表!N14*2+MAX(附表!G14*2,附表!J14*2) -> 310 | G8: 一项社交技能（取悦、话术、恐吓、说服），格斗（斗殴），射击，法律，图书馆，心理学，潜行，追踪。 | K8: 本地执法机构，客户。 | M8: 世界上有许多著名的侦探机构，其中最著名的是平克顿和伯恩斯调查局(后来合并成一家公司)。这样的公司一般有两类工作人员：安保人员和调查人员。 企业或个人雇用安保人员来保护自己的资产和人员免受盗贼、刺客和绑匪的威胁。这些安保人员角色使用巡警的职业模板。调查人员则是便衣侦探，负责为公司客户解决各种异常事件、阻止谋杀事件、寻找失踪的人员等等。
A9: 7 | B9: 精神病医生（古典） | D9: 10-60 | E9: 教育×4 | F9: =附表!N14*4 -> 260 | G9: 法律，聆听，医学，外语，精神分析，心理学，科学（生物学，化学）。 | K9: 其他精神疾病研究者，医生，有时还有执法机构的侦探。 | M9: 在1920 年代，“精神病医生”这个词专用来称呼治疗精神失常的医生(也就是早期的精神科医生)。精神分析在当时的美国鲜为人知，而且它的基本内容都是性生活和如厕训练之类令大众不齿的东西。精神病学，一种正规的从行为主义发展来的医学理论则要普及得多。精神病医生、精神科医生和神经科医生还经常爆发激烈的论战。
A10: 8 | B10: 动物训练师 | D10: 10-40 | E10: 教育×2＋外貌或意志×2 | F10: =附表!N14*2+MAX(附表!K14*2,附表!M14*2) -> 280 | G10: 跳跃，聆听，自然，心理学，科学（动物学），潜行，追踪，任意一项其他个人或时代特长。 | K10: 动物园，马戏团，赞助人，演员。 | M10: 动物训练师可能在电影工作室、巡回马戏团、马厩工作或自由工作。不管是训练导盲犬、狮子钻火圈，他们工作时基本要独自一人长时间近距离地照看这些动物。动物训练师可以像对人一样对动物使用「心理学」技能。
A11: 9 | B11: 文物学家（原作向） | D11: 30-70 | E11: 教育×4 | F11: =附表!N14*4 -> 260 | G11: 估价，技艺（任一），历史，图书馆，外语，一项社交技能（取悦、话术、恐吓、说服），侦查，任意一项其他个人或时代特长。 | I11: 任意特长数: | K11: 书商，古董收藏者，历史研究学会。 | M11: 文物学家也许是调查员可以从事的最具有洛夫克拉夫特风格的职业：那些历久弥新的的卓越作品、湮没在古代传说中的神奇力量，总能使他们乐在其中。独立的收入使文物学家能够研究古旧晦涩的文物，或者根据自己的兴趣爱好集中探寻特别的种类。他们通常有着欣赏的眼光、敏锐的头脑，和讽刺无知、自大、贪婪者的愚蠢时尖酸刻薄的幽默。
A12: 10 | B12: 古董商 | D12: 30-50 | E12: 教育×4 | F12: =附表!N14*4 -> 260 | G12: 会计，估价，汽车驾驶，两项社交技能（取悦、话术、恐吓、说服），历史，图书馆，导航。 | K12: 本地的历史学家，其他古董商，可能还包括赝造师。 | M12: 古董商通常自己开店，从自己所在的地方转卖物品，或继续扩展业务范围，通过倒卖物品到城市商店赚取利润。
A13: 11 | B13: 考古学家（原作向） | D13: 10-40 | E13: 教育×4 | F13: =附表!N14*4 -> 260 | G13: 估价，考古，历史，外语，图书馆，侦查，机械维修，导航或科学（任一：如化学、物理、地理等）。 | H13: 自定义职业属性 | K13: 赞助人，博物馆，大学。 | M13: 考古学家研究探索历史的痕迹。主要来说，是对人类历史相关的物质数据进行各种鉴识、检查、分析。这项工作包含辛苦细致的研究，更不必提情愿亲自下斗铲土的决心。 在1920 年代，成功的考古学家会被当成著名冒险家与探险家，名利双收。有人运用科学方法考古，不过更多的人对付老祖宗的秘密时喜好暴力破解的办法，甚至祭出炸药，这种碉堡了的办法现代人可是很难看得惯的。
A14: 12 | B14: 建筑师 | D14: 30-70 | E14: 教育×4 | F14: =附表!N14*4 -> 260 | G14: 会计，技艺（技术制图），法律，母语，计算机或图书馆，说服，心理学，科学（数学）。 | H14: 属性名称 | I14: 是否使用 | J14: 使用倍数 | K14: 本地建设和城市规划部门，建筑公司。 | M14: 建筑师掌握设计和营造建筑的知识，不论是个人房屋的改造还是造价数百万美元的地标工程。建筑师与项目经理紧密合作，负责监督施工全程。建筑师必须了解当地的规划法律，健康和安全法规，和基础的公众安全原则。他们既可以在大公司工作，也可以自由工作，这在很大程度上取决于信誉。 在1920 年代，许多人尝试在自家或小办公室单干。不过他们苦心创造的宏伟设计很少能卖得出去。 建筑师也可能专擅某一学科，比如军事建筑或景观工程等。
A15: 13 | B15: 艺术家 | D15: 9-50 | E15: 教育×2＋敏捷或意志×2 | F15: =附表!N14*2+MAX(附表!J14*2,附表!M14*2) -> 280 | G15: 技艺（任一），历史或自然，一项社交技能（取悦、话术、恐吓、说服），外语，心理学，侦查，任意两项其他个人或时代特长。 | H15: 力量 | I15: × | J15: =IF(I15="√",2,0) -> 0 | K15: 美术馆，美术批评家，富有的赞助人，广告业者。 | M15: 艺术家在这里可以是画家，雕塑家等等。他们有时沈浸于自己虚幻的想象当中，有时又沐浴在激发热情和理解的灵感之下。不论是否天资优秀，艺术家的内心必须足够强大，这样才能战胜生涯起步时的障碍和挑剔的眼光，并且在自己小有名气以后继续努力。有些艺术家对物质生活是否丰富并不在乎，而有些则有着强烈的创业倾向。
A16: 14 | B16: 精神病院看护 | D16: 8-20 | E16: 教育×2＋力量或敏捷×2 | F16: =附表!N14*2+MAX(附表!G14*2,附表!J14*2) -> 310 | G16: 闪避，格斗（斗殴），急救，两项社交技能（取悦、话术、恐吓、说服），聆听，心理学，潜行。 | H16: 敏捷 | I16: × | J16: =IF(I16="√",2,0) -> 0 | K16: 医护人员，患者和患者家属。允许接触医疗记录、药品或其他医疗用品。 | M16: 尽管少数富有的人会选择私人疗养院，大多精神病患者最终会被安置到州县设置的定点医院。这些地方除了医生护士以外，还会有一支看护队伍。选聘看护的时候，力量和体格往往比医学知识更被看重。
A17: 15 | B17: 运动员 | D17: 9-70 | E17: 教育×2＋力量或敏捷×2 | F17: =附表!N14*2+MAX(附表!G14*2,附表!J14*2) -> 310 | G17: 攀爬，跳跃，格斗（斗殴），骑乘，一项社交技能（取悦、话术、恐吓、说服），游泳，投掷，任意一项其他个人或时代特长。 | H17: 体质 | I17: × | J17: =IF(I17="√",2,0) -> 0 | K17: 体育界，体育专栏作家，其他明星。 | M17: 运动员可能效力于职业的棒球、足球、板球或者篮球队伍。这支队伍也许是大联盟队伍，有着稳定工资，参加的比赛万人瞩目；或者是众多小联盟队伍之一，尤其是在1920 年代的棒球界。这些队伍往往寄于大联盟队伍篱下，各方面都受其管理，工资更是刚够运动员糊口又不至于让他们跳槽的水平。 成功的运动员在自己的专业领域会拥有相当的声誉——现今尤其如此，在世界各地都能看到体育明星和电影明星并肩站在红地毯上的场景。
A18: 16 | B18: 作家（原作向） | D18: 9-30 | E18: 教育×4 | F18: =附表!N14*4 -> 260 | G18: 技艺（文学），历史，图书馆，自然或神秘学，外语，母语，心理学，任意一项其他个人或时代特长。 | H18: 体型 | I18: × | J18: =IF(I18="√",2,0) -> 0 | K18: 出版社，文学评论家，历史学家等。 | M18: 作家不同于记者，他们用文字定义和探讨人们的社会生活，尤其是人们的情感变化。他们的劳动通常孤立而又自我中心：虽然以前写作是个能稳拿工资的行当，但如今只靠写作发大财的人屈指可数。 作家的工作习惯相差极大。通常作家们会花费数月乃至数年的时间调查取材，为新书的创作做准备；然后闭门谢客，投入紧张的创作。
A19: 17 | B19: 酒保 | D19: 8-25 | E19: 教育×2＋外貌×2 | F19: =附表!N14*2+附表!K14*2 -> 260 | G19: 会计，两项社交技能（取悦、话术、恐吓、说服），格斗（斗殴），聆听，心理学，侦查，任意一项其他个人或时代特长。 | H19: 外貌 | I19: × | J19: =IF(I19="√",2,0) -> 0 | K19: 常客，可能有犯罪组织。 | M19: 酒保虽然不一定是酒吧的掌柜，却一定是所有客人的朋友。对客人们的好声气，一部分来说是出于他们的职业或者业务，而更多的来说则是达到目的的一种手段。 1920 年代，由于禁酒令的存在，酒保变成了非法的职业；但是遍地开花的黑酒吧又不能没有酒保，结果就是酒保仍然不愁找不到活干。
A20: 18 | B20: 猎人 | D20: 20-50 | E20: 教育×2＋力量或敏捷×2 | F20: =附表!N14*2+MAX(附表!G14*2,附表!J14*2) -> 310 | G20: 射击，聆听或侦查，自然，导航，外语或生存（任一），科学（生物学或植物学），潜行，追踪。 | H20: 智力 | I20: × | J20: =IF(I20="√",2,0) -> 0 | K20: 外国政府官员，狩猎监管人员，前客户(大多很有钱)，黑市商人与黑社会，动物园主。 | M20: 猎人是优秀的追踪者和狩猎者，通常靠为富裕的客户捕猎为生。绝大多数猎人会对地球上某一个部分的情况烂熟于心，比如加拿大森林、非洲草原等等。有些人可能从事盗猎活动，例如为私人收藏家捕捉珍稀动物，或者贩卖受保护的动物和违反道德的动物制品，如兽皮、象牙之类——虽然1920 年代大多数国家这些活动都不算违法。 尽管“王牌猎人”是最典型的类型，不过在加拿大育空的深山老林里打驼鹿和熊为生的土著人也可以算是猎人。
A21: 19 | B21: 书商 | D21: 20-40 | E21: 教育×4 | F21: =附表!N14*4 -> 260 | G21: 会计，估价，汽车驾驶，历史，图书馆，母语，外语，一项社交技能（取悦、话术、恐吓、说服）。 | H21: 教育 | I21: √ | J21: =IF(I21="√",IF(SUM(J15:J20,J22:J23)>0,2,4),0) -> 4 | K21: 目录学家、其他书商、图书馆和大学、客户。 | M21: 书商可能拥有自己的店面或者利基(小众)邮购服务，也可能辗转全国甚至海外专门经销书籍。许多人拥有富有的，能提供利润丰厚又稀罕的工作的固定客户。
A22: 20 | B22: 赏金猎人 | D22: 9-30 | E22: 教育×2＋力量或敏捷×2 | F22: =附表!N14*2+MAX(附表!G14*2,附表!J14*2) -> 310 | G22: 汽车驾驶，电子学或电气维修，格斗或射击，一项社交技能（取悦、话术、恐吓、说服），法律，心理学，追踪，潜行。 | H22: 意志 | I22: × | J22: =IF(I22="√",2,0) -> 0 | K22: 保释业者，本地警察，线人。 | M22: 赏金猎人捉拿罪犯并将他们交给正义去审判。最常见的情况是受保释人的委托去缉捕逃狱者。赏金猎人们为了自己的猎物可以不择手段，几乎不会考虑其他人的正当权益之类细枝末节的东西。 非法闯入、威胁、肢体暴力，都是赏金猎人屡试不爽的秘技。现在这些秘技还包括了电话窃听、黑客操作和其他的秘密监控。 (译注：所谓保释业者。向法院交纳保释金，可以在审判之前免受收押；若被保释者按时接受审判，法院会退还保释金。保释金数额较大，故有保释业者以提供保释金收取手续费为业。)
A23: 21 | B23: 拳击手、摔跤手 | D23: 9-60 | E23: 教育×2＋力量×2 | F23: =附表!N14*2+附表!G14*2 -> 310 | G23: 闪避，格斗（斗殴），恐吓，跳跃，心理学，侦查，任意两项其他个人或时代特长。 | H23: 幸运 | I23: × | J23: =IF(I23="√",2,0) -> 0 | K23: 运动会主办者，记者，犯罪组织，专业训练人员。 | M23: 拳击手和摔跤手各分为职业和业余两种。 职业拳击手和职业摔角手的活动由外部利益支持的贸助人安排，并有合同约束。他们还要进行全日制的工作和训练。 业余拳击的竞赛种类非常丰富，同时它也是那些想成为职业拳手的人的训练场。不过也有业余和准职业的选手靠参加黑市拳击赛谋生，举办这些比赛的通常是本地的黑社会或者是从中渔利的庄家。
A24: 22 | B24: 管家、男仆、女仆 | D24: 9-40 | E24: 教育×4 | F24: =附表!N14*4 -> 260 | G24: 会计或估价，技艺（任一：如烹饪、裁缝、理发），急救，聆听，外语，心理学，侦查，任意一项其他个人或时代特长。 | H24: 计算方式
A25: 23 | B25: 神职人员 | D25: 9-60 | E25: 教育×4 | F25: =附表!N14*4 -> 260 | G25: 会计，历史，图书馆，聆听，外语，一项社交技能（取悦、话术、恐吓、说服），心理学，任意一项其他技能。 | H25: 所有属性的点数相加 | K25: 教会高层、地方教会、小区领导。 | M25: 神职人员通常担任一个教区的牧师，或是经过分配外出传教，尤其是去国外(见传教士)。 不同的教会工作的侧重点和组织结构各不相同，如天主教会的牧师可能上升到主教、大主教和红衣主教，而一个卫理公会的牧师则会升职到教区主管和主教。 许多神职人员都接受忏悔(不仅仅是天主教)。虽然不能透露忏悔的内容，但是要怎样利用它们就全凭他们自己了。 有些教职人员在教堂接受医生、律师、学者的专业培训。这样的调查员应该选择最符合自己工作的职业模板。
A26: 24 | B26: 程序员、电子工程师（现代） | D26: 10-70 | E26: 教育×4 | F26: =附表!N14*4 -> 260 | G26: 计算机，电气维修，电子学、图书馆，科学（数学），侦查，任意两项其他个人或时代特长。 | K26: 其他IT 工作者，同事和上司，专业网络小区。 | M26: 计算器程序员通常是设计、编写、测试、调试和维护计算器程序源代码的职业。他们精通从形式逻辑到系统平台(程序运行环境)的各种知识，可能是自由工作者，也可能供职于软件开发部门。 计算器技术人员负责计算器系统和网络的开发和维护工作，经常与其他人员(如项目经理)合作来保证系统的完整稳定和正常提供所需功能。类似的职业还包括数据库管理员、系统管理员、网络管理员、多媒体开发人员、软件工程师、网络管理员等。
A27: 25 | B27: 黑客/骇客（现代） | D27: 10-70 | E27: 教育×4 | F27: =附表!N14*4 -> 260 | G27: 计算机，电气维修，电子学，图书馆，侦查，一项社交技能（取悦、话术、恐吓、说服），任意两项其他技能。 | K27: 其他IT 工作者，专业网络小区，政治团体，犯罪组织。 | M27: 计算器黑客利用计算器和计算器网络为手段，进行干扰或破坏以达成政治目的(有时被称为“政治黑客”)或获取非法利益。达成目标的手段主要是非法入侵计算器和其他用户帐户，目的则可能包括篡改网页、人肉搜索、盗取身份信息、垃圾邮件炸弹、拒绝服务攻击等等。
A28: 26 | B28: 牛仔 | D28: 9-20 | E28: 教育×2＋力量或敏捷×2 | F28: =附表!N14*2+MAX(附表!G14*2,附表!J14*2) -> 310 | G28: 闪避，格斗或射击，急救或自然，跳跃，骑乘，生存（任一），投掷，追踪。 | K28: 本地企业家，州农业部门，牛仔比赛主办者，艺人。 | M28: 牛仔在西部的牧区和牧场工作。有些人拥有自己的牧场，更多的则是在各处打工为生。想赚大钱的牛仔会去冒着丢胳膊少腿乃至送命的危险参加牛仔巡回赛，通过旅行获取名誉。 在1920 年代，一些牛仔能在好莱坞找到西部片替身演员和群众演员的工作，例如怀特·厄普就曾为西部电影担任顾问。在现代，有些牧场也对想要体验一把牛仔生活的游客开放。
A29: 27 | B29: 工匠 | D29: 10-40 | E29: 教育×2＋敏捷×2 | F29: =附表!N14*2+附表!J14*2 -> 210 | G29: 会计，技艺（任二），机械维修，自然，侦查，任意两项其他个人或时代特长。 | K29: 本地商人，其他工匠和艺术家。 | M29: 工匠也可能被人叫做师傅或大师，是擅长对各种材料进行手工加工的人。通常都是才能出众的人，有的凭借自己的艺术作品出名，有的则会服务于自己的小区。 可能的行当包括：家具、珠宝、钟表、陶艺、锻造、纺织、书法、裁缝、木工、书籍装裱、玩具制造、彩色玻璃吹制等等。
A30: 28 | B30: 罪犯-刺客 | D30: 30-60 | E30: 教育×2＋力量或敏捷×2 | F30: =附表!N14*2+MAX(附表!G14*2,附表!J14*2) -> 310 | G30: 乔装，电气维修，格斗，射击，锁匠，机械维修，潜行，心理学。 | K30: 很少，大都是黑社会的人，人们尽量避免和他们交情过深。 | M30: 杀手是地下世界的冷血夺命者。这是一项严谨的活计，他们从外地受雇杀人，接近目标，果断下手，又迅速离开。杀手通常很难融入社会，因为很多杀手行为总是很刻板，其他人很容易以为他们不近人情。但是另一方面，他们也会结婚生子，在其他方面和普通人没有什么不同。
A31: 29 | B31: 罪犯-银行劫匪 | D31: 5-75 | E31: 教育×2＋力量或敏捷×2 | F31: =附表!N14*2+MAX(附表!G14*2,附表!J14*2) -> 310 | G31: 汽车驾驶，电气维修或机械维修，格斗，射击，恐吓，锁匠，操作重型机械，任意一项其他个人或时代特长。 | K31: 同伙(不论是现在还是以前的)，独行罪犯，犯罪组织。 | M31: 罪犯的体格和相貌形形色色，有些是纯粹碰运气伺机行事，比如扒手和暴徒；有些则组成分工明确，会详细调查并制定计划的犯罪组织。后者包括银行劫匪、飞贼、赝造者和诈骗者。 罪犯可能为别人工作，后者通常是“匪帮”或罪犯家族；也可能单打独斗，如果成功的报酬值得去费力冒险，才会和别人搭伙。自由犯罪者则往往被称为抢劫犯、响马贼和江洋大盗。
A32: 30 | B32: 罪犯-打手、暴徒 | D32: 5-30 | E32: 教育×2＋力量×2 | F32: =附表!N14*2+附表!G14*2 -> 310 | G32: 汽车驾驶，格斗，射击，两项社交技能（取悦、话术、恐吓、说服），心理学，潜行，侦查。 | K32: 犯罪组织，本地执法机构，本地企业。 | M32: 打手、暴徒都是犯罪组织的兵卒。他们被犯罪组织豢养，不过团伙上层出事的时候，倒霉的往往是他们这些喽啰。对于他们来说，嘴紧和忠心属于职业道德。
A33: 31 | B33: 罪犯-窃贼 | D33: 5-40 | E33: 教育×2＋敏捷×2 | F33: =附表!N14*2+附表!J14*2 -> 210 | G33: 估价，攀爬，电气维修或机械维修，聆听，锁匠，妙手，潜行，侦查。 | K33: 赃物贩子，其他的盗贼。 | M33: 罪犯的体格和相貌形形色色，有些是纯粹碰运气伺机行事，比如扒手和暴徒；有些则组成分工明确，会详细调查并制定计划的犯罪组织。后者包括银行劫匪、飞贼、赝造者和诈骗者。 罪犯可能为别人工作，后者通常是“匪帮”或罪犯家族；也可能单打独斗，如果成功的报酬值得去费力冒险，才会和别人搭伙。自由犯罪者则往往被称为抢劫犯、响马贼和江洋大盗。
A34: 32 | B34: 罪犯-欺诈师 | D34: 10-65 | E34: 教育×2＋外貌×2 | F34: =附表!N14*2+附表!K14*2 -> 260 | G34: 估价，技艺（表演），法律或外语，聆听，两项社交技能（取悦、话术、恐吓、说服），心理学，妙手。 | K34: 其他的诈骗师，独行罪犯。 | M34: 欺诈师通常都是油嘴滑舌的人物。他们或单独或集体出没在富裕的人家和小区周边，诈取他们来之不易的钱财。许多骗局覆杂精妙，诈骗团伙会倾巢出动乃至租用建筑；有些则不需要这么麻烦，只要一个骗子几分钟就能搞定。
A35: 33 | B35: 罪犯-独行罪犯 | D35: 5-65 | E35: 教育×2＋敏捷或外貌×2 | F35: =附表!N14*2+MAX(附表!J14*2,附表!K14*2) -> 260 | G35: 技艺（表演）或乔装，估价，一项社交技能（取悦、话术、恐吓、说服），格斗或射击，锁匠或机械维修，潜行，心理学，侦查。 | K35: 轻罪罪犯，本地执法机构。 | M35: 罪犯的体格和相貌形形色色，有些是纯粹碰运气伺机行事，比如扒手和暴徒；有些则组成分工明确，会详细调查并制定计划的犯罪组织。后者包括银行劫匪、飞贼、赝造者和诈骗者。 罪犯可能为别人工作，后者通常是“匪帮”或罪犯家族；也可能单打独斗，如果成功的报酬值得去费力冒险，才会和别人搭伙。自由犯罪者则往往被称为抢劫犯、响马贼和江洋大盗。
A36: 34 | B36: 罪犯-女飞贼（古典） | D36: 10-80 | E36: 教育×2＋外貌×2 | F36: =附表!N14*2+附表!K14*2 -> 260 | G36: 技艺（任意），两项社交技能（取悦、话术、恐吓、说服），格斗（斗殴）或射击（手枪），汽车驾驶，聆听，潜行，任意一项其他个人或时代特长。 | K36: 黑帮，执法机构，本地企业 | M36: 女飞贼是名为专业大盗的女人。大部分都是独立行动，也有对自己的男伴言听计从的时候。 不过这也不一定，实际上情况可能完全相反，她完全可以在干了某一票以后就卷走所有现金和皮草溜之大吉。
A37: 35 | B37: 罪犯-赃物贩子 | D37: 20-40 | E37: 教育×2＋外貌×2 | F37: =附表!N14*2+附表!K14*2 -> 260 | G37: 会计，估价，技艺（伪造），历史，一项社交技能（取悦、话术、恐吓、说服），图书馆，侦查，任意一项其他技能。 | K37: 犯罪组织，贸易伙伴，黑市和和守法的买主。 | M37: 赃物贩子，顾名思义是买卖偷抢来的财产，通常是收购赃物并转手卖给其他罪犯或(无意中)守法的顾客。主要来说，他们是小偷和买家的中间人，有时也会从交易中收取提成；不过更常见的还是以极低的价格直接收购赃物。
A38: 36 | B38: 罪犯-赝造者 | D38: 20-60 | E38: 教育×4 | F38: =附表!N14*4 -> 260 | G38: 会计，估价，技艺（伪造），历史，图书馆，侦查，妙手，任意一项其他个人或时代特长（如计算机）。 | K38: 犯罪组织，商人。 | M38: 赝造者是地下世界的艺术家，专门从事伪造官方文件、契约、转让书，并提供伪造的签名。初学者只能做做小贼的假身份证，而顶级的赝造者连印假币的铸模都能做。
A39: 37 | B39: 罪犯-走私者 | D39: 20-60 | E39: 教育×2＋外貌或敏捷×2 | F39: =附表!N14*2+MAX(附表!J14*2,附表!K14*2) -> 260 | G39: 射击，聆听，导航，一项社交技能（取悦、话术、恐吓、说服），汽车驾驶或驾驶（飞行器或船），心理学，妙手，侦查。 | K39: 犯罪组织，海岸卫队，海关官员。 | M39: 走私一直是一个有利可图的高风险行当。走私者往往有一个合法的表面职业，比如船长、飞行员或商人，以掩盖他们非法运输的行为。
A40: 38 | B40: 罪犯-混混 | D40: 3-10 | E40: 教育×2＋力量或敏捷×2 | F40: =附表!N14*2+MAX(附表!G14*2,附表!J14*2) -> 310 | G40: 攀爬，一项社交技能（取悦、话术、恐吓、说服），格斗，射击，跳跃，妙手，潜行，投掷。 | K40: 其他轻罪罪犯，其他混混，本地的赃物贩子，黑帮，当然还有警察。 | M40: 街头混混一般都是些小年轻，弄不好还在寻觅加入真正黑帮的契机。不过他们的本事也就限于偷车，盗窃商店货物，抢钱或者夜盗。
...

Sheet 成长表（测试）
B1: 技能成长表
A2: 技能 | B2: 总计成长 | C2: 初始 | D2: 请填入模组名称 | E2: 模组2 | F2: 模组3 | G2: 模组4 | H2: 模组5 | I2: 模组6 | J2: 模组7 | K2: 模组8 | L2: 模组9 | M2: 模组10 | N2: 模组11 | O2: 模组12 | P2: 模组13 | Q2: 模组14 | R2: 模组15 | S2: 模组16 | T2: 模组17 | U2: 模组18 | V2: 模组19 | W2: 模组20 | X2: 模组21 | Y2: 模组22 | Z2: 模组23 | AA2: 模组24 | AB2: 模组25 | AC2: 模组26 | AD2: 模组27 | AE2: 模组28 | AF2: 模组29 | AG2: 模组30 | AH2: 模组31 | AI2: 模组32 | AJ2: 模组33 | AK2: 模组34 | AL2: 模组35 | AM2: 模组36 | AN2: 模组37 | AO2: 模组38 | AP2: 模组39 | AQ2: 模组40 | AR2: 模组41 | AS2: 模组42 | AT2: 模组43 | AU2: 模组44 | AV2: 模组45 | AW2: 模组46 | AX2: 模组47 | AY2: 模组48 | AZ2: 模组49 | BA2: 模组50 | BB2: 模组51 | BC2: 模组52 | BD2: 模组53 | BE2: 模组54 | BF2: 模组55 | BG2: 模组56 | BH2: 模组57 | BI2: 模组58 | BJ2: 模组59 | BK2: 模组60 | BL2: 模组61 | BM2: 模组62 | BN2: 模组63 | BO2: 模组64 | BP2: 模组65 | BQ2: 模组66 | BR2: 模组67 | BS2: 模组68 | BT2: 模组69 | BU2: 模组70 | BV2: 模组71 | BW2: 模组72 | BX2: 模组73 | BY2: 模组74 | BZ2: 模组75 | CA2: 模组76 | CB2: 模组77 | CC2: 模组78 | CD2: 模组79 | CE2: 模组80 | CF2: 模组81 | CG2: 模组82 | CH2: 模组83 | CI2: 模组84 | CJ2: 模组85 | CK2: 模组86 | CL2: 模组87 | CM2: 模组88 | CN2: 模组89 | CO2: 模组90 | CP2: 模组91 | CQ2: 模组92 | CR2: 模组93 | CS2: 模组94 | CT2: 模组95 | CU2: 模组96 | CV2: 模组97 | CW2: 模组98 | CX2: 模组99 | CY2: 模组100
A3: 会计 | B3: =SUM(D3:CY3) -> 0 | C3: 5 | D3: 请填入成长数值
A4: 人类学 | B4: =SUM(D4:CY4) -> 0 | C4: 1 | D4: 后面依次类推哦
A5: 估价 | B5: =SUM(D5:CY5) -> 0 | C5: 5 | D5: 0
A6: 考古学 | B6: =SUM(D6:CY6) -> 1 | C6: 1 | D6: 1
A7: 技艺① | B7: =SUM(D7:CY7) -> 2 | C7: 5 | D7: 2
A8: 技艺② | B8: =SUM(D8:CY8) -> 0 | C8: 5 | D8: 以上这些是示例
A9: 技艺③ | B9: =SUM(D9:CY9) -> 0 | C9: 5
A10: 取悦 | B10: =SUM(D10:CY10) -> 0 | C10: 15
A11: 攀爬 | B11: =SUM(D11:CY11) -> 0 | C11: 20
A12: 计算机使用 Ω | B12: =SUM(D12:CY12) -> 0 | C12: 5
A13: 信用评级 | B13: =SUM(D13:CY13) -> 0 | C13: 0
A14: 克苏鲁神话 | B14: =SUM(D14:CY14) -> 0 | C14: 0
A15: 乔装 | B15: =SUM(D15:CY15) -> 0 | C15: 5
A16: 闪避 | B16: =SUM(D16:CY16) -> 0 | C16: 0
A17: 汽车驾驶 | B17: =SUM(D17:CY17) -> 0 | C17: 20
A18: 电气维修 | B18: =SUM(D18:CY18) -> 0 | C18: 10
A19: 电子学 Ω | B19: =SUM(D19:CY19) -> 0 | C19: 1
A20: 话术 | B20: =SUM(D20:CY20) -> 0 | C20: 5
... A68: 学识： | B68: =SUM(D68:CY68) -> 0 | C68: 1
A69: 自定义技能 | B69: =SUM(D69:CY69) -> 0
A70: 自定义技能 | B70: =SUM(D70:CY70) -> 0
A71: STR | B71: =SUM(D71:CY71) -> 0
A72: CON | B72: =SUM(D72:CY72) -> 0
A73: SIZ | B73: =SUM(D73:CY73) -> 0
A74: DEX | B74: =SUM(D74:CY74) -> 0
A75: APP | B75: =SUM(D75:CY75) -> 0
A76: INT | B76: =SUM(D76:CY76) -> 0
A77: POW | B77: =SUM(D77:CY77) -> 0
A78: EDU | B78: =SUM(D78:CY78) -> 0
A79: 幸运 | B79: =SUM(D79:CY79) -> 0
A80: 理智 | B80: =SUM(D80:CY80) -> 0
B81: =SUM(D81:CY81) -> 0
B82: =SUM(D82:CY82) -> 0
B83: =SUM(D83:CY83) -> 0
B84: =SUM(D84:CY84) -> 0
B85: =SUM(D85:CY85) -> 0
B86: =SUM(D86:CY86) -> 0
B87: =SUM(D87:CY87) -> 0
...

Sheet 本职技能
B1: 0 | C1: 1 | D1: 2 | E1: 3 | F1: 4 | G1: 5 | H1: 6 | I1: 7 | J1: 8 | K1: 9 | L1: 10 | M1: 11 | N1: 12 | O1: 13 | P1: 14 | Q1: 15 | R1: 16 | S1: 17 | T1: 18 | U1: 19 | V1: 20 | W1: 21 | X1: 22 | Y1: 23 | Z1: 24 | AA1: 25 | AB1: 26 | AC1: 27 | AD1: 28 | AE1: 29 | AF1: 30 | AG1: 31 | AH1: 32 | AI1: 33 | AJ1: 34 | AK1: 35 | AL1: 36 | AM1: 37 | AN1: 38 | AO1: 39 | AP1: 40 | AQ1: 41 | AR1: 42 | AS1: 43 | AT1: 44 | AU1: 45 | AV1: 46 | AW1: 47 | AX1: 48 | AY1: 49 | AZ1: 50 | BA1: 51 | BB1: 52 | BC1: 53 | BD1: 54 | BE1: 55 | BF1: 56 | BG1: 57 | BH1: 58 | BI1: 59 | BJ1: 60 | BK1: 61 | BL1: 62 | BM1: 63 | BN1: 64 | BO1: 65 | BP1: 66 | BQ1: 67 | BR1: 68 | BS1: 69 | BT1: 70 | BU1: 71 | BV1: 72 | BW1: 73 | BX1: 74 | BY1: 75 | BZ1: 76 | CA1: 77 | CB1: 78 | CC1: 79 | CD1: 80 | CE1: 81 | CF1: 82 | CG1: 83 | CH1: 84 | CI1: 85 | CJ1: 86 | CK1: 87 | CL1: 88 | CM1: 89 | CN1: 90 | CO1: 91 | CP1: 92 | CQ1: 93 | CR1: 94 | CS1: 95 | CT1: 96 | CU1: 97 | CV1: 98 | CW1: 99 | CX1: 100 | CY1: 101 | CZ1: 102 | DA1: 103 | DB1: 104 | DC1: 105 | DD1: 106 | DE1: 107 | DF1: 108 | DG1: 109 | DH1: 110 | DI1: 111 | DJ1: 112 | DK1: 113 | DL1: 114 | DM1: 115 | DN1: 116 | DO1: 117 | DP1: 118 | DQ1: 119 | DR1: 120 | DS1: 121 | DT1: 122 | DU1: 123 | DV1: 124 | DW1: 125 | DX1: 126 | DY1: 127 | DZ1: 128 | EA1: 129 | EB1: 130 | EC1: 131 | ED1: 132 | EE1: 133 | EF1: 134 | EG1: 135 | EH1: 136 | EI1: 137 | EJ1: 138 | EK1: 139 | EL1: 140 | EM1: 141 | EN1: 142 | EO1: 143 | EP1: 144 | EQ1: 145 | ER1: 146 | ES1: 147 | ET1: 148 | EU1: 149 | EV1: 150 | EW1: 151 | EX1: 152 | EY1: 153 | EZ1: 154 | FA1: 155 | FB1: 156 | FC1: 157 | FD1: 158 | FE1: 159 | FF1: 160 | FG1: 161 | FH1: 162 | FI1: 163 | FJ1: 164 | FK1: 165 | FL1: 166 | FM1: 167 | FN1: 168 | FO1: 169 | FP1: 170 | FQ1: 171 | FR1: 172 | FS1: 173 | FT1: 174 | FU1: 175 | FV1: 176 | FW1: 177 | FX1: 178 | FY1: 179 | FZ1: 180 | GA1: 181 | GB1: 182 | GC1: 183 | GD1: 184 | GE1: 185 | GF1: 186 | GG1: 187 | GH1: 188 | GI1: 189 | GJ1: 190 | GK1: 191 | GL1: 192 | GM1: 193 | GN1: 194 | GO1: 195 | GP1: 196 | GQ1: 197 | GR1: 198 | GS1: 199 | GT1: 200 | GU1: 201 | GV1: 202 | GW1: 203 | GX1: 204 | GY1: 205 | GZ1: 206 | HA1: 207 | HB1: 208 | HC1: 209 | HD1: 210 | HE1: 211 | HF1: 212 | HG1: 213 | HH1: 214 | HI1: 215 | HJ1: 216 | HK1: 217 | HL1: 218 | HM1: 219 | HN1: 220 | HO1: 221 | HP1: 222 | HQ1: 223 | HR1: 224 | HS1: 225 | HT1: 226 | HU1: 227 | HV1: 228 | HW1: 229 | HX1: 230
C2: 自定义职业 | D2: 会计师 | E2: 杂技演员 | F2: 演员-戏剧演员 | G2: 演员-电影演员 | H2: 事务所侦探 | I2: 精神病医生（古典） | J2: 动物训练师 | K2: 文物学家（原作向） | L2: 古董商 | M2: 考古学家（原作向） | N2: 建筑师 | O2: 艺术家 | P2: 精神病院看护 | Q2: 运动员 | R2: 作家（原作向） | S2: 酒保 | T2: 猎人 | U2: 书商 | V2: 赏金猎人 | W2: 拳击手、摔跤手 | X2: 管家、男仆、女仆 | Y2: 神职人员 | Z2: 程序员、电子工程师（现代） | AA2: 黑客/骇客（现代） | AB2: 牛仔 | AC2: 工匠 | AD2: 罪犯-刺客 | AE2: 罪犯-银行劫匪 | AF2: 罪犯-打手、暴徒 | AG2: 罪犯-窃贼 | AH2: 罪犯-欺诈师 | AI2: 罪犯-独行罪犯 | AJ2: 罪犯-女飞贼（古典） | AK2: 罪犯-赃物贩子 | AL2: 罪犯-赝造者 | AM2: 罪犯-走私者 | AN2: 罪犯-混混 | AO2: 教团首领 | AP2: 除魅师（现代） | AQ2: 设计师 | AR2: 业余艺术爱好者（原作向） | AS2: 潜水员 | AT2: 医生（原作向） | AU2: 流浪者 | AV2: 司机-私人司机 | AW2: 司机-司机 | AX2: 司机-出租车司机 | AY2: 编辑 | AZ2: 政府官员 | BA2: 工程师 | BB2: 艺人 | BC2: 探险家（古典） | BD2: 农民 | BE2: 联邦探员 | BF2: 消防员 | BG2: 驻外记者 | BH2: 法医 | BI2: 赌徒 | BJ2: 黑帮-黑帮老大 | BK2: 黑帮-马仔 | BL2: 绅士、淑女 | BM2: 游民 | BN2: 勤杂护工 | BO2: 记者(原作向)-调查记者 | BP2: 记者(原作向)-通讯记者 | BQ2: 法官 | BR2: 实验室助理 | BS2: 非熟练工人 | BT2: 工人-伐木工 | BU2: 工人-矿工 | BV2: 律师 | BW2: 图书馆管理员（原作向） | BX2: 技师 | BY2: 军官 | BZ2: 传教士 | CA2: 登山家 | CB2: 博物馆管理员 | CC2: 音乐家 | CD2: 护士 | CE2: 神秘学家 | CF2: 旅行家 | CG2: 超心理学家 | CH2: 药剂师 | CI2: 摄影师-摄影师 | CJ2: 摄影师-摄影记者 | CK2: 飞行员-飞行员 | CL2: 飞行员-特技飞行员（古典） | CM2: 警方(原作向)-警探 | CN2: 警方(原作向)-巡警 | CO2: 私家侦探 | CP2: 教授（原作向） | CQ2: 淘金客 | CR2: 性工作者 | CS2: 精神病学家 | CT2: 心理学家、精神分析学家 | CU2: 研究员 | CV2: 海员-军舰海员 | CW2: 海员-民船海员 | CX2: 推销员 | CY2: 科学家 | CZ2: 秘书 | DA2: 店老板 | DB2: 士兵、海军陆战队士兵 | DC2: 间谍 | DD2: 学生、实习生 | DE2: 替身演员 | DF2: 部落成员 | DG2: 殡葬师 | DH2: 工会活动家 | DI2: 服务生 | DJ2: 白领工人-职员、主管 | DK2: 白领工人-中高层管理人员 | DL2: 狂热者 | DM2: 饲养员 | DN2: 大使 | DO2: 运动员（游泳/潜水） | DP2: 运动员（高尔夫） | DQ2: 运动员（网球） | DR2: 运动员（田径） | DS2: 发言人 | DT2: 保释担保人 | DU2: 神职人员(天主教牧师) | DV2: 神职人员(新教牧师) | DW2: 神职人员(犹太教拉比) | DX2: 专栏作家 | DY2: 社会主义者/激进主义者 | DZ2: 撰稿人 | EA2: 罪犯（赌博庄家） | EB2: 罪犯（放高利贷者） | EC2: 罪犯（扒手） | ED2: 罪犯（地下钱庄） | EE2: 罪犯（黑律师） | EF2: 牙医 | EG2: 外科医生/内科医生 | EH2: 整形医生 | EI2: 司机-公交司机 | EJ2: 实地调研员 | EK2: 电影摄制人员 | EL2: 司法家 | EM2: 运动经理 | EN2: 商船队船员 | EO2: 古典音乐家 | EP2: 赛车手/赛艇手 | EQ2: 电台播音员 | ER2: 推销员（圣经推销员） | ES2: 推销员（旅行推销员） | ET2: 小企业家 | EU2: 舞台工作人员 | EV2: 证券经纪人 | EW2: 勘测员 | EX2: 电话接线员 | EY2: 星探 | EZ2: 医疗技术员 | FA2: 队医 | FB2: 寻宝猎人 | FC2: 西部治安官 | FD2: 暴走族 | FE2: 神职人员(和尚,尼姑) | FF2: 神职人员(神官,巫女) | FG2: 风水师 | FH2: 家传降妖人 | FI2: 高中生(教育60以下) | FJ2: 市子（盲人） | FK2: 言灵师/阴阳师 | FL2: 炼丹师 | FM2: 外语教师 | FN2: 非法移民 | FO2: 相扑力士(SIZ>80,STR>70) | FP2: 渔民 | FQ2: 心理治疗师 | FR2: 女学生 | FS2: 寄居学生 | FT2: 动物辅助治疗师 | FU2: 急诊医生/救援队员 | FV2: 密医 | FW2: 科学搜查研究员 | FX2: 山岳救援队员 | FY2: 舞者 | FZ2: 服装设计师 | GA2: 海上自卫队员 | GB2: 海警 | GC2: 陆上自卫队员 | GD2: 私人军事公司成员 | GE2: 冒险家教授 | GF2: 评论家 | GG2: 偶像 | GH2: 歌手 | GI2: 搞笑艺人 | GJ2: 运动员艺人 | GK2: 播音员 | GL2: 主持人 | GM2: 电视解说员 | GN2: 网络明星 | GO2: 经纪人 | GP2: 捉鬼人 | GQ2: 占卜师、灵媒师 | GR2: 机械师 | GS2: 厨师 | GT2: 网络犯罪者 | GU2: 佣兵 | GV2: 自宅警备员 | GW2: 壮汉保镖 | GX2: 游戏测试员 | GY2: 交际花 | GZ2: 考古学家 | HA2: 贵族 | HB2: 艺术家 | HC2: 作家 | HD2: 马车夫 | HE2: 牧师 | HF2: 咨询侦探 | HG2: 工匠 | HH2: 罪犯 | HI2: 业余艺术爱好者 | HJ2: 艺人 | HK2: 退役军官 | HL2: 探险家 | HM2: 私家侦探 | HN2: 记者 | HO2: 劳工 | HP2: 律师 | HQ2: 医生 | HR2: 警察 | HS2: 教授/学者 | HT2: 科学家 | HU2: 佣人 | HV2: 店主 | HW2: 士兵 | HX2: 密探
A3: ☆ | M3: 1 | N3: 1 | O3: 1 | R3: 1 | T3: 1 | V3: 1 | X3: 1 | AB3: 1 | AE3: 1 | AG3: 1 | AH3: 1 | AI3: 1 | AJ3: 1 | AM3: 1 | AP3: 1 | AQ3: 1 | BC3: 1 | BM3: 1 | BR3: 1 | BT3: 1 | CM3: 1 | CN3: 1 | CV3: 1 | CX3: 1 | CY3: 1 | CZ3: 1 | DB3: 1 | DC3: 1 | DD3: 1 | DE3: 1 | DF3: 1 | DJ3: 1 | EJ3: 1 | EN3: 1 | ER3: 1 | FB3: 1 | FC3: 1 | FE3: 1 | FI3: 1 | FJ3: 1 | FL3: 1 | FZ3: 1 | GC3: 1 | GD3: 1 | GE3: 1 | GF3: 1 | GU3: 1 | GW3: 1 | GY3: 1 | HK3: 1
A4: ⊙ | T4: 1 | V4: 1 | AB4: 1 | AI4: 1 | CZ4: 1
A5: ☯ | F5: 2 | G5: 2 | H5: 1 | K5: 1 | L5: 2 | O5: 1 | P5: 2 | Q5: 1 | S5: 2 | U5: 1 | V5: 1 | Y5: 1 | AA5: 1 | AF5: 2 | AH5: 2 | AI5: 1 | AJ5: 2 | AK5: 1 | AM5: 1 | AN5: 1 | AO5: 2 | AP5: 2 | AR5: 2 | AU5: 1 | AV5: 2 | AW5: 1 | AY5: 2 | BB5: 2 | BD5: 1 | BG5: 2 | BI5: 2 | BJ5: 2 | BK5: 2 | BL5: 2 | BN5: 1 | BO5: 1 | BP5: 1 | BV5: 2 | BY5: 2 | BZ5: 1 | CC5: 1 | CD5: 1 | CE5: 1 | CH5: 1 | CI5: 1 | CJ5: 1 | CM5: 1 | CO5: 1 | CR5: 2 | CU5: 1 | CW5: 1 | CX5: 2 | CY5: 1 | CZ5: 2 | DA5: 2 | DC5: 1 | DG5: 1 | DH5: 2 | DI5: 2 | DJ5: 1 | DK5: 2 | DL5: 2 | DO5: 1 | DP5: 1 | DQ5: 1 | DR5: 1 | DS5: 3 | DT5: 2 | DU5: 1 | DV5: 1 | DW5: 1 | DX5: 1 | DY5: 2 | DZ5: 2 | EA5: 2 | EB5: 2 | EC5: 1 | EE5: 2 | EI5: 1 | EJ5: 1 | EK5: 1 | EM5: 2 | EO5: 1 | ER5: 2 | ES5: 2 | ET5: 2 | EU5: 2 | EV5: 2 | EX5: 2 | EY5: 2 | FA5: 2 | FB5: 1 | FE5: 1 | FF5: 1 | FG5: 1 | FM5: 2 | FQ5: 2 | FR5: 1 | FV5: 1 | FY5: 2 | GB5: 1 | GF5: 1 | GG5: 2 | GH5: 2 | GI5: 2 | GN5: 2 | GO5: 2 | GP5: 1 | GQ5: 2 | GT5: 1 | GW5: 1 | GX5: 1 | GY5: 1 | GZ5: 1 | HC5: 1 | HD5: 1 | HE5: 1 | HG5: 1 | HH5: 1 | HJ5: 2 | HK5: 1 | HM5: 2 | HN5: 2 | HP5: 2 | HR5: 1 | HS5: 1 | HT5: 1 | HV5: 1 | HX5: 1
A6: ※ | AI6: 1 | DB6: 1 | DE6: 1 | GC6: 1 | GD6: 1 | GU6: 1 | HO6: 1 | HU6: 1
