Workbook
Name APP: 人物卡!$AA$5
Name CON: 人物卡!$U$5
Name DEX: 人物卡!$AA$3
Name EDU: 人物卡!$AG$5
Name INT: 人物卡!$AA$7
Name Luck: 人物卡!$AG$7
Name MP: 人物卡!$W$10
Name POW: 人物卡!$AG$3
Name SIZ: 人物卡!$U$7
Name STR: 人物卡!$U$3

Sheet 人物卡
B1: 彩色-黑红色 欢迎使用！建议用wps打开 可能会有小bug 如果发现了欢迎来群里联系作者（657573844）
B2: 调查员信息 | S2: 年龄补正： | V2: =附表!D37 -> 教育进步*1 | AA2: 属性 | AC2: 总点数(不含运): | AG2: =IF(AC2="总点数(含运):",U3+U5+U7+AA3+AA5+AA7+AG3+AG5+AG7,U3+U5+U7+AA7+AA5+AA3+AG3+AG5) -> 480 | AU2: 调查员可能
B3: 姓名 | E3: 尤金 | J3: 玩家 | M3: 文月 | S3: 力量 STR | U3: 30 | W3: =INT(U3/2) -> 15 | Y3: 敏捷 DEX | AA3: 70 | AC3: =INT(AA3/2) -> 35 | AE3: 意志 POW | AG3: 60 | AI3: =INT(AG3/2) -> 30 | AU3: =IF(U3=0,"",IF(U3<=15,"虚弱，孱弱",IF(U3<=40,"力量弱小",IF(U3<=60,"有正常人的力量",IF(U3<=80,"超乎常人的力量",IF(U3<100,"超乎超乎常人的力量")))))) -> 力量弱小 | BC3: =IF(AA3=0,"",IF(AA3<=20,"很不灵活",IF(AA3<=40,"不是很灵活",IF(AA3<=60,"普通人水平",IF(AA3<=80,"是一位运动健将",IF(AA3<100,"高速而灵活,可以达成超凡的技艺")))))) -> 是一位运动健将 | BK3: =IF(AG3=0,"",IF(AG3<=20,"尔不过玩物",IF(AG3<=40,"痴愚盲目",IF(AG3<=60,"如常人一般会有一定自制力",IF(AG3<=80,"我心如铁，心坚石穿",IF(AG3<100,"泰山崩于面而色不变",IF(AG3<140,"钢铁之心，还能看见鬼","你怕是个假人吧"))))))) -> 如常人一般会有一定自制力
B4: 年龄 | E4: 29 | J4: 时代 | M4: 1920s | W4: =INT(U3/5) -> 6 | AC4: =INT(AA3/5) -> 14 | AI4: =INT(AG3/5) -> 12
B5: 职业 | E5: 私家侦探 | J5: 职业序号 | M5: 219 | S5: 体质 CON | U5: 50 | W5: =INT(U5/2) -> 25 | Y5: 外貌 APP | AA5: 80 | AC5: =INT(AA5/2) -> 40 | AE5: 教育 EDU | AG5: 55 | AI5: =INT(AG5/2) -> 27 | AU5: =IF(U5=0,"",IF(U5<=20,"常年患病在身",IF(U5<=40,"体弱多病",IF(U5<=60,"不会生什么大毛病",IF(U5<=80,"健硕，浑身湿透也不会感冒",IF(U5<100,"身体素质极好，精神抖擞")))))) -> 不会生什么大毛病 | BC5: =IF(AA5=0,"",IF(AA5<=20,"用脸就能恐惧敌人。。或队友",IF(AA5<=40,"有些难看",IF(AA5<=60,"人群之中谁也不会看你一眼之后就忘不掉你容颜",IF(AA5<=80,"五官端正，仪表堂堂",IF(AA5<100,"沉鱼落雁，闭月羞花")))))) -> 五官端正，仪表堂堂 | BK5: =IF(AG5=0,"",IF(AG5<=20,"目不识丁",IF(AG5<=40,"小学毕业",IF(AG5<=60,"高中毕业",IF(AG5<=80,"是重点大学的学生，或是普通大学的研究生",IF(AG5<100,"饱读诗书，满腹经纶")))))) -> 高中毕业
B6: 性别 | E6: 男 | J6: 国籍 | M6: 美国 | W6: =INT(U5/5) -> 10 | AC6: =INT(AA5/5) -> 16 | AI6: =INT(AG5/5) -> 11
B7: 住地 | E7: 布鲁克林区 | J7: 故乡 | M7: 纽约 | S7: 体型 SIZ | U7: 55 | W7: =INT(U7/2) -> 27 | Y7: 智力 灵感 | AA7: 80 | AC7: =INT(AA7/2) -> 40 | AE7: 幸运 Luck | AG7: 50 | AI7: =INT(AG7/2) -> 25 | AU7: =IF(U7=0,"",IF(U7<=20,"孩童，身短体瘦",IF(U7<=40,"乙女身材",IF(U7<=60,"普遍身高155-175",IF(U7<=80,"不是高就是胖",IF(U7<=100,"大号的人",IF(U7<150,"听说你正在申请身高世界记录？",IF(U7<180,"你可能是一头牛",IF(U7<200,"你已经是历史上最重的人类了","过分了喂！"))))))))) -> 普遍身高155-175 | BC7: =IF(INT=0,"",IF(INT<=20,"脑子是个好东西，可惜。。。",IF(INT<=40,"理解知识要耗费比普通人更多的时间",IF(INT<=60,"有着普通人的灵光一现",IF(INT<=80,"可以自主进行发明创造",IF(INT<100,"天才级水准")))))) -> 可以自主进行发明创造 | BK7: =IF(Luck=0,"",IF(Luck<=20,"克夫克妻",IF(Luck<=40,"霉运连连",IF(Luck<=60,"命格平庸",IF(Luck<=80,"在马路边捡到100块",IF(Luck<100,"被幸运女神所眷顾")))))) -> 命格平庸
B8: 现时间 | E8: 公元 | G8: 2023 | J8: 1月 | L8: 1日 | N8: 0：00 | W8: =INT(U7/5) -> 11 | AC8: =INT(AA7/5) -> 16 | AI8: =INT(AG7/5) -> 10
B9: =IF(F9=0,"","任意特长数：") -> 任意特长数： | F9: =INDEX(本职技能!$A$2:$IE$68,MATCH("任意特长",本职技能!$A$2:$A$74,0),MATCH(附表!B58,本职技能!$A$1:$IE$1,0)) -> 1 | K9: =INDEX(本职技能!$A$2:$IE$68,MATCH("☆",本职技能!$A$2:$A$74,0),MATCH(附表!B58,本职技能!$A$1:$IE$1,0)) -> 0 | T9: =INDEX(本职技能!$A$2:$IE$68,MATCH("⊙",本职技能!$A$2:$A$74,0),MATCH(附表!B58,本职技能!$A$1:$IE$1,0)) -> 0 | AC9: =INDEX(本职技能!$A$2:$IE$68,MATCH("☯",本职技能!$A$2:$A$74,0),MATCH(附表!B58,本职技能!$A$1:$IE$1,0)) -> 2 | AL9: =INDEX(本职技能!$A$2:$IE$68,MATCH("※",本职技能!$A$2:$A$74,0),MATCH(附表!B58,本职技能!$A$1:$IE$1,0)) -> 0
B10: 体力 Hit Points | E10: =G10 -> 10 | G10: =INT((U5+U7)/10) -> 10 | I10: 状态: | K10: 理智 Sanity | N10: =IF(AG3>P10,P10,AG3) -> 60 | P10: =99-R28 -> 99 | R10: 状态: | T10: 魔法 Magic Points | W10: =Y10 -> 12 | Y10: =INT(AG3/5) -> 12 | AA10: 每h恢复 | AC10: 移动力 MOV | AF10: =AI11+8 -> 8 | AI10: 调整值 | AK10: 护甲 Armor | AN10: =IF($AN12=0,"0",VLOOKUP($AN12,'防具表 载具表'!B2:I101,2,FALSE)) | AR10: 覆盖部位
I11: 健康 | R11: 清醒 | AA11: =IF(AG3="","",INT(AG3/100+1)) -> 1 | AI11: =附表!C9 -> 0 | AR11: =IF($AN12=0,"",VLOOKUP($AN12,'防具表 载具表'!B2:I101,4,FALSE))
B12: 重伤值: | D12: =CEILING(G10/2,1) -> 5 | F12: 临时体力值： | I12: 0 | K12: 今日损失 : | N12: 0 | P12: 剩余： | R12: =N10-N12 -> 60 | T12: 使用过的魔法 : | AC12: 移动方式 | AE12: 步式 | AG12: 护甲减值 | AI12: 关 | AK12: 护甲类型 : | AN12: 请看【防具表】
B13: [0]经历包可选技能： | I13: =附表!B17 -> 会计，两项社交技能（取悦、话术、恐吓、说服），法律，图书馆，聆听，锁匠，艺术及手艺（摄影），侦查，任意一项其他个人或时代特长
B15: 技能表
B16: 成功标 | D16: =附表!G15 -> 经历包 | F16: 技能名称 | J16: 初始 | L16: 成长/经历 | N16: 职业 | P16: 兴趣 | R16: 成功率 普通/困难/极限 | X16: 成功标 | Z16: =附表!G15 -> 经历包 | AB16: 技能名称 | AF16: 初始 | AH16: 成长/经历 | AJ16: 职业 | AL16: 兴趣 | AN16: 成功率 普通/困难/极限
B17: ☐ | D17: =IF(ISTEXT(IFERROR(VLOOKUP(人物卡!F17,人物卡!BJ19:BR23,1,FALSE),IFERROR(VLOOKUP(人物卡!F17,BB19:BB23,1,FALSE),0))),"★",INDEX(本职技能!$A$2:$IE$75,MATCH(人物卡!F17,本职技能!$A$2:$A$74,0),MATCH(附表!B58,本职技能!$A$1:$IE$1,0))) -> ★ | F17: 会计 | J17: 5 | R17: =SUM(J17:P17) -> 5 | T17: =INT(R17/2) -> 2 | V17: =INT(R17/5) -> 1 | X17: ☐ | Z17: =IF(ISTEXT(IFERROR(VLOOKUP(人物卡!AB17,人物卡!BJ19:BR23,1,FALSE),IFERROR(VLOOKUP(人物卡!AB17,人物卡!BB19:BC23,1,FALSE),0))),"★",INDEX(本职技能!$A$2:$IE$75,MATCH(人物卡!AB17,本职技能!$A$2:$A$74,0),MATCH(附表!B58,本职技能!$A$1:$IE$1,0))) -> ★ | AB17: 法律 | AF17: 5 | AN17: =SUM(AF17:AL17) -> 5 | AP17: =INT(AN17/2) -> 2 | AR17: =INT(AN17/5) -> 1
B18: ☐ | D18: =IF(ISTEXT(IFERROR(VLOOKUP(人物卡!F18,BJ19:BJ23,1,FALSE),IFERROR(VLOOKUP(人物卡!F18,BB19:BB23,1,FALSE),0))),"★",INDEX(本职技能!$A$2:$IE$75,MATCH(人物卡!F18,本职技能!$A$2:$A$74,0),MATCH(附表!B58,本职技能!$A$1:$IE$1,0))) -> 0 | F18: 人类学 | J18: 1 | R18: =SUM(J18:P18) -> 1 | T18: =INT(R18/2) -> 0 | V18: =INT(R18/5) -> 0 | X18: ☐ | Z18: =IF(ISTEXT(IFERROR(VLOOKUP(人物卡!AB18,人物卡!BJ19:BR23,1,FALSE),IFERROR(VLOOKUP(人物卡!AB18,人物卡!BB19:BC23,1,FALSE),0))),"★",INDEX(本职技能!$A$2:$IE$75,MATCH(人物卡!AB18,本职技能!$A$2:$A$74,0),MATCH(附表!B58,本职技能!$A$1:$IE$1,0))) -> ★ | AB18: 图书馆使用 | AF18: 20 | AN18: =SUM(AF18:AL18) -> 20 | AP18: =INT(AN18/2) -> 10 | AR18: =INT(AN18/5) -> 4 | AU18: 你现在有这么多 | BB18: 那么你分配到了哪里?
B19: ☐ | D19: =IF(ISTEXT(IFERROR(VLOOKUP(人物卡!F19,人物卡!BJ19:BR23,1,FALSE),IFERROR(VLOOKUP(人物卡!F19,人物卡!BB19:BC23,1,FALSE),0))),"★",INDEX(本职技能!$A$2:$IE$75,MATCH(人物卡!F19,本职技能!$A$2:$A$74,0),MATCH(附表!B58,本职技能!$A$1:$IE$1,0))) -> 0 | F19: 估价 | J19: 5 | R19: =SUM(J19:P19) -> 5 | T19: =INT(R19/2) -> 2 | V19: =INT(R19/5) -> 1 | X19: ☐ | Z19: =IF(ISTEXT(IFERROR(VLOOKUP(人物卡!AB19,BJ19:BJ23,1,FALSE),IFERROR(VLOOKUP(人物卡!AB19,BB19:BB23,1,FALSE),0))),"★",INDEX(本职技能!$A$2:$IE$75,MATCH(人物卡!AB19,本职技能!$A$2:$A$74,0),MATCH(附表!B58,本职技能!$A$1:$IE$1,0))) -> ★ | AB19: 聆听 | AF19: 20 | AJ19: 45 | AL19: 5 | AN19: =SUM(AF19:AL19) -> 70 | AP19: =INT(AN19/2) -> 35 | AR19: =INT(AN19/5) -> 14 | AU19: 任意特长
B20: ☐ | D20: =IF(ISTEXT(IFERROR(VLOOKUP(人物卡!F20,人物卡!BJ19:BR23,1,FALSE),IFERROR(VLOOKUP(人物卡!F20,人物卡!BB19:BC23,1,FALSE),0))),"★",INDEX(本职技能!$A$2:$IE$75,MATCH(人物卡!F20,本职技能!$A$2:$A$74,0),MATCH(附表!B58,本职技能!$A$1:$IE$1,0))) -> 0 | F20: 考古学 | J20: 1 | R20: =SUM(J20:P20) -> 1 | T20: =INT(R20/2) -> 0 | V20: =INT(R20/5) -> 0 | X20: ☐ | Z20: =IF(ISTEXT(IFERROR(VLOOKUP(人物卡!AB20,人物卡!BJ19:BR23,1,FALSE),IFERROR(VLOOKUP(人物卡!AB20,人物卡!BB19:BC23,1,FALSE),0))),"★",INDEX(本职技能!$A$2:$IE$75,MATCH(人物卡!AB20,本职技能!$A$2:$A$74,0),MATCH(附表!B58,本职技能!$A$1:$IE$1,0))) -> ★ | AB20: 锁匠 | AF20: 1 | AJ20: 70 | AN20: =SUM(AF20:AL20) -> 71 | AP20: =INT(AN20/2) -> 35 | AR20: =INT(AN20/5) -> 14 | AU20: =附表!AD25 -> 1
B21: ☐ | D21: =IF(ISTEXT(IFERROR(VLOOKUP(人物卡!F21,人物卡!BJ19:BR23,1,FALSE),IFERROR(VLOOKUP(人物卡!F21,人物卡!BB19:BC23,1,FALSE),0))),"★",INDEX(本职技能!$A$2:$IE$75,MATCH(人物卡!F21,本职技能!$A$2:$A$74,0),MATCH(附表!B58,本职技能!$A$1:$IE$1,0))) -> 摄影★ | F21: 技艺① | J21: =IF(ISBLANK(AU27),5,IF(H21=AU27,BA27,5)) -> 5 | R21: =J21+L21+N21+P21 -> 5 | T21: =INT(R21/2) -> 2 | V21: =INT(R21/5) -> 1 | X21: ☐ | Z21: =IF(ISTEXT(IFERROR(VLOOKUP(人物卡!AB21,人物卡!BJ19:BR23,1,FALSE),IFERROR(VLOOKUP(人物卡!AB21,人物卡!BB19:BC23,1,FALSE),0))),"★",INDEX(本职技能!$A$2:$IE$75,MATCH(人物卡!AB21,本职技能!$A$2:$A$74,0),MATCH(附表!B58,本职技能!$A$1:$IE$1,0))) -> 0 | AB21: 机械维修 | AF21: 10 | AN21: =SUM(AF21:AL21) -> 10 | AP21: =INT(AN21/2) -> 5 | AR21: =INT(AN21/5) -> 2
B22: ☐ | D22: =IF(ISTEXT(IFERROR(VLOOKUP(人物卡!F22,人物卡!BJ19:BR23,1,FALSE),IFERROR(VLOOKUP(人物卡!F22,人物卡!BB19:BC23,1,FALSE),0))),"★",INDEX(本职技能!$A$2:$IE$75,MATCH(人物卡!F22,本职技能!$A$2:$A$74,0),MATCH(附表!B58,本职技能!$A$1:$IE$1,0))) -> 0 | F22: 技艺② | J22: =IF(ISBLANK(AU27),5,IF(H22=AU27,BA27,5)) -> 5 | R22: =P22+N22+L22+J22 -> 5 | T22: =INT(R22/2) -> 2 | V22: =INT(R22/5) -> 1 | X22: ☐ | Z22: =IF(ISTEXT(IFERROR(VLOOKUP(人物卡!AB22,人物卡!BJ19:BR23,1,FALSE),IFERROR(VLOOKUP(人物卡!AB22,人物卡!BB19:BC23,1,FALSE),0))),"★",INDEX(本职技能!$A$2:$IE$75,MATCH(人物卡!AB22,本职技能!$A$2:$A$74,0),MATCH(附表!B58,本职技能!$A$1:$IE$1,0))) -> 0 | AB22: 医学 | AF22: 1 | AN22: =SUM(AF22:AL22) -> 1 | AP22: =INT(AN22/2) -> 0 | AR22: =INT(AN22/5) -> 0
B23: ☐ | D23: =IF(ISTEXT(IFERROR(VLOOKUP(人物卡!F23,人物卡!BJ19:BR23,1,FALSE),IFERROR(VLOOKUP(人物卡!F23,人物卡!BB19:BC23,1,FALSE),0))),"★",INDEX(本职技能!$A$2:$IE$75,MATCH(人物卡!F23,本职技能!$A$2:$A$74,0),MATCH(附表!B58,本职技能!$A$1:$IE$1,0))) -> 0 | F23: 技艺③ | J23: =IF(ISBLANK(AU27),5,IF(H23=AU27,BA27,5)) -> 5 | R23: =P23+N23+L23+J23 -> 5 | T23: =INT(R23/2) -> 2 | V23: =INT(R23/5) -> 1 | X23: ☐ | Z23: =IF(ISTEXT(IFERROR(VLOOKUP(人物卡!AB23,人物卡!BJ19:BR23,1,FALSE),IFERROR(VLOOKUP(人物卡!AB23,人物卡!BB19:BC23,1,FALSE),0))),"★",INDEX(本职技能!$A$2:$IE$75,MATCH(人物卡!AB23,本职技能!$A$2:$A$74,0),MATCH(附表!B58,本职技能!$A$1:$IE$1,0))) -> 0 | AB23: 博物学 | AF23: 10 | AN23: =SUM(AF23:AL23) -> 10 | AP23: =INT(AN23/2) -> 5 | AR23: =INT(AN23/5) -> 2 | AU23: 提示当前职业
B24: ☐ | D24: =IF(ISTEXT(IFERROR(VLOOKUP(人物卡!F24,人物卡!BJ19:BR23,1,FALSE),IFERROR(VLOOKUP(人物卡!F24,人物卡!BB19:BC23,1,FALSE),0))),"★",INDEX(本职技能!$A$2:$IE$75,MATCH(人物卡!F24,本职技能!$A$2:$A$74,0),MATCH(附表!B58,本职技能!$A$1:$IE$1,0))) -> ☯ | F24: 取悦 | J24: 15 | N24: 15 | P24: 40 | R24: =SUM(J24:P24) -> 70 | T24: =INT(R24/2) -> 35 | V24: =INT(R24/5) -> 14 | X24: ☐ | Z24: =IF(ISTEXT(IFERROR(VLOOKUP(人物卡!AB24,人物卡!BJ19:BR23,1,FALSE),IFERROR(VLOOKUP(人物卡!AB24,人物卡!BB19:BC23,1,FALSE),0))),"★",INDEX(本职技能!$A$2:$IE$75,MATCH(人物卡!AB24,本职技能!$A$2:$A$74,0),MATCH(附表!B58,本职技能!$A$1:$IE$1,0))) -> 0 | AB24: 导航 | AF24: 10 | AN24: =SUM(AF24:AL24) -> 10 | AP24: =INT(AN24/2) -> 5 | AR24: =INT(AN24/5) -> 2 | AU24: 请将你选择的任意特长写在上方栏内，这样既方便你写卡又方便KP审卡
B25: ☐ | D25: =IF(ISTEXT(IFERROR(VLOOKUP(人物卡!F25,人物卡!BJ19:BR23,1,FALSE),IFERROR(VLOOKUP(人物卡!F25,人物卡!BB19:BC23,1,FALSE),0))),"★",INDEX(本职技能!$A$2:$IE$75,MATCH(人物卡!F25,本职技能!$A$2:$A$74,0),MATCH(附表!B58,本职技能!$A$1:$IE$1,0))) -> 0 | F25: 攀爬 | J25: 20 | R25: =SUM(J25:P25) -> 20 | T25: =INT(R25/2) -> 10 | V25: =INT(R25/5) -> 4 | X25: ☐ | Z25: =IF(ISTEXT(IFERROR(VLOOKUP(人物卡!AB25,人物卡!BJ19:BR23,1,FALSE),IFERROR(VLOOKUP(人物卡!AB25,人物卡!BB19:BC23,1,FALSE),0))),"★",INDEX(本职技能!$A$2:$IE$75,MATCH(人物卡!AB25,本职技能!$A$2:$A$74,0),MATCH(附表!B58,本职技能!$A$1:$IE$1,0))) -> 0 | AB25: 神秘学 | AF25: 5 | AN25: =SUM(AF25:AL25) -> 5 | AP25: =INT(AN25/2) -> 2 | AR25: =INT(AN25/5) -> 1 | AU25: 自定义子技能 | BC25: 自定义经历包 | BK25: 自定义状态
B26: ☐ | D26: =IF(ISTEXT(IFERROR(VLOOKUP(人物卡!F26,人物卡!BJ19:BR23,1,FALSE),IFERROR(VLOOKUP(人物卡!F26,人物卡!BB19:BC23,1,FALSE),0))),"★",INDEX(本职技能!$A$2:$IE$75,MATCH(人物卡!F26,本职技能!$A$2:$A$74,0),MATCH(附表!B58,本职技能!$A$1:$IE$1,0))) -> 0 | F26: 计算机使用 Ω | J26: 5 | R26: =SUM(J26:P26) -> 5 | T26: =INT(R26/2) -> 2 | V26: =INT(R26/5) -> 1 | X26: ☐ | Z26: =IF(ISTEXT(IFERROR(VLOOKUP(人物卡!AB26,人物卡!BJ19:BR23,1,FALSE),IFERROR(VLOOKUP(人物卡!AB26,人物卡!BB19:BC23,1,FALSE),0))),"★",INDEX(本职技能!$A$2:$IE$75,MATCH(人物卡!AB26,本职技能!$A$2:$A$74,0),MATCH(附表!B58,本职技能!$A$1:$IE$1,0))) -> 0 | AB26: 操作重型机械 | AF26: 1 | AN26: =SUM(AF26:AL26) -> 1 | AP26: =INT(AN26/2) -> 0 | AR26: =INT(AN26/5) -> 0 | AU26: 技能名称 | BA26: 基础值 | BC26: 经历包名称 | BK26: 状态名称(例:生病、精神分裂)
B27: —— | D27: ★ | F27: 信用评级 | J27: 0 | N27: 20 | R27: =SUM(J27:P27) -> 20 | T27: =INT(R27/2) -> 10 | V27: =INT(R27/5) -> 4 | X27: ☐ | Z27: =IF(ISTEXT(IFERROR(VLOOKUP(人物卡!AB27,人物卡!BJ19:BR23,1,FALSE),IFERROR(VLOOKUP(人物卡!AB27,人物卡!BB19:BC23,1,FALSE),0))),"★",INDEX(本职技能!$A$2:$IE$75,MATCH(人物卡!AB27,本职技能!$A$2:$A$74,0),MATCH(附表!B58,本职技能!$A$1:$IE$1,0))) -> ☯ | AB27: 说服 | AF27: 10 | AN27: =SUM(AF27:AL27) -> 10 | AP27: =INT(AN27/2) -> 5 | AR27: =INT(AN27/5) -> 2
B28: —— | D28: =IF(ISTEXT(IFERROR(VLOOKUP(F28,人物卡!BJ19:BR23,1,FALSE),IFERROR(VLOOKUP(F28,人物卡!BB19:BC23,1,FALSE),0))),"★",INDEX(本职技能!$A$2:$IE$75,MATCH(F28,本职技能!$A$2:$A$74,0),MATCH(附表!B58,本职技能!$A$1:$IE$1,0))) -> 0 | F28: 克苏鲁神话 | J28: 0 | N28: —— | P28: —— | R28: =SUM(J28:P28) -> 0 | T28: =INT(R28/2) -> 0 | V28: =INT(R28/5) -> 0 | X28: ☐ | Z28: =IF(ISTEXT(IFERROR(VLOOKUP(人物卡!AB28,人物卡!BJ19:BR23,1,FALSE),IFERROR(VLOOKUP(人物卡!AB28,人物卡!BB19:BC23,1,FALSE),0))),"★",INDEX(本职技能!$A$2:$IE$75,MATCH(人物卡!AB28,本职技能!$A$2:$A$74,0),MATCH(附表!B58,本职技能!$A$1:$IE$1,0))) -> 0 | AB28: 驾驶： | AF28: =IF(ISBLANK(AU27),1,IF(AD28=AU27,BA27,1)) -> 1 | AN28: =SUM(AF28:AL28) -> 1 | AP28: =INT(AN28/2) -> 0 | AR28: =INT(AN28/5) -> 0 | AU28: 用法/备注 | BC28: san值减少 | BG28: 技能增长 | BK28: 身体状态 | BO28: 精神状态
B29: ☐ | D29: =IF(ISTEXT(IFERROR(VLOOKUP(人物卡!F29,人物卡!BJ19:BR23,1,FALSE),IFERROR(VLOOKUP(人物卡!F29,人物卡!BB19:BC23,1,FALSE),0))),"★",INDEX(本职技能!$A$2:$IE$75,MATCH(人物卡!F29,本职技能!$A$2:$A$74,0),MATCH(附表!B58,本职技能!$A$1:$IE$1,0))) -> 0 | F29: 乔装 | J29: 5 | R29: =SUM(J29:P29) -> 5 | T29: =INT(R29/2) -> 2 | V29: =INT(R29/5) -> 1 | X29: ☐ | Z29: =IF(ISTEXT(IFERROR(VLOOKUP(人物卡!AB29,人物卡!BJ19:BR23,1,FALSE),IFERROR(VLOOKUP(人物卡!AB29,人物卡!BB19:BC23,1,FALSE),0))),"★",INDEX(本职技能!$A$2:$IE$75,MATCH(人物卡!AB29,本职技能!$A$2:$A$74,0),MATCH(附表!B58,本职技能!$A$1:$IE$1,0))) -> 0 | AB29: 精神分析 | AF29: 1 | AN29: =SUM(AF29:AL29) -> 1 | AP29: =INT(AN29/2) -> 0 | AR29: =INT(AN29/5) -> 0
B30: ☐ | D30: =IF(ISTEXT(IFERROR(VLOOKUP(人物卡!F30,人物卡!BJ19:BR23,1,FALSE),IFERROR(VLOOKUP(人物卡!F30,人物卡!BB19:BC23,1,FALSE),0))),"★",INDEX(本职技能!$A$2:$IE$75,MATCH(人物卡!F30,本职技能!$A$2:$A$74,0),MATCH(附表!B58,本职技能!$A$1:$IE$1,0))) -> 0 | F30: 闪避 | J30: =INT(DEX/2) -> 35 | P30: 25 | R30: =SUM(J30:P30) -> 60 | T30: =INT(R30/2) -> 30 | V30: =INT(R30/5) -> 12 | X30: ☐ | Z30: =IF(ISTEXT(IFERROR(VLOOKUP(人物卡!AB30,人物卡!BJ19:BR23,1,FALSE),IFERROR(VLOOKUP(人物卡!AB30,人物卡!BB19:BC23,1,FALSE),0))),"★",INDEX(本职技能!$A$2:$IE$75,MATCH(人物卡!AB30,本职技能!$A$2:$A$74,0),MATCH(附表!B58,本职技能!$A$1:$IE$1,0))) -> 0 | AB30: 心理学 | AF30: 10 | AL30: 50 | AN30: =SUM(AF30:AL30) -> 60 | AP30: =INT(AN30/2) -> 30 | AR30: =INT(AN30/5) -> 12 | BC30: 可选技能
B31: ☐ | D31: =IF(ISTEXT(IFERROR(VLOOKUP(人物卡!F31,人物卡!BJ19:BR23,1,FALSE),IFERROR(VLOOKUP(人物卡!F31,人物卡!BB19:BC23,1,FALSE),0))),"★",INDEX(本职技能!$A$2:$IE$75,MATCH(人物卡!F31,本职技能!$A$2:$A$74,0),MATCH(附表!B58,本职技能!$A$1:$IE$1,0))) -> 0 | F31: 汽车驾驶 | J31: 20 | R31: =SUM(J31:P31) -> 20 | T31: =INT(R31/2) -> 10 | V31: =INT(R31/5) -> 4 | X31: ☐ | Z31: =IF(ISTEXT(IFERROR(VLOOKUP(人物卡!AB31,人物卡!BJ19:BR23,1,FALSE),IFERROR(VLOOKUP(人物卡!AB31,人物卡!BB19:BC23,1,FALSE),0))),"★",INDEX(本职技能!$A$2:$IE$75,MATCH(人物卡!AB31,本职技能!$A$2:$A$74,0),MATCH(附表!B58,本职技能!$A$1:$IE$1,0))) -> 0 | AB31: 骑术 | AF31: 5 | AN31: =SUM(AF31:AL31) -> 5 | AP31: =INT(AN31/2) -> 2 | AR31: =INT(AN31/5) -> 1
B32: ☐ | D32: =IF(ISTEXT(IFERROR(VLOOKUP(人物卡!F32,人物卡!BJ19:BR23,1,FALSE),IFERROR(VLOOKUP(人物卡!F32,人物卡!BB19:BC23,1,FALSE),0))),"★",INDEX(本职技能!$A$2:$IE$75,MATCH(人物卡!F32,本职技能!$A$2:$A$74,0),MATCH(附表!B58,本职技能!$A$1:$IE$1,0))) -> 0 | F32: 电气维修 | J32: 10 | R32: =SUM(J32:P32) -> 10 | T32: =INT(R32/2) -> 5 | V32: =INT(R32/5) -> 2 | X32: ☐ | Z32: =IF(ISTEXT(IFERROR(VLOOKUP(人物卡!AB32,人物卡!BJ19:BR23,1,FALSE),IFERROR(VLOOKUP(人物卡!AB32,人物卡!BB19:BC23,1,FALSE),0))),"★",INDEX(本职技能!$A$2:$IE$75,MATCH(人物卡!AB32,本职技能!$A$2:$A$74,0),MATCH(附表!B58,本职技能!$A$1:$IE$1,0))) -> 0 | AB32: 科学① | AF32: =IF(ISBLANK(AU27),IF(AD32="数学",10,1),IF(AD32=AU27,BA27,1)) -> 1 | AN32: =AF32+AH32+AL32+AJ32 -> 1 | AP32: =INT(AN32/2) -> 0 | AR32: =INT(AN32/5) -> 0
B33: ☐ | D33: =IF(ISTEXT(IFERROR(VLOOKUP(人物卡!F33,人物卡!BJ19:BR23,1,FALSE),IFERROR(VLOOKUP(人物卡!F33,人物卡!BB19:BC23,1,FALSE),0))),"★",INDEX(本职技能!$A$2:$IE$75,MATCH(人物卡!F33,本职技能!$A$2:$A$74,0),MATCH(附表!B58,本职技能!$A$1:$IE$1,0))) -> 0 | F33: 电子学 Ω | J33: 1 | R33: =SUM(J33:P33) -> 1 | T33: =INT(R33/2) -> 0 | V33: =INT(R33/5) -> 0 | X33: ☐ | Z33: =IF(ISTEXT(IFERROR(VLOOKUP(人物卡!AB33,人物卡!BJ19:BR23,1,FALSE),IFERROR(VLOOKUP(人物卡!AB33,人物卡!BB19:BC23,1,FALSE),0))),"★",INDEX(本职技能!$A$2:$IE$75,MATCH(人物卡!AB33,本职技能!$A$2:$A$74,0),MATCH(附表!B58,本职技能!$A$1:$IE$1,0))) -> 0 | AB33: 科学② | AF33: =IF(ISBLANK(AU27),IF(AD33="数学",10,1),IF(AD33=AU27,BA27,1)) -> 1 | AN33: =AL33+AJ33+AF33+AH33 -> 1 | AP33: =INT(AN33/2) -> 0 | AR33: =INT(AN33/5) -> 0
B34: ☐ | D34: =IF(ISTEXT(IFERROR(VLOOKUP(人物卡!F34,人物卡!BJ19:BR23,1,FALSE),IFERROR(VLOOKUP(人物卡!F34,人物卡!BB19:BC23,1,FALSE),0))),"★",INDEX(本职技能!$A$2:$IE$75,MATCH(人物卡!F34,本职技能!$A$2:$A$74,0),MATCH(附表!B58,本职技能!$A$1:$IE$1,0))) -> ☯ | F34: 话术 | J34: 5 | N34: 65 | R34: =SUM(J34:P34) -> 70 | T34: =INT(R34/2) -> 35 | V34: =INT(R34/5) -> 14 | X34: ☐ | Z34: =IF(ISTEXT(IFERROR(VLOOKUP(人物卡!AB34,人物卡!BJ19:BR23,1,FALSE),IFERROR(VLOOKUP(人物卡!AB34,人物卡!BB19:BC23,1,FALSE),0))),"★",INDEX(本职技能!$A$2:$IE$75,MATCH(人物卡!AB34,本职技能!$A$2:$A$74,0),MATCH(附表!B58,本职技能!$A$1:$IE$1,0))) -> 0 | AB34: 科学③ | AF34: =IF(ISBLANK(AU27),IF(AD34="数学",10,1),IF(AD34=AU27,BA27,1)) -> 1 | AN34: =AF34+AH34+AJ34+AL34 -> 1 | AP34: =INT(AN34/2) -> 0 | AR34: =INT(AN34/5) -> 0 | BC34: 备注
B35: ☐ | D35: =IF(ISTEXT(IFERROR(VLOOKUP(人物卡!F35,人物卡!BJ19:BR23,1,FALSE),IFERROR(VLOOKUP(人物卡!F35,人物卡!BB19:BC23,1,FALSE),0))),"★",INDEX(本职技能!$A$2:$IE$75,MATCH(人物卡!F35,本职技能!$A$2:$A$74,0),MATCH(附表!B58,本职技能!$A$1:$IE$1,0))) -> 0 | F35: 格斗： | H35: 斗殴 | J35: 25 | R35: =SUM(J35:P35) -> 25 | T35: =INT(R35/2) -> 12 | V35: =INT(R35/5) -> 5 | X35: ☐ | Z35: =IF(ISTEXT(IFERROR(VLOOKUP(人物卡!AB35,人物卡!BJ19:BR23,1,FALSE),IFERROR(VLOOKUP(人物卡!AB35,人物卡!BB19:BC23,1,FALSE),0))),"★",INDEX(本职技能!$A$2:$IE$75,MATCH(人物卡!AB35,本职技能!$A$2:$A$74,0),MATCH(附表!B58,本职技能!$A$1:$IE$1,0))) -> 0 | AB35: 妙手 | AF35: 10 | AN35: =SUM(AF35:AL35) -> 10 | AP35: =INT(AN35/2) -> 5 | AR35: =INT(AN35/5) -> 2
B36: ☐ | D36: =IF(ISTEXT(IFERROR(VLOOKUP(人物卡!F36,人物卡!BJ19:BR23,1,FALSE),IFERROR(VLOOKUP(人物卡!F36,人物卡!BB19:BC23,1,FALSE),0))),"★",INDEX(本职技能!$A$2:$IE$75,MATCH(人物卡!F36,本职技能!$A$2:$A$74,0),MATCH(附表!B58,本职技能!$A$1:$IE$1,0))) -> 0 | F36: 格斗① | J36: =附表!C11 -> 0 | R36: =J36+L36+N36+P36 -> 0 | T36: =INT(R36/2) -> 0 | V36: =INT(R36/5) -> 0 | X36: ☐ | Z36: =IF(ISTEXT(IFERROR(VLOOKUP(人物卡!AB36,人物卡!BJ19:BR23,1,FALSE),IFERROR(VLOOKUP(人物卡!AB36,人物卡!BB19:BC23,1,FALSE),0))),"★",INDEX(本职技能!$A$2:$IE$75,MATCH(人物卡!AB36,本职技能!$A$2:$A$74,0),MATCH(附表!B58,本职技能!$A$1:$IE$1,0))) -> ★ | AB36: 侦查 | AF36: 25 | AJ36: 55 | AN36: =SUM(AF36:AL36) -> 80 | AP36: =INT(AN36/2) -> 40 | AR36: =INT(AN36/5) -> 16 | AU36: 自定义年龄补正 | BK36: 自定义货币
B37: ☐ | D37: =IF(ISTEXT(IFERROR(VLOOKUP(F37,人物卡!BJ19:BR23,1,FALSE),IFERROR(VLOOKUP(F37,人物卡!BB19:BC23,1,FALSE),0))),"★",INDEX(本职技能!$A$2:$IE$75,MATCH(F37,本职技能!$A$2:$A$74,0),MATCH(附表!B58,本职技能!$A$1:$IE$1,0))) -> 0 | F37: 格斗② | J37: =附表!C12 -> 0 | R37: =J37+L37+P37+N37 -> 0 | T37: =INT(R37/2) -> 0 | V37: =INT(R37/5) -> 0 | X37: ☐ | Z37: =IF(ISTEXT(IFERROR(VLOOKUP(人物卡!AB37,人物卡!BJ19:BR23,1,FALSE),IFERROR(VLOOKUP(人物卡!AB37,人物卡!BB19:BC23,1,FALSE),0))),"★",INDEX(本职技能!$A$2:$IE$75,MATCH(人物卡!AB37,本职技能!$A$2:$A$74,0),MATCH(附表!B58,本职技能!$A$1:$IE$1,0))) -> 0 | AB37: 潜行 | AF37: 20 | AL37: 40 | AN37: =SUM(AF37:AL37) -> 60 | AP37: =INT(AN37/2) -> 30 | AR37: =INT(AN37/5) -> 12 | AU37: 年龄补正 | BK37: 货币名称 | BO37: 与美元的汇率
B38: ☐ | D38: =IF(ISTEXT(IFERROR(VLOOKUP(F38,人物卡!BJ19:BR23,1,FALSE),IFERROR(VLOOKUP(F38,人物卡!BB19:BC23,1,FALSE),0))),"★",INDEX(本职技能!$A$2:$IE$75,MATCH(F38,本职技能!$A$2:$A$74,0),MATCH(附表!B58,本职技能!$A$1:$IE$1,0))) -> 0 | F38: 格斗③ | J38: =附表!C13 -> 0 | R38: =P38+N38+L38+J38 -> 0 | T38: =INT(R38/2) -> 0 | V38: =INT(R38/5) -> 0 | X38: ☐ | Z38: =IF(ISTEXT(IFERROR(VLOOKUP(人物卡!AB38,人物卡!BJ19:BR23,1,FALSE),IFERROR(VLOOKUP(人物卡!AB38,人物卡!BB19:BC23,1,FALSE),0))),"★",INDEX(本职技能!$A$2:$IE$75,MATCH(人物卡!AB38,本职技能!$A$2:$A$74,0),MATCH(附表!B58,本职技能!$A$1:$IE$1,0))) -> 0 | AB38: 生存： | AF38: 10 | AN38: =SUM(AF38:AL38) -> 10 | AP38: =INT(AN38/2) -> 5 | AR38: =INT(AN38/5) -> 2
B39: ☐ | D39: =IF(ISTEXT(IFERROR(VLOOKUP(人物卡!F39,人物卡!BJ19:BR23,1,FALSE),IFERROR(VLOOKUP(人物卡!F39,人物卡!BB19:BC23,1,FALSE),0))),"★",INDEX(本职技能!$A$2:$IE$75,MATCH(人物卡!F39,本职技能!$A$2:$A$74,0),MATCH(附表!B58,本职技能!$A$1:$IE$1,0))) -> 0 | F39: 射击： | H39: 手枪 | J39: 20 | R39: =SUM(J39:P39) -> 20 | T39: =INT(R39/2) -> 10 | V39: =INT(R39/5) -> 4 | X39: ☐ | Z39: =IF(ISTEXT(IFERROR(VLOOKUP(人物卡!AB39,人物卡!BJ19:BR23,1,FALSE),IFERROR(VLOOKUP(人物卡!AB39,人物卡!BB19:BC23,1,FALSE),0))),"★",INDEX(本职技能!$A$2:$IE$75,MATCH(人物卡!AB39,本职技能!$A$2:$A$74,0),MATCH(附表!B58,本职技能!$A$1:$IE$1,0))) -> 0 | AB39: 游泳 | AF39: 20 | AN39: =SUM(AF39:AL39) -> 20 | AP39: =INT(AN39/2) -> 10 | AR39: =INT(AN39/5) -> 4 | AU39: 推 荐 关 系 人 | AV39: =IF(M5=0," ",""&LOOKUP(M5,职业列表!A2:A232,职业列表!L2:L232))
B40: ☐ | D40: =IF(ISTEXT(IFERROR(VLOOKUP(人物卡!F40,人物卡!BJ19:BR23,1,FALSE),IFERROR(VLOOKUP(人物卡!F40,人物卡!BB19:BC23,1,FALSE),0))),"★",INDEX(本职技能!$A$2:$IE$75,MATCH(人物卡!F40,本职技能!$A$2:$A$74,0),MATCH(附表!B58,本职技能!$A$1:$IE$1,0))) -> 0 | F40: 射击① | J40: =附表!E11 -> 0 | R40: =P40+N40+L40+J40 -> 0 | T40: =INT(R40/2) -> 0 | V40: =INT(R40/5) -> 0 | X40: ☐ | Z40: =IF(ISTEXT(IFERROR(VLOOKUP(人物卡!AB40,人物卡!BJ19:BR23,1,FALSE),IFERROR(VLOOKUP(人物卡!AB40,人物卡!BB19:BC23,1,FALSE),0))),"★",INDEX(本职技能!$A$2:$IE$75,MATCH(人物卡!AB40,本职技能!$A$2:$A$74,0),MATCH(附表!B58,本职技能!$A$1:$IE$1,0))) -> 0 | AB40: 投掷 | AF40: 20 | AN40: =SUM(AF40:AL40) -> 20 | AP40: =INT(AN40/2) -> 10 | AR40: =INT(AN40/5) -> 4
B41: ☐ | D41: =IF(ISTEXT(IFERROR(VLOOKUP(F41,人物卡!BJ19:BR23,1,FALSE),IFERROR(VLOOKUP(F41,人物卡!BB19:BC23,1,FALSE),0))),"★",INDEX(本职技能!$A$2:$IE$75,MATCH(F41,本职技能!$A$2:$A$74,0),MATCH(附表!B58,本职技能!$A$1:$IE$1,0))) -> 0 | F41: 射击② | J41: =附表!E12 -> 0 | R41: =P41+N41+L41+J41 -> 0 | T41: =INT(R41/2) -> 0 | V41: =INT(R41/5) -> 0 | X41: ☐ | Z41: =IF(ISTEXT(IFERROR(VLOOKUP(人物卡!AB41,人物卡!BJ19:BR23,1,FALSE),IFERROR(VLOOKUP(人物卡!AB41,人物卡!BB19:BC23,1,FALSE),0))),"★",INDEX(本职技能!$A$2:$IE$75,MATCH(人物卡!AB41,本职技能!$A$2:$A$74,0),MATCH(附表!B58,本职技能!$A$1:$IE$1,0))) -> 0 | AB41: 追踪 | AF41: 10 | AN41: =SUM(AF41:AL41) -> 10 | AP41: =INT(AN41/2) -> 5 | AR41: =INT(AN41/5) -> 2
...

Sheet 简化卡
B2: =人物卡!E3&"，"&人物卡!E6&"，"&人物卡!E4&"岁"&"，"&人物卡!E5&"，"&人物卡!M4&"，"&"现居："&人物卡!E7&"，"&人物卡!M6&"，"&人物卡!M7&"人" -> 尤金，男，29岁，私家侦探，1920s，现居：布鲁克林区，美国，纽约人 | N2: 技能 | Z2: 当前时间
B3: STR | C3: =STR -> 30 | D3: =INT(C3/2) -> 15 | E3: DEX | F3: =DEX -> 70 | G3: =INT(F3/2) -> 35 | H3: POW | I3: =POW -> 60 | J3: =INT(I3/2) -> 30 | K3: INT | L3: =INT -> 80 | M3: =INT(L3/2) -> 40 | N3: =IF(Q3=0,"",人物卡!F17) | Q3: =IF(人物卡!R17-人物卡!J17=0,0,人物卡!R17) -> 0 | R3: =INT(Q3/2) -> 0 | S3: =INT(Q3/5) -> 0 | T3: =IF(W3=0,"",人物卡!AB17) | W3: =IF(人物卡!AN17-人物卡!AF17=0,0,人物卡!AN17) -> 0 | X3: =INT(W3/2) -> 0 | Y3: =INT(W3/5) -> 0 | Z3: =人物卡!E8 -> 公元 | AA3: =人物卡!G8 -> 2023 | AC3: =人物卡!J8 -> 1月 | AD3: =人物卡!N8 -> 0：00
D4: =INT(C3/5) -> 6 | G4: =INT(F3/5) -> 14 | J4: =INT(I3/5) -> 12 | M4: =INT(L3/5) -> 16 | N4: =IF(Q4=0,"",人物卡!F18) | Q4: =IF(人物卡!R18-人物卡!J18=0,0,人物卡!R18) -> 0 | R4: =INT(Q4/2) -> 0 | S4: =INT(Q4/5) -> 0 | T4: =IF(W4=0,"",人物卡!AB18) | W4: =IF(人物卡!AN18-人物卡!AF18=0,0,人物卡!AN18) -> 0 | X4: =INT(W4/2) -> 0 | Y4: =INT(W4/5) -> 0 | AC4: =人物卡!L8 -> 1日
B5: CON | C5: =CON -> 50 | D5: =INT(C5/2) -> 25 | E5: APP | F5: =APP -> 80 | G5: =INT(F5/2) -> 40 | H5: EDU | I5: =EDU -> 55 | J5: =INT(I5/2) -> 27 | K5: SIZ | L5: =SIZ -> 55 | M5: =INT(L5/2) -> 27 | N5: =IF(Q5=0,"",人物卡!F19) | Q5: =IF(人物卡!R19-人物卡!J19=0,0,人物卡!R19) -> 0 | R5: =INT(Q5/2) -> 0 | S5: =INT(Q5/5) -> 0 | T5: =IF(W5=0,"",人物卡!AB19) -> 聆听 | W5: =IF(人物卡!AN19-人物卡!AF19=0,0,人物卡!AN19) -> 70 | X5: =INT(W5/2) -> 35 | Y5: =INT(W5/5) -> 14 | Z5: 调查员伙伴
D6: =INT(C5/5) -> 10 | G6: =INT(F5/5) -> 16 | J6: =INT(I5/5) -> 11 | M6: =INT(L5/5) -> 11 | N6: =IF(Q6=0,"",人物卡!F20) | Q6: =IF(人物卡!R20-人物卡!J20=0,0,人物卡!R20) -> 0 | R6: =INT(Q6/2) -> 0 | S6: =INT(Q6/5) -> 0 | T6: =IF(W6=0,"",人物卡!AB20) -> 锁匠 | W6: =IF(人物卡!AN20-人物卡!AF20=0,0,人物卡!AN20) -> 71 | X6: =INT(W6/2) -> 35 | Y6: =INT(W6/5) -> 14 | Z6: 姓名 | AB6: 注释
B7: HP | C7: =人物卡!E10 -> 10 | D7: =人物卡!G10 -> 10 | E7: SAN | F7: =人物卡!N10 -> 60 | G7: =人物卡!P10 -> 99 | H7: MP | I7: =人物卡!W10 -> 12 | J7: =MP -> 12 | K7: Armor | L7: =人物卡!AN10 | N7: =IF(Q7=0,0,"技艺：") -> 0 | O7: =IF(N7=0,"",人物卡!H21) | Q7: =IF(人物卡!R21-人物卡!J21=0,0,人物卡!R21) -> 0 | R7: =INT(Q7/2) -> 0 | S7: =INT(Q7/5) -> 0 | T7: =IF(W7=0,"",人物卡!AB21) | W7: =IF(人物卡!AN21-人物卡!AF21=0,0,人物卡!AN21) -> 0 | X7: =INT(W7/2) -> 0 | Y7: =INT(W7/5) -> 0 | Z7: =人物卡!W131 -> 0 | AB7: =人物卡!AD131 -> 那次团的二五仔，团灭了全体
N8: =IF(Q8=0,0,"技艺：") -> 0 | O8: =IF(N8=0,"",人物卡!H22) | Q8: =IF(人物卡!R22-人物卡!J22=0,0,人物卡!R22) -> 0 | R8: =INT(Q8/2) -> 0 | S8: =INT(Q8/5) -> 0 | T8: =IF(W8=0,"",人物卡!AB22) | W8: =IF(人物卡!AN22-人物卡!AF22=0,0,人物卡!AN22) -> 0 | X8: =INT(W8/2) -> 0 | Y8: =INT(W8/5) -> 0 | Z8: =人物卡!W132 -> 0 | AB8: =人物卡!AD132 -> 0
B9: DB | C9: =人物卡!AP53 -> 0 | E9: Build | F9: =人物卡!AP56 -> 0 | H9: LUCK | I9: =Luck -> 50 | K9: MOV | L9: =人物卡!AF10 -> 8 | N9: =IF(Q9=0,0,"技艺：") -> 0 | O9: =IF(N9=0,"",人物卡!H23) | Q9: =IF(人物卡!R23-人物卡!J23=0,0,人物卡!R23) -> 0 | R9: =INT(Q9/2) -> 0 | S9: =INT(Q9/5) -> 0 | T9: =IF(W9=0,"",人物卡!AB23) | W9: =IF(人物卡!AN23-人物卡!AF23=0,0,人物卡!AN23) -> 0 | X9: =INT(W9/2) -> 0 | Y9: =INT(W9/5) -> 0 | Z9: =人物卡!W133 -> 0 | AB9: =人物卡!AD133 -> 0
N10: =IF(Q10=0,"",人物卡!F24) -> 取悦 | Q10: =IF(人物卡!R24-人物卡!J24=0,0,人物卡!R24) -> 70 | R10: =INT(Q10/2) -> 35 | S10: =INT(Q10/5) -> 14 | T10: =IF(W10=0,"",人物卡!AB24) | W10: =IF(人物卡!AN24-人物卡!AF24=0,0,人物卡!AN24) -> 0 | X10: =INT(W10/2) -> 0 | Y10: =INT(W10/5) -> 0 | Z10: =人物卡!W134 -> 0 | AB10: =人物卡!AD134 -> 0
B11: 武器表 | N11: =IF(Q11=0,"",人物卡!F25) | Q11: =IF(人物卡!R25-人物卡!J25=0,0,人物卡!R25) -> 0 | R11: =INT(Q11/2) -> 0 | S11: =INT(Q11/5) -> 0 | T11: =IF(W11=0,"",人物卡!AB25) | W11: =IF(人物卡!AN25-人物卡!AF25=0,0,人物卡!AN25) -> 0 | X11: =INT(W11/2) -> 0 | Y11: =INT(W11/5) -> 0 | Z11: =人物卡!W135 -> 0 | AB11: =人物卡!AD135 -> 0
B12: =人物卡!B54 -> 无 | C12: =人物卡!G54 -> 肉搏 | D12: =人物卡!M54 -> 斗殴 | E12: =人物卡!Q54 -> 25 | F12: =人物卡!S54 -> 12 | G12: =人物卡!U54 -> 5 | H12: =人物卡!W54 -> 1D3+DB | I12: =人物卡!AA54 -> —— | J12: =人物卡!AC54 -> × | K12: =人物卡!AE54 -> 1 | L12: =人物卡!AG54 -> —— | M12: =人物卡!AJ54 -> —— | N12: =IF(Q12=0,"",人物卡!F26) | Q12: =IF(人物卡!R26-人物卡!J26=0,0,人物卡!R26) -> 0 | R12: =INT(Q12/2) -> 0 | S12: =INT(Q12/5) -> 0 | T12: =IF(W12=0,"",人物卡!AB26) | W12: =IF(人物卡!AN26-人物卡!AF26=0,0,人物卡!AN26) -> 0 | X12: =INT(W12/2) -> 0 | Y12: =INT(W12/5) -> 0 | Z12: =人物卡!W136 -> 0 | AB12: =人物卡!AD136 -> 0
B13: =人物卡!B55 -> 钢笔刀 | C13: =人物卡!G55 -> 小型刀具(弹簧折叠刀等) | D13: =IF(人物卡!M55="请选择类型","",人物卡!M55) -> 斗殴 | E13: =人物卡!Q55 -> 25 | F13: =人物卡!S55 -> 12 | G13: =人物卡!U55 -> 5 | H13: =人物卡!W55 -> 1D4+DB | I13: =人物卡!AA55 -> 接触 | J13: =人物卡!AC55 -> √ | K13: =人物卡!AE55 -> 1 | L13: =人物卡!AG55 -> —— | M13: =人物卡!AJ55 -> —— | N13: =人物卡!F27 -> 信用评级 | Q13: =人物卡!R27 -> 20 | R13: =IF(Q13=0,32767,INT(Q13/2)) -> 10 | S13: =IF(Q13=0,32767,INT(Q13/5)) -> 4 | T13: =IF(W13=0,"",人物卡!AB27) | W13: =IF(人物卡!AN27-人物卡!AF27=0,0,人物卡!AN27) -> 0 | X13: =INT(W13/2) -> 0 | Y13: =INT(W13/5) -> 0 | Z13: =人物卡!W137 -> 0 | AB13: =人物卡!AD137 -> 0
B14: =人物卡!B56 -> 0 | C14: =人物卡!G56 -> 0 | D14: =IF(人物卡!M56="请选择类型","",人物卡!M56) -> ←请选择类型 | E14: =人物卡!Q56 | F14: =人物卡!S56 | G14: =人物卡!U56 | H14: =人物卡!W56 | I14: =人物卡!AA56 | J14: =人物卡!AC56 | K14: =人物卡!AE56 | L14: =人物卡!AG56 | M14: =人物卡!AJ56 | N14: =IF(Q14=0,"",人物卡!F28) | Q14: =IF(人物卡!R28-人物卡!J28=0,0,人物卡!R28) -> 0 | R14: =INT(Q14/2) -> 0 | S14: =INT(Q14/5) -> 0 | T14: =IF(W14=0,0,人物卡!AB28) -> 0 | U14: =IF(T14=0,"",人物卡!AD28) | W14: =IF(人物卡!AN28-人物卡!AF28=0,0,人物卡!AN28) -> 0 | X14: =INT(W14/2) -> 0 | Y14: =INT(W14/5) -> 0 | Z14: =人物卡!W138 -> 0 | AB14: =人物卡!AD138 -> 0
B15: =人物卡!B57 -> 0 | C15: =人物卡!G57 -> 0 | D15: =IF(人物卡!M57="请选择类型","",人物卡!M57) | E15: =人物卡!Q57 | F15: =人物卡!S57 | G15: =人物卡!U57 | H15: =人物卡!W57 | I15: =人物卡!AA57 | J15: =人物卡!AC57 | K15: =人物卡!AE57 | L15: =人物卡!AG57 | M15: =人物卡!AJ57 | N15: =IF(Q15=0,"",人物卡!F29) | Q15: =IF(人物卡!R29-人物卡!J29=0,0,人物卡!R29) -> 0 | R15: =INT(Q15/2) -> 0 | S15: =INT(Q15/5) -> 0 | T15: =IF(W15=0,"",人物卡!AB29) | W15: =IF(人物卡!AN29-人物卡!AF29=0,0,人物卡!AN29) -> 0 | X15: =INT(W15/2) -> 0 | Y15: =INT(W15/5) -> 0 | Z15: =人物卡!W139 -> 0 | AB15: =人物卡!AD139 -> 0
B16: =人物卡!B58 -> 0 | C16: =人物卡!G58 -> 0 | D16: =IF(人物卡!M58="请选择类型","",人物卡!M58) -> 0 | E16: =人物卡!Q58 -> 0 | F16: =人物卡!S58 -> 0 | G16: =人物卡!U58 -> 0 | H16: =人物卡!W58 -> 0 | I16: =人物卡!AA58 -> 0 | J16: =人物卡!AC58 -> 0 | K16: =人物卡!AE58 -> 0 | L16: =人物卡!AG58 -> 0 | M16: =人物卡!AJ58 -> 0 | N16: =人物卡!F30 -> 闪避 | Q16: =人物卡!R30 -> 60 | R16: =IF(Q16=0,32767,INT(Q16/2)) -> 30 | S16: =IF(Q16=0,32767,INT(Q16/5)) -> 12 | T16: =IF(W16=0,"",人物卡!AB30) -> 心理学 | W16: =IF(人物卡!AN30-人物卡!AF30=0,0,人物卡!AN30) -> 60 | X16: =INT(W16/2) -> 30 | Y16: =INT(W16/5) -> 12 | Z16: =人物卡!W140 -> 0 | AB16: =人物卡!AD140 -> 0
B17: 资产 | N17: =IF(Q17=0,"",人物卡!F31) | Q17: =IF(人物卡!R31-人物卡!J31=0,0,人物卡!R31) -> 0 | R17: =INT(Q17/2) -> 0 | S17: =INT(Q17/5) -> 0 | T17: =IF(W17=0,"",人物卡!AB31) | W17: =IF(人物卡!AN31-人物卡!AF31=0,0,人物卡!AN31) -> 0 | X17: =INT(W17/2) -> 0 | Y17: =INT(W17/5) -> 0 | Z17: =人物卡!W141 -> 0 | AB17: =人物卡!AD141 -> 0
B18: 信用评级 | E18: 生活水平 | G18: 消费水平 | I18: 其他资产 | K18: 当前现金($) | M18: 单位 | N18: =IF(Q18=0,"",人物卡!F32) | Q18: =IF(人物卡!R32-人物卡!J32=0,0,人物卡!R32) -> 0 | R18: =INT(Q18/2) -> 0 | S18: =INT(Q18/5) -> 0 | T18: =IF(W18=0,0,"科学：") -> 0 | U18: =IF(T18=0,"",人物卡!AD32) | W18: =IF(人物卡!AN32-人物卡!AF32=0,0,人物卡!AN32) -> 0 | X18: =INT(W18/2) -> 0 | Y18: =INT(W18/5) -> 0
B19: =人物卡!B63 -> 20%/10%/4% | E19: =人物卡!F63 -> 标准 | G19: =人物卡!I63 -> 10 | I19: =人物卡!L63 -> 没有 | K19: =人物卡!O63 -> 10 | M19: =人物卡!S63 -> 美元 | N19: =IF(Q19=0,"",人物卡!F33) | Q19: =IF(人物卡!R33-人物卡!J33=0,0,人物卡!R33) -> 0 | R19: =INT(Q19/2) -> 0 | S19: =INT(Q19/5) -> 0 | T19: =IF(W19=0,0,"科学：") -> 0 | U19: =IF(T19=0,"",人物卡!AD33) | W19: =IF(人物卡!AN33-人物卡!AF33=0,0,人物卡!AN33) -> 0 | X19: =INT(W19/2) -> 0 | Y19: =INT(W19/5) -> 0
B20: =人物卡!L64 -> 请在这里详述你的资产 | N20: =IF(Q20=0,"",人物卡!F34) -> 话术 | Q20: =IF(人物卡!R34-人物卡!J34=0,0,人物卡!R34) -> 70 | R20: =INT(Q20/2) -> 35 | S20: =INT(Q20/5) -> 14 | T20: =IF(W20=0,0,"科学：") -> 0 | U20: =IF(T20=0,"",人物卡!AD34) | W20: =IF(人物卡!AN34-人物卡!AF34=0,0,人物卡!AN34) -> 0 | X20: =INT(W20/2) -> 0 | Y20: =INT(W20/5) -> 0
N21: =IF(Q21=0,0,"格斗：") -> 0 | O21: =IF(N21=0,"",人物卡!H35) | Q21: =IF(人物卡!R35-人物卡!J35=0,0,人物卡!R35) -> 0 | R21: =INT(Q21/2) -> 0 | S21: =INT(Q21/5) -> 0 | T21: =IF(W21=0,"",人物卡!AB35) | W21: =IF(人物卡!AN35-人物卡!AF35=0,0,人物卡!AN35) -> 0 | X21: =INT(W21/2) -> 0 | Y21: =INT(W21/5) -> 0 | Z21: 神话相关
B22: 随身物品 | N22: =IF(Q22=0,0,"格斗：") -> 0 | O22: =IF(N22=0,"",人物卡!H36) | Q22: =IF(人物卡!R36-人物卡!J36=0,0,人物卡!R36) -> 0 | R22: =INT(Q22/2) -> 0 | S22: =INT(Q22/5) -> 0 | T22: =IF(W22=0,"",人物卡!AB36) -> 侦查 | W22: =IF(人物卡!AN36-人物卡!AF36=0,0,人物卡!AN36) -> 80 | X22: =INT(W22/2) -> 40 | Y22: =INT(W22/5) -> 16 | Z22: 遇到了 | AD22: 累计消耗
B23: =人物卡!F80 -> 炭黑色大衣 | E23: =人物卡!F81 -> 炭黑色大衣 | H23: =人物卡!F82 -> 炭黑色大衣 | K23: =人物卡!F83 -> 炭黑色大衣 | N23: =IF(Q23=0,0,"格斗：") -> 0 | O23: =IF(N23=0,"",人物卡!H37) | Q23: =IF(人物卡!R37-人物卡!J37=0,0,人物卡!R37) -> 0 | R23: =INT(Q23/2) -> 0 | S23: =INT(Q23/5) -> 0 | T23: =IF(W23=0,"",人物卡!AB37) -> 潜行 | W23: =IF(人物卡!AN37-人物卡!AF37=0,0,人物卡!AN37) -> 60 | X23: =INT(W23/2) -> 30 | Y23: =INT(W23/5) -> 12 | Z23: =人物卡!W99 -> 例：米-戈 | AD23: =人物卡!AR99 -> 6
B24: =人物卡!F84 -> 中灰色西装裤 | E24: =人物卡!F85 -> 西装马甲内侧 | H24: =人物卡!F86 -> 衬衫内帖胸口处 | K24: =人物卡!F91 -> 0 | N24: =IF(Q24=0,0,"格斗：") -> 0 | O24: =IF(N24=0,"",人物卡!H38) | Q24: =IF(人物卡!R38-人物卡!J38=0,0,人物卡!R38) -> 0 | R24: =INT(Q24/2) -> 0 | S24: =INT(Q24/5) -> 0 | T24: =IF(W24=0,0,人物卡!AB38) -> 0 | U24: =IF(T24=0,"",人物卡!AD38) | W24: =IF(人物卡!AN38-人物卡!AF38=0,0,人物卡!AN38) -> 0 | X24: =INT(W24/2) -> 0 | Y24: =INT(W24/5) -> 0 | Z24: =人物卡!W100 -> 例：修格斯 | AD24: =人物卡!AR100 -> 5
B25: =人物卡!F92 -> 0 | E25: =人物卡!F93 -> 0 | H25: =人物卡!N80 -> 小型黄铜望远镜 | K25: =人物卡!N81 -> 便签本、钢笔刀 | N25: =IF(Q25=0,0,"射击：") -> 0 | O25: =IF(N25=0,"",人物卡!H39) | Q25: =IF(人物卡!R39-人物卡!J39=0,0,人物卡!R39) -> 0 | R25: =INT(Q25/2) -> 0 | S25: =INT(Q25/5) -> 0 | T25: =IF(W25=0,"",人物卡!AB39) | W25: =IF(人物卡!AN39-人物卡!AF39=0,0,人物卡!AN39) -> 0 | X25: =INT(W25/2) -> 0 | Y25: =INT(W25/5) -> 0 | Z25: =人物卡!W101 -> 0 | AD25: =人物卡!AR101 -> 0
B26: =人物卡!N82 -> 绣字手帕 | E26: =人物卡!N83 -> 钱包 | H26: =人物卡!N84 -> 精致烟盒和打火机 | K26: =人物卡!N85 -> 一对昂贵的宝石耳环 | N26: =IF(Q26=0,0,"射击：") -> 0 | O26: =IF(N26=0,"",人物卡!H40) | Q26: =IF(人物卡!R40-人物卡!J40=0,0,人物卡!R40) -> 0 | R26: =INT(Q26/2) -> 0 | S26: =INT(Q26/5) -> 0 | T26: =IF(W26=0,"",人物卡!AB40) | W26: =IF(人物卡!AN40-人物卡!AF40=0,0,人物卡!AN40) -> 0 | X26: =INT(W26/2) -> 0 | Y26: =INT(W26/5) -> 0 | Z26: =人物卡!W102 -> 0 | AD26: =人物卡!AR102 -> 0
B27: =人物卡!N86 -> 凯瑟琳的银项链 | E27: =人物卡!N91 -> 0 | H27: =人物卡!N92 -> 0 | K27: =人物卡!N93 -> 0 | N27: =IF(Q27=0,0,"射击：") -> 0 | O27: =IF(N27=0,"",人物卡!H41) | Q27: =IF(人物卡!R41-人物卡!J41=0,0,人物卡!R41) -> 0 | R27: =INT(Q27/2) -> 0 | S27: =INT(Q27/5) -> 0 | T27: =IF(W27=0,"",人物卡!AB41) | W27: =IF(人物卡!AN41-人物卡!AF41=0,0,人物卡!AN41) -> 0 | X27: =INT(W27/2) -> 0 | Y27: =INT(W27/5) -> 0 | Z27: =人物卡!W103 -> 0 | AD27: =人物卡!AR103 -> 0
B28: 背景故事 | N28: =IF(Q28=0,0,"射击：") -> 0 | O28: =IF(N28=0,"",人物卡!H42) | Q28: =IF(人物卡!R42-人物卡!J42=0,0,人物卡!R42) -> 0 | R28: =INT(Q28/2) -> 0 | S28: =INT(Q28/5) -> 0 | T28: =IF(W28=0,"",人物卡!AB42) | W28: =IF(人物卡!AN42-人物卡!AF42=0,0,人物卡!AN42) -> 0 | X28: =INT(W28/2) -> 0 | Y28: =INT(W28/5) -> 0 | Z28: =人物卡!W104 -> 0 | AD28: =人物卡!AR104 -> 0
B29: 描述 | C29: =人物卡!AA62 -> 高瘦，黑发蓝眼，英俊 | G29: 关键 | H29: =人物卡!W80 -> 纽约港口漂浮着油污与垃圾的臭味，母亲凯瑟琳沉海自杀后，西奥多觉得又多了一丝血腥味。 她所有的不幸都源自西奥多酗酒、出轨、家暴的父亲，于是某一个冬日，喝醉的父亲“意外”从结冰的消防梯跌落而亡，警方以醉鬼失足草草结案。 凯瑟琳曾说他是最聪明的孩子，明年春天要送他去上学，到头来，却由社会这所最残酷的学校教会他察言观色、谎言求生，谁也不知道他的真实想法，而西奥多天生的智慧让他摸索到适合自己的道路，他成为了一名私家侦探。 区别于不满足现状的许多同行，西奥多无意成为福尔摩斯，反而沉迷捉奸事业，很乐意为女士们服务，偶尔不收钱，甚至倒贴。至于男委托人，请付双倍报酬。 因为职业与过分英俊的外表，他有时也会卷入一些麻烦。 但没关系，凯瑟琳的银项链一直在他的心口处。 上帝不会保佑他，凯瑟琳会。 | N29: =IF(Q29=0,"",人物卡!F43) | Q29: =IF(人物卡!R43-人物卡!J43=0,0,人物卡!R43) -> 0 | R29: =INT(Q29/2) -> 0 | S29: =INT(Q29/5) -> 0 | T29: =IF(W29=0,"",人物卡!AB48) | W29: =IF(人物卡!AN43-人物卡!AF43=0,0,人物卡!AN43) -> 0 | X29: =INT(W29/2) -> 0 | Y29: =INT(W29/5) -> 0 | Z29: =人物卡!W105 -> 0 | AD29: =人物卡!AR105 -> 0
B30: 信仰 | C30: =人物卡!AA64 -> 他没有什么追求，但或许他能为像凯瑟琳一样的人做些什么 | G30: =人物卡!AR64 -> ☐ | N30: =IF(Q30=0,"",人物卡!F44) | Q30: =IF(人物卡!R44-人物卡!J44=0,0,人物卡!R44) -> 0 | R30: =INT(Q30/2) -> 0 | S30: =INT(Q30/5) -> 0 | T30: =IF(W30=0,"",人物卡!AB44) | W30: =IF(人物卡!AN44-人物卡!AF44=0,0,人物卡!AN44) -> 0 | X30: =INT(W30/2) -> 0 | Y30: =INT(W30/5) -> 0 | Z30: =人物卡!W106 -> 0 | AD30: =人物卡!AR106 -> 0
B31: 重要人 | C31: =人物卡!AA66 -> 母亲凯瑟琳 | G31: =人物卡!AR66 -> ☐ | N31: =IF(Q31=0,"",人物卡!F45) | Q31: =IF(人物卡!R45-人物卡!J45=0,0,人物卡!R45) -> 0 | R31: =INT(Q31/2) -> 0 | S31: =INT(Q31/5) -> 0 | T31: =IF(W31=0,"",人物卡!AB45) | W31: =IF(人物卡!AN45-人物卡!AF45=0,0,人物卡!AN45) -> 0 | X31: =INT(W31/2) -> 0 | Y31: =INT(W31/5) -> 0 | Z31: =人物卡!W107 -> 0 | AD31: =人物卡!AR107 -> 0
B32: 重要地 | C32: =人物卡!AA68 -> 纽约港口 | G32: =人物卡!AR68 -> ☐ | N32: =IF(Q32=0,"",人物卡!F46) | Q32: =IF(人物卡!R46-人物卡!J46=0,0,人物卡!R46) -> 0 | R32: =INT(Q32/2) -> 0 | S32: =INT(Q32/5) -> 0 | T32: =IF(W32=0,"",人物卡!AB46) | W32: =IF(人物卡!AN46-人物卡!AF46=0,0,人物卡!AN46) -> 0 | X32: =INT(W32/2) -> 0 | Y32: =INT(W32/5) -> 0 | Z32: =人物卡!W108 -> 0 | AD32: =人物卡!AR108 -> 0
B33: 宝物 | C33: =人物卡!AA70 -> 凯瑟琳的银项链 | G33: =人物卡!AR70 -> ☐ | N33: =IF(Q33=0,0,"外语：") -> 0 | O33: =IF(N33=0,"",人物卡!H47) | Q33: =IF(人物卡!R47-人物卡!J47=0,0,人物卡!R47) -> 0 | R33: =INT(Q33/2) -> 0 | S33: =INT(Q33/5) -> 0 | T33: =IF(W33=0,"",人物卡!AB47) | W33: =IF(人物卡!AN47-人物卡!AF47=0,0,人物卡!AN47) -> 0 | X33: =INT(W33/2) -> 0 | Y33: =INT(W33/5) -> 0 | Z33: =人物卡!W109 -> 0 | AD33: =人物卡!AR109 -> 0
B34: 特质 | C34: =人物卡!AA74 -> 散漫，看着不那么靠谱，女人缘极好 | G34: =人物卡!AR74 -> ☐ | N34: =IF(Q34=0,0,"外语：") -> 0 | O34: =IF(N34=0,"",人物卡!H48) | Q34: =IF(人物卡!R48-人物卡!J48=0,0,人物卡!R48) -> 0 | R34: =INT(Q34/2) -> 0 | S34: =INT(Q34/5) -> 0 | T34: =IF(W34=0,"",人物卡!#REF!) | W34: =IF(人物卡!AN48-人物卡!AF48=0,0,人物卡!AN48) -> 0 | X34: =INT(W34/2) -> 0 | Y34: =INT(W34/5) -> 0
B35: 伤疤 | C35: =人物卡!AA76 -> 无 | G35: =人物卡!AR76 -> ☐ | N35: =IF(Q35=0,0,"外语：") -> 0 | O35: =IF(N35=0,"",人物卡!H49) | Q35: =IF(人物卡!R49-人物卡!J49=0,0,人物卡!R49) -> 0 | R35: =INT(Q35/2) -> 0 | S35: =INT(Q35/5) -> 0 | T35: =IF(W35=0,"",人物卡!AB49) | W35: =IF(人物卡!AN49-人物卡!AF49=0,0,人物卡!AN49) -> 0 | X35: =INT(W35/2) -> 0 | Y35: =INT(W35/5) -> 0
B36: 恐惧 | C36: =人物卡!AA78 -> 0 | N36: 母语： | O36: =人物卡!H50 -> 0 | Q36: =人物卡!R50 -> 55 | R36: =IF(Q36=0,32767,INT(Q36/2)) -> 27 | S36: =IF(Q36=0,32767,INT(Q36/5)) -> 11 | T36: =IF(W36=0,"",人物卡!AB50) | W36: =IF(人物卡!AN50-人物卡!AF50=0,0,人物卡!AN50) -> 0 | X36: =INT(W36/2) -> 0 | Y36: =INT(W36/5) -> 0
B38: .st指令快捷输入 | Z38: TXT框→
B39: 请右键下格，点击“复制”，并且在右方的TXT栏“粘贴”就可以导出文本，放进QQ发送给骰子娘啦
B40: =附表!S23 -> .st 力量30str30敏捷70dex70意志60pow60体质50con50外貌80app80教育55知识55edu55体型55siz55智力80灵感80int80san60san值60理智60理智值60幸运50运气50mp12魔法12hp10体力10会计5人类学1估价5考古学1取悦70攀爬20计算机5计算机使用5电脑5信用20信誉20信用评级20克苏鲁0克苏鲁神话0cm0乔装5闪避60汽车20驾驶20汽车驾驶20电气维修10电子学1话术70斗殴25手枪20急救30历史5恐吓15跳跃20母语55法律5图书馆20图书馆使用20聆听70开锁71撬锁71锁匠71机械维修10医学1博物学10自然学10领航10导航10神秘学5重型操作1重型机械1操作重型机械1重型1说服10精神分析1心理学60骑术5妙手10侦查80潜行60生存10游泳20投掷20追踪10驯兽5潜水1爆破1读唇1催眠1炮术1
B41: 技能名的改变
B42: 原技能名称： | D42: 简化 | F42: 别名 | J42: 原技能名称： | L42: 简化 | N42: 别名 | R42: 原技能名称： | T42: 简化 | V42: 别名
...

Sheet 职业列表
A1: 序号 | B1: 职业 | D1: 最小 信誉 | E1: 最大 信誉 | F1: 职业属性 | G1: 技能点 | H1: 本职技能（请往右翻→） | L1: 推荐关系人 | N1: 职业介绍 | R1: =人物卡!M4 -> 1920s
A2: 0 | B2: 选择职业序号为0，则清除职业模板提示和点数计算器，供强迫症患者使用。 | I2: 右侧下拉框选择自定义职业技能与属性 | J2: 自定义职业本职技能
A3: 1 | B3: =IF(C3="","自定义职业",C3) -> 自定义职业 | D3: 0 | E3: 50 | F3: =附表!AB5 -> 教育×2+力量×2或体质×2 | G3: =附表!AF5 -> 210 | H3: =IF(附表!P60=1,附表!Q61&附表!Q62&附表!Q63&附表!Q64&附表!Q65&附表!Q66&附表!Q67&附表!Q68&附表!Q72&附表!Q69&附表!Q70&附表!Q71,"不多于8个本职技能。在职业属性中输入第二职业属性的数值（留空则视为EDU）并自行设置起始信誉。使用自定义职业前，请先咨询你的守秘人。") -> 不多于8个本职技能。在职业属性中输入第二职业属性的数值（留空则视为EDU）并自行设置起始信誉。使用自定义职业前，请先咨询你的守秘人。 | L3: 列出一些角色在职业工作中可能接触的个人或组织,它们也可以为调查员的个人背景提供灵感。 | N3: 不多于7个本职技能。 在职业属性中输入第二职业属性的名字（如外貌、意志、教育、敏捷、力量、体质、体型，留空则视为EDU）并自行设置起始信誉。使用自定义职业前，请先咨询你的KP
A4: 2 | B4: 会计师 | D4: 30 | E4: 70 | F4: 教育×4 | G4: =EDU*4 -> 220 | H4: 会计，法律，图书馆，聆听，说服，侦查，任意其他两项个人或时代特长。 | L4: 生意伙伴，法律界，金融业界(银行，其他会计师)。 | N4: 会计师可能在企业工作或作为自由会计师，为个体经营者和企业客户担任顾问。 他们是优秀的研究者，既勤奋又关注细节，能够通过仔细分析个人和企业事务历史记录、财务报表和其他记录支持其他调查员。
A5: 3 | B5: 杂技演员 | D5: 9 | E5: 20 | F5: 教育×2＋敏捷×2 | G5: =EDU*2+DEX*2 -> 250 | H5: 攀爬，闪避，跳跃，投掷，侦查，游泳，任意两项其他个人或时代特长。 | L5: 业余运动员圈，体育专栏作家，马戏团，嘉年华管理者。 | N5: 杂技演员可能是参加各级比赛(甚至奥运会)的业余运动员，也可能是专业的演员，在马戏团、嘉年华、歌舞团之类的地方作为娱乐业从业者工作。
A6: 4 | B6: 演员-戏剧演员 | D6: 9 | E6: 40 | F6: 教育×2＋外貌×2 | G6: =EDU*2+APP*2 -> 270 | H6: 技艺（表演），乔装，格斗，历史，两项社交技能（取悦、话术、恐吓、说服），心理学，任意一项其他个人或时代特长。 | L6: 戏剧产业，报刊艺术批评家，演员公会。 | N6: 一般指舞台剧演员和电影演员。许多演员有相当深厚的文化素养，认为自己才是“正统”的，倾向于轻视电影业的商业活动。直到20 世纪后期电影业的地位提高，电影演员的薪酬增加，这种情况才发生改变。 电影业和电影明星一直是世界人民关注的焦点。许多明星一夜成名，在媒体的聚光灯下过着光鲜亮丽的生活。 在1920 年代，虽然全国都有大型剧院，美国的戏剧中心仍然是纽约城。英国的情况与之相近，戏剧的中心在伦敦，其他的剧团则在各郡作巡回演出。巡回剧团乘火车旅行，演出内容既包括新编剧目，也包括莎士比亚和其他人的传统剧目。有些剧团也会花时间去国外采风，通常是去加拿大、夏威夷、澳大利亚和欧洲大陆。 20 年代后期出现了有声电影，不少默片时代的明星难以适应有声电影的冲击，挥舞手臂的夸张扮演从此让位给了细致入微的角色特写。这段时间前期的明星包括约翰·加菲尔德和弗兰西斯·布什曼，后期则是贾莱·库珀和琼·克劳馥。
A7: 5 | B7: 演员-电影演员 | D7: 20 | E7: 90 | F7: 教育×2＋外貌×2 | G7: =EDU*2+APP*2 -> 270 | H7: 技艺（表演），乔装，汽车驾驶，两项社交技能（取悦、话术、恐吓、说服），心理学，任意两项其他个人或时代特长（如骑乘或格斗）。 | L7: 电影工作室，媒体评论员，作家。 | N7: 一般指舞台剧演员和电影演员。许多演员有相当深厚的文化素养，认为自己才是“正统”的，倾向于轻视电影业的商业活动。直到20 世纪后期电影业的地位提高，电影演员的薪酬增加，这种情况才发生改变。 电影业和电影明星一直是世界人民关注的焦点。许多明星一夜成名，在媒体的聚光灯下过着光鲜亮丽的生活。 在1920 年代，虽然全国都有大型剧院，美国的戏剧中心仍然是纽约城。英国的情况与之相近，戏剧的中心在伦敦，其他的剧团则在各郡作巡回演出。巡回剧团乘火车旅行，演出内容既包括新编剧目，也包括莎士比亚和其他人的传统剧目。有些剧团也会花时间去国外采风，通常是去加拿大、夏威夷、澳大利亚和欧洲大陆。 20 年代后期出现了有声电影，不少默片时代的明星难以适应有声电影的冲击，挥舞手臂的夸张扮演从此让位给了细致入微的角色特写。这段时间前期的明星包括约翰·加菲尔德和弗兰西斯·布什曼，后期则是贾莱·库珀和琼·克劳馥。
A8: 6 | B8: 事务所侦探/保安 | D8: 20 | E8: 45 | F8: 教育×2＋力量或敏捷×2 | G8: =EDU*2+MAX(STR*2,DEX*2) -> 250 | H8: 一项社交技能（取悦、话术、恐吓、说服），格斗（斗殴），射击，法律，图书馆，心理学，潜行，追踪。 | L8: 本地执法机构，客户。 | N8: 世界上有许多著名的侦探机构，其中最著名的是平克顿和伯恩斯调查局(后来合并成一家公司)。这样的公司一般有两类工作人员：安保人员和调查人员。 企业或个人雇用安保人员来保护自己的资产和人员免受盗贼、刺客和绑匪的威胁。这些安保人员角色使用巡警的职业模板。调查人员则是便衣侦探，负责为公司客户解决各种异常事件、阻止谋杀事件、寻找失踪的人员等等。
A9: 7 | B9: 精神病医生（古典） | D9: 10 | E9: 60 | F9: 教育×4 | G9: =EDU*4 -> 220 | H9: 法律，聆听，医学，外语，精神分析，心理学，科学（生物学，化学）。 | L9: 其他精神疾病研究者，医生，有时还有执法机构的侦探。 | N9: 在1920 年代，“精神病医生”这个词专用来称呼治疗精神失常的医生(也就是早期的精神科医生)。精神分析在当时的美国鲜为人知，而且它的基本内容都是性生活和如厕训练之类令大众不齿的东西。精神病学，一种正规的从行为主义发展来的医学理论则要普及得多。精神病医生、精神科医生和神经科医生还经常爆发激烈的论战。
A10: 8 | B10: 动物训练师 | D10: 10 | E10: 40 | F10: 教育×2＋外貌或意志×2 | G10: =EDU*2+MAX(APP*2,POW*2) -> 270 | H10: 跳跃，聆听，自然，心理学，科学（动物学），潜行，追踪，任意一项其他个人或时代特长。 | L10: 动物园，马戏团，赞助人，演员。 | N10: 动物训练师可能在电影工作室、巡回马戏团、马厩工作或自由工作。不管是训练导盲犬、狮子钻火圈，他们工作时基本要独自一人长时间近距离地照看这些动物。动物训练师可以像对人一样对动物使用「心理学」技能。
A11: 9 | B11: 文物学家（原作向） | D11: 30 | E11: 70 | F11: 教育×4 | G11: =EDU*4 -> 220 | H11: 估价，技艺（任一），历史，图书馆，外语，一项社交技能（取悦、话术、恐吓、说服），侦查，任意一项其他个人或时代特长。 | J11: 任意特长数: | L11: 书商，古董收藏者，历史研究学会。 | N11: 文物学家也许是调查员可以从事的最具有洛夫克拉夫特风格的职业：那些历久弥新的的卓越作品、湮没在古代传说中的神奇力量，总能使他们乐在其中。独立的收入使文物学家能够研究古旧晦涩的文物，或者根据自己的兴趣爱好集中探寻特别的种类。他们通常有着欣赏的眼光、敏锐的头脑，和讽刺无知、自大、贪婪者的愚蠢时尖酸刻薄的幽默。
A12: 10 | B12: 古董商 | D12: 30 | E12: 50 | F12: 教育×4 | G12: =EDU*4 -> 220 | H12: 会计，估价，汽车驾驶，两项社交技能（取悦、话术、恐吓、说服），历史，图书馆，导航。 | L12: 本地的历史学家，其他古董商，可能还包括赝造师。 | N12: 古董商通常自己开店，从自己所在的地方转卖物品，或继续扩展业务范围，通过倒卖物品到城市商店赚取利润。
A13: 11 | B13: 考古学家（原作向） | D13: 10 | E13: 40 | F13: 教育×4 | G13: =EDU*4 -> 220 | H13: 估价，考古，历史，外语，图书馆，侦查，机械维修，导航或科学（任一：如化学、物理、地理等）。 | I13: 自定义职业属性 | L13: 赞助人，博物馆，大学。 | N13: 考古学家研究探索历史的痕迹。主要来说，是对人类历史相关的物质数据进行各种鉴识、检查、分析。这项工作包含辛苦细致的研究，更不必提情愿亲自下斗铲土的决心。 在1920 年代，成功的考古学家会被当成著名冒险家与探险家，名利双收。有人运用科学方法考古，不过更多的人对付老祖宗的秘密时喜好暴力破解的办法，甚至祭出炸药，这种碉堡了的办法现代人可是很难看得惯的。
A14: 12 | B14: 建筑师 | D14: 30 | E14: 70 | F14: 教育×4 | G14: =EDU*4 -> 220 | H14: 会计，技艺（技术制图），法律，母语，计算机或图书馆，说服，心理学，科学（数学）。 | I14: 属性名称 | J14: 是否使用 | K14: 使用倍数 | L14: 本地建设和城市规划部门，建筑公司。 | N14: 建筑师掌握设计和营造建筑的知识，不论是个人房屋的改造还是造价数百万美元的地标工程。建筑师与项目经理紧密合作，负责监督施工全程。建筑师必须了解当地的规划法律，健康和安全法规，和基础的公众安全原则。他们既可以在大公司工作，也可以自由工作，这在很大程度上取决于信誉。 在1920 年代，许多人尝试在自家或小办公室单干。不过他们苦心创造的宏伟设计很少能卖得出去。 建筑师也可能专擅某一学科，比如军事建筑或景观工程等。
A15: 13 | B15: 艺术家 | D15: 9 | E15: 50 | F15: 教育×2＋敏捷或意志×2 | G15: =EDU*2+MAX(DEX*2,POW*2) -> 250 | H15: 技艺（任一），历史或自然，一项社交技能（取悦、话术、恐吓、说服），外语，心理学，侦查，任意两项其他个人或时代特长。 | I15: 力量 | J15: √ | K15: =IF(J15="√",2,0) -> 2 | L15: 美术馆，美术批评家，富有的赞助人，广告业者。 | N15: 艺术家在这里可以是画家，雕塑家等等。他们有时沈浸于自己虚幻的想象当中，有时又沐浴在激发热情和理解的灵感之下。不论是否天资优秀，艺术家的内心必须足够强大，这样才能战胜生涯起步时的障碍和挑剔的眼光，并且在自己小有名气以后继续努力。有些艺术家对物质生活是否丰富并不在乎，而有些则有着强烈的创业倾向。
A16: 14 | B16: 精神病院看护 | D16: 8 | E16: 20 | F16: 教育×2＋力量或敏捷×2 | G16: =EDU*2+MAX(STR*2,DEX*2) -> 250 | H16: 闪避，格斗（斗殴），急救，两项社交技能（取悦、话术、恐吓、说服），聆听，心理学，潜行。 | I16: 敏捷 | J16: × | K16: =IF(J16="√",2,0) -> 0 | L16: 医护人员，患者和患者家属。允许接触医疗记录、药品或其他医疗用品。 | N16: 尽管少数富有的人会选择私人疗养院，大多精神病患者最终会被安置到州县设置的定点医院。这些地方除了医生护士以外，还会有一支看护队伍。选聘看护的时候，力量和体格往往比医学知识更被看重。
A17: 15 | B17: 运动员 | D17: 9 | E17: 70 | F17: 教育×2＋力量或敏捷×2 | G17: =EDU*2+MAX(STR*2,DEX*2) -> 250 | H17: 攀爬，跳跃，格斗（斗殴），骑乘，一项社交技能（取悦、话术、恐吓、说服），游泳，投掷，任意一项其他个人或时代特长。 | I17: 体质 | J17: √ | K17: =IF(J17="√",2,0) -> 2 | L17: 体育界，体育专栏作家，其他明星。 | N17: 运动员可能效力于职业的棒球、足球、板球或者篮球队伍。这支队伍也许是大联盟队伍，有着稳定工资，参加的比赛万人瞩目；或者是众多小联盟队伍之一，尤其是在1920 年代的棒球界。这些队伍往往寄于大联盟队伍篱下，各方面都受其管理，工资更是刚够运动员糊口又不至于让他们跳槽的水平。 成功的运动员在自己的专业领域会拥有相当的声誉——现今尤其如此，在世界各地都能看到体育明星和电影明星并肩站在红地毯上的场景。
A18: 16 | B18: 作家（原作向） | D18: 9 | E18: 30 | F18: 教育×4 | G18: =EDU*4 -> 220 | H18: 技艺（文学），历史，图书馆，自然或神秘学，外语，母语，心理学，任意一项其他个人或时代特长。 | I18: 体型 | J18: × | K18: =IF(J18="√",2,0) -> 0 | L18: 出版社，文学评论家，历史学家等。 | N18: 作家不同于记者，他们用文字定义和探讨人们的社会生活，尤其是人们的情感变化。他们的劳动通常孤立而又自我中心：虽然以前写作是个能稳拿工资的行当，但如今只靠写作发大财的人屈指可数。 作家的工作习惯相差极大。通常作家们会花费数月乃至数年的时间调查取材，为新书的创作做准备；然后闭门谢客，投入紧张的创作。 | V18: =IF(K39="是",I40,0) -> 0
A19: 17 | B19: 酒保 | D19: 8 | E19: 25 | F19: 教育×2＋外貌×2 | G19: =EDU*2+APP*2 -> 270 | H19: 会计，两项社交技能（取悦、话术、恐吓、说服），格斗（斗殴），聆听，心理学，侦查，任意一项其他个人或时代特长。 | I19: 外貌 | J19: × | K19: =IF(J19="√",2,0) -> 0 | L19: 常客，可能有犯罪组织。 | N19: 酒保虽然不一定是酒吧的掌柜，却一定是所有客人的朋友。对客人们的好声气，一部分来说是出于他们的职业或者业务，而更多的来说则是达到目的的一种手段。 1920 年代，由于禁酒令的存在，酒保变成了非法的职业；但是遍地开花的黑酒吧又不能没有酒保，结果就是酒保仍然不愁找不到活干。 | V19: =IF(K51="是",I52,0) -> 0
A20: 18 | B20: 猎人 | D20: 20 | E20: 50 | F20: 教育×2＋力量或敏捷×2 | G20: =EDU*2+MAX(STR*2,DEX*2) -> 250 | H20: 射击，聆听或侦查，自然，导航，外语或生存（任一），科学（生物学或植物学），潜行，追踪。 | I20: 智力 | J20: × | K20: =IF(J20="√",2,0) -> 0 | L20: 外国政府官员，狩猎监管人员，前客户(大多很有钱)，黑市商人与黑社会，动物园主。 | N20: 猎人是优秀的追踪者和狩猎者，通常靠为富裕的客户捕猎为生。绝大多数猎人会对地球上某一个部分的情况烂熟于心，比如加拿大森林、非洲草原等等。有些人可能从事盗猎活动，例如为私人收藏家捕捉珍稀动物，或者贩卖受保护的动物和违反道德的动物制品，如兽皮、象牙之类——虽然1920 年代大多数国家这些活动都不算违法。 尽管“王牌猎人”是最典型的类型，不过在加拿大育空的深山老林里打驼鹿和熊为生的土著人也可以算是猎人。 | V20: =IF(K63="是",I64,0) -> 0
A21: 19 | B21: 书商 | D21: 20 | E21: 40 | F21: 教育×4 | G21: =EDU*4 -> 220 | H21: 会计，估价，汽车驾驶，历史，图书馆，母语，外语，一项社交技能（取悦、话术、恐吓、说服）。 | I21: 教育 | J21: √ | K21: =IF(J21="√",IF(SUM(K15:K20,K22:K23)>0,2,4),0) -> 2 | L21: 目录学家、其他书商、图书馆和大学、客户。 | N21: 书商可能拥有自己的店面或者利基(小众)邮购服务，也可能辗转全国甚至海外专门经销书籍。许多人拥有富有的，能提供利润丰厚又稀罕的工作的固定客户。
A22: 20 | B22: 赏金猎人 | D22: 9 | E22: 30 | F22: 教育×2＋力量或敏捷×2 | G22: =EDU*2+MAX(STR*2,DEX*2) -> 250 | H22: 汽车驾驶，电子学或电气维修，格斗或射击，一项社交技能（取悦、话术、恐吓、说服），法律，心理学，追踪，潜行。 | I22: 意志 | J22: × | K22: =IF(J22="√",2,0) -> 0 | L22: 保释业者，本地警察，线人。 | N22: 赏金猎人捉拿罪犯并将他们交给正义去审判。最常见的情况是受保释人的委托去缉捕逃狱者。赏金猎人们为了自己的猎物可以不择手段，几乎不会考虑其他人的正当权益之类细枝末节的东西。 非法闯入、威胁、肢体暴力，都是赏金猎人屡试不爽的秘技。现在这些秘技还包括了电话窃听、黑客操作和其他的秘密监控。 (译注：所谓保释业者。向法院交纳保释金，可以在审判之前免受收押；若被保释者按时接受审判，法院会退还保释金。保释金数额较大，故有保释业者以提供保释金收取手续费为业。)
A23: 21 | B23: 拳击手/摔跤手 | D23: 9 | E23: 60 | F23: 教育×2＋力量×2 | G23: =EDU*2+STR*2 -> 170 | H23: 闪避，格斗（斗殴），恐吓，跳跃，心理学，侦查，任意两项其他个人或时代特长。 | I23: 幸运 | J23: × | K23: =IF(J23="√",2,0) -> 0 | L23: 运动会主办者，记者，犯罪组织，专业训练人员。 | N23: 拳击手和摔跤手各分为职业和业余两种。 职业拳击手和职业摔角手的活动由外部利益支持的贸助人安排，并有合同约束。他们还要进行全日制的工作和训练。 业余拳击的竞赛种类非常丰富，同时它也是那些想成为职业拳手的人的训练场。不过也有业余和准职业的选手靠参加黑市拳击赛谋生，举办这些比赛的通常是本地的黑社会或者是从中渔利的庄家。
A24: 22 | B24: 管家/男仆/女仆 | D24: 9 | E24: 40 | F24: 教育×4 | G24: =EDU*4 -> 220 | H24: 会计或估价，技艺（任一：如烹饪、裁缝、理发），急救，聆听，外语，心理学，侦查，任意一项其他个人或时代特长。 | I24: 计算方式 | V24: 检查有没有被使用
A25: 23 | B25: 神职人员 | D25: 9 | E25: 60 | F25: 教育×4 | G25: =EDU*4 -> 220 | H25: 会计，历史，图书馆，聆听，外语，一项社交技能（取悦、话术、恐吓、说服），心理学，任意一项其他技能。 | I25: 教育+其他属性点数中的最大值(官方) | L25: 教会高层、地方教会、小区领导。 | N25: 神职人员通常担任一个教区的牧师，或是经过分配外出传教，尤其是去国外(见传教士)。 不同的教会工作的侧重点和组织结构各不相同，如天主教会的牧师可能上升到主教、大主教和红衣主教，而一个卫理公会的牧师则会升职到教区主管和主教。 许多神职人员都接受忏悔(不仅仅是天主教)。虽然不能透露忏悔的内容，但是要怎样利用它们就全凭他们自己了。 有些教职人员在教堂接受医生、律师、学者的专业培训。这样的调查员应该选择最符合自己工作的职业模板。 | V25: =IF(K39="是",IF(职业列表!$I$31="社交技能","☯","☆"),"")
A26: 24 | B26: 程序员/电子工程师（现代） | D26: 10 | E26: 70 | F26: 教育×4 | G26: =EDU*4 -> 220 | H26: 计算机，电气维修，电子学、图书馆，科学（数学），侦查，任意两项其他个人或时代特长。 | I26: =F3 -> 教育×2+力量×2或体质×2 | L26: 其他IT 工作者，同事和上司，专业网络小区。 | N26: 计算器程序员通常是设计、编写、测试、调试和维护计算器程序源代码的职业。他们精通从形式逻辑到系统平台(程序运行环境)的各种知识，可能是自由工作者，也可能供职于软件开发部门。 计算器技术人员负责计算器系统和网络的开发和维护工作，经常与其他人员(如项目经理)合作来保证系统的完整稳定和正常提供所需功能。类似的职业还包括数据库管理员、系统管理员、网络管理员、多媒体开发人员、软件工程师、网络管理员等。 | V26: =IF(K51="是",IF(职业列表!$I$43="社交技能","☯","⊙"),"") | W26: 检查有没有
A27: 25 | B27: 黑客/骇客（现代） | D27: 10 | E27: 70 | F27: 教育×4 | G27: =EDU*4 -> 220 | H27: 计算机，电气维修，电子学，图书馆，侦查，一项社交技能（取悦、话术、恐吓、说服），任意两项其他技能。 | L27: 其他IT 工作者，专业网络小区，政治团体，犯罪组织。 | N27: 计算器黑客利用计算器和计算器网络为手段，进行干扰或破坏以达成政治目的(有时被称为“政治黑客”)或获取非法利益。达成目标的手段主要是非法入侵计算器和其他用户帐户，目的则可能包括篡改网页、人肉搜索、盗取身份信息、垃圾邮件炸弹、拒绝服务攻击等等。 | V27: =IF(K63="是",IF(职业列表!$I$55="社交技能","☯","※"),"") | W27: =IF(ISNUMBER(职业列表!$J$3+职业列表!$J$4+职业列表!$J$5+职业列表!$J$6+职业列表!$J$7+职业列表!$J$8+职业列表!$J$9+职业列表!$J$10),0,1) -> 0
A28: 26 | B28: 牛仔 | D28: 9 | E28: 20 | F28: 教育×2＋力量或敏捷×2 | G28: =EDU*2+MAX(STR*2,DEX*2) -> 250 | H28: 闪避，格斗或射击，急救或自然，跳跃，骑乘，生存（任一），投掷，追踪。 | L28: 本地企业家，州农业部门，牛仔比赛主办者，艺人。 | N28: 牛仔在西部的牧区和牧场工作。有些人拥有自己的牧场，更多的则是在各处打工为生。想赚大钱的牛仔会去冒着丢胳膊少腿乃至送命的危险参加牛仔巡回赛，通过旅行获取名誉。 在1920 年代，一些牛仔能在好莱坞找到西部片替身演员和群众演员的工作，例如怀特·厄普就曾为西部电影担任顾问。在现代，有些牧场也对想要体验一把牛仔生活的游客开放。
A29: 27 | B29: 工匠 | D29: 10 | E29: 40 | F29: 教育×2＋敏捷×2 | G29: =EDU*2+DEX*2 -> 250 | H29: 会计，技艺（任二），机械维修，自然，侦查，任意两项其他个人或时代特长。 | I29: =V25&"自定义 X 选 X 技能"&V25 -> 自定义 X 选 X 技能
A30: 28 | B30: 罪犯-刺客 | D30: 30 | E30: 60 | F30: 教育×2＋力量或敏捷×2 | G30: =EDU*2+MAX(STR*2,DEX*2) -> 250 | H30: 乔装，电气维修，格斗，射击，锁匠，机械维修，潜行，心理学。 | I30: 备注 | J30: 技能列表 | K30: 选择几项
A31: 29 | B31: 罪犯-银行劫匪 | D31: 5 | E31: 75 | F31: 教育×2＋力量或敏捷×2 | G31: =EDU*2+MAX(STR*2,DEX*2) -> 250 | H31: 汽车驾驶，电气维修或机械维修，格斗，射击，恐吓，锁匠，操作重型机械，任意一项其他个人或时代特长。 | I31: 社交技能 | J31: 恐吓 | K31: 1
A32: 30 | B32: 罪犯-打手/暴徒 | D32: 5 | E32: 30 | F32: 教育×2＋力量×2 | G32: =EDU*2+STR*2 -> 170 | H32: 汽车驾驶，格斗，射击，两项社交技能（取悦、话术、恐吓、说服），心理学，潜行，侦查。 | I32: 如果名称为 “社交技能” 则符号变为☯ | J32: 说服 | U32: =IF(IFERROR(VLOOKUP("驯兽",$J$3:$K$10,1,FALSE),"%^&@%##@^")="驯兽",1,0) -> 0 | W32: 驯兽 | X32: ☆
A33: 31 | B33: 罪犯-窃贼 | D33: 5 | E33: 40 | F33: 教育×2＋敏捷×2 | G33: =EDU*2+DEX*2 -> 250 | H33: 估价，攀爬，电气维修或机械维修，聆听，锁匠，妙手，潜行，侦查。 | J33: 话术 | U33: =IF(IFERROR(VLOOKUP("驯兽",$J$31:$J$39,1,FALSE),"%^&@%##@^")="驯兽",1,0) -> 0 | V33: =IF(IF(IFERROR(VLOOKUP("驯兽",$J$3:$K$10,1,FALSE),"%^&@%##@^")="驯兽",1,0)+IF(IFERROR(VLOOKUP("驯兽",$J$31:$J$39,1,FALSE),"%^&@%##@^")="驯兽",1,0)+IF(IFERROR(VLOOKUP("驯兽",$J$43:$J$51,1,FALSE),"%^&@%##@^")="驯兽",1,0)+IF(IFERROR(VLOOKUP("驯兽",$J$55:$J$63,1,FALSE),"%^&@%##@^")="驯兽",1,0)=0,0,0) -> 0 | W33: =_xlfn.IFS(IF(IFERROR(VLOOKUP("驯兽",职业列表!$J$3:$K$10,1,FALSE),"%^&@%##@^")="驯兽",1,0)=1,"★",IF(IFERROR(VLOOKUP("驯兽",职业列表!$J$31:$J$39,1,FALSE),"%^&@%##@^")="驯兽",1,0)=1,IF($I$31="社交技能","☯","☆"),IF(IFERROR(VLOOKUP("驯兽",职业列表!$J$43:$J$51,1,FALSE),"%^&@%##@^")="驯兽",1,0)=1,IF($I$43="社交技能","☯","⊙"),IF(IFERROR(VLOOKUP("驯兽",职业列表!$J$55:$J$63,1,FALSE),"%^&@%##@^")="驯兽",1,0)=1,IF($I$55="社交技能","☯","※"),IF(IFERROR(VLOOKUP("驯兽",职业列表!$J$3:$K$10,1,FALSE),"%^&@%##@^")="驯兽",1,0)+IF(IFERROR(VLOOKUP("驯兽",职业列表!$J$31:$J$39,1,FALSE),"%^&@%##@^")="驯兽",1,0)+IF(IFERROR(VLOOKUP("驯兽",职业列表!$J$43:$J$51,1,FALSE),"%^&@%##@^")="驯兽",1,0)+IF(IFERROR(VLOOKUP("驯兽",职业列表!$J$55:$J$63,1,FALSE),"%^&@%##@^")="驯兽",1,0)=0,0) -> 0 | X33: ※
A34: 32 | B34: 罪犯-欺诈师 | D34: 10 | E34: 65 | F34: 教育×2＋外貌×2 | G34: =EDU*2+APP*2 -> 270 | H34: 估价，技艺（表演），法律或外语，聆听，两项社交技能（取悦、话术、恐吓、说服），心理学，妙手。 | J34: 取悦 | U34: =IF(IFERROR(VLOOKUP("驯兽",$J$43:$J$51,1,FALSE),"%^&@%##@^")="驯兽",1,0) -> 0 | X34: ☯
A35: 33 | B35: 罪犯-独行罪犯 | D35: 5 | E35: 65 | F35: 教育×2＋敏捷或外貌×2 | G35: =EDU*2+MAX(DEX*2,APP*2) -> 270 | H35: 技艺（表演）或乔装，估价，一项社交技能（取悦、话术、恐吓、说服），格斗或射击，锁匠或机械维修，潜行，心理学，侦查。 | U35: =IF(IFERROR(VLOOKUP("驯兽",$J$55:$J$63,1,FALSE),"%^&@%##@^")="驯兽",1,0) -> 0 | X35: ⊙
A36: 34 | B36: 罪犯-女飞贼（古典） | D36: 10 | E36: 80 | F36: 教育×2＋外貌×2 | G36: =EDU*2+APP*2 -> 270 | H36: 技艺（任意），两项社交技能（取悦、话术、恐吓、说服），格斗（斗殴）或射击（手枪），汽车驾驶，聆听，潜行，任意一项其他个人或时代特长。
A37: 35 | B37: 罪犯-赃物贩子 | D37: 20 | E37: 40 | F37: 教育×2＋外貌×2 | G37: =EDU*2+APP*2 -> 270 | H37: 会计，估价，技艺（伪造），历史，一项社交技能（取悦、话术、恐吓、说服），图书馆，侦查，任意一项其他技能。
A38: 36 | B38: 罪犯-赝造者 | D38: 20 | E38: 60 | F38: 教育×4 | G38: =EDU*4 -> 220 | H38: 会计，估价，技艺（伪造），历史，图书馆，侦查，妙手，任意一项其他个人或时代特长（如计算机）。 | K38: 是否选用?
A39: 37 | B39: 罪犯-走私者 | D39: 20 | E39: 60 | F39: 教育×2＋外貌或敏捷×2 | G39: =EDU*2+MAX(DEX*2,APP*2) -> 270 | H39: 射击，聆听，导航，一项社交技能（取悦、话术、恐吓、说服），汽车驾驶或驾驶（飞行器或船），心理学，妙手，侦查。 | K39: 否
A40: 38 | B40: 罪犯-混混 | D40: 3 | E40: 10 | F40: 教育×2＋力量或敏捷×2 | G40: =EDU*2+MAX(STR*2,DEX*2) -> 250 | H40: 攀爬，一项社交技能（取悦、话术、恐吓、说服），格斗，射击，跳跃，妙手，潜行，投掷。 | I40: =_xlfn.IFS(附表!P74=0,"",附表!P74=1,附表!O75&附表!Q85,附表!P74=2,附表!O76&附表!Q85,附表!P74=3,附表!O74&附表!Q85) -> 一项社交技能:(恐吓、说服、话术、取悦)
...

Sheet 技能注释
A2: 需要注意的是：艺术与手艺是试做部分，这些技能的注释仅供参考。 玩家也可以添加更多手艺，比如：游戏，木工，油漆工，铁匠之类的。 具体作用和KP交流好左边是自定义表,在下面写好改技能的备注(用法) | B2: 技能查询 | N2: 技能成功等级与注释
B3: 技能名称 | E3: 基础成功率 | G3: 特殊适用 | I3: 成功难度等级取决于 | N3: 成功率 | O3: 解释
B4: 会计 | E4: =IF($B4=附表!B213,"【←下拉框】",VLOOKUP($B4,附表!B95:K212,2,FALSE)) -> 5% | G4: =IF($B4=附表!B213,"",VLOOKUP($B4,附表!B95:K212,3,FALSE)) -> —— | I4: =IF($B4=附表!B213,"",VLOOKUP($B4,附表!B95:K212,4,FALSE)) -> 如果有人想要隐瞒什么，那么难度等级将会取决于进行隐藏的人的会计技能。 | N4: 0 | O4: 并不知晓有这种学问或技能的存在。
N6: 1-5 | O6: 完完全全的门外汉，仅仅是知道有这种技能而已
N8: 5-10 | O8: 经过了最基础的了解，可以说出一两个专业名词，但是实际操作几乎不可能。
B10: 孤注一掷示例 | I10: 普通难度 | K10: 困难难度 | N10: 11-19 | O10: 自行摸索的自学或经过一段不认真的教育（指学习与教课双方）之后获取的知识。
B11: =IF($B4=附表!B213,"",VLOOKUP($B4,附表!B95:K212,8,FALSE)) -> · 花费更多的时间来阅览文档 · 拜访银行或者企业来确认自己的发现 · 复核里面的账目和数据 | I11: =IF($B4=附表!B213,"",VLOOKUP($B4,附表!B95:K212,6,FALSE)) -> 详尽以及良好整理的会计账簿。 | K11: =IF($B4=附表!B213,"",VLOOKUP($B4,附表!B95:K212,7,FALSE)) -> 无序或者残缺的会计账簿。
N12: 20-25 | O12: 非常有天赋或非常努力的人可以在短时间内达到这种程度，再或者一些知识渊博的人也能得到这个级别的知识。
N14: 26-39 | O14: 一定时间内经过了系统式的教育或名师指导。对这方面拥有了一个初步的了解，专业性上比普通人都要强， 但是实际操作依旧有些困难。
N17: 40-49 | O17: 对这方面拥有很高的热情，但基础知识或学习时间依旧没有达到标准。 这阶段很可能是一个瓶颈期
N20: 50 | O20: 已经可以以此为生但依旧不是非常熟练 如果以该技能为职业至少要达到50
N23: 51-70 | O23: 不断精进的技术，虽然放到同行里一抓一大把，但是基本上已经可以独当一面了。
B24: 孤注一掷失败的范例结果 | H24: 疯狂调查员孤注一掷失败的范例结果
B25: =IF($B4=附表!B213,"",VLOOKUP($B4,附表!B95:K212,9,FALSE)) -> · 调查员与其他人之间的讨论让敌对势力对调查员的意图起了警觉 · 账簿最重要的一部分被摧毁或者丢失了（可能调查员因为疲劳将咖啡洒出在了上面）。 | H25: =IF($B4=附表!B213,"",VLOOKUP($B4,附表!B95:K212,10,FALSE)) -> 他可能会被发现他把部分的账簿吃下了肚。 | N25: 71-80 | O25: 在一定范围内你具有了比较高的知名度，虽然不至于成为权威但是已经是一个很好的咨询对象了。 对于这个技能你无论怎么操作都非常得心应手（除了更加精进的钻研自己 的技术或说服流氓同行）
N28: 81-90 | O28: 该专业的权威，即使你仅靠这方面的技能也能得到很多人的重视与保护。
N30: 91-99 | O30: 伟人级别，如果你有时间有精力，绝对可以创造一个不可磨灭的瑰宝留给后世纪子孙。
N32: 100 | O32: 在当代，和这方面有关的事情你已经无所不知了，如果出现了一种你不认识的东西，这种东西就会被称为：新大陆
N34: 101-110 | O34: 对于这方面拥有全新的解释或发现，并且已经初步了解了这些新知识。
N36: 111-140 | O36: 超越本时代几乎所有人，能和你平起平坐的应该不会超过十个人。拥有着大量的发明创造， 甚至在之后很长一段时间内都会不分国界的被世纪人记住
B39: 技能解释 | N39: 150 | O39: 进入了超时代的知识领域，即使穿越也可以成为该领域的专家 从这个阶段开始和其相关的领域知识也会一并提高，并且可能是超时代的
B40: =IF($B4=附表!B213,"",VLOOKUP($B4,附表!B95:K212,5,FALSE)) -> · 使你理解会计工作的流程以及一个企业或者个人的金融职务。 · 通过检查账簿，你可以发现做假账的员工，对资金的偷偷挪用，对行贿或者敲诈的款项支付，以及经济状况是否比表面陈述的更好或者更差。 · 通过仔细检查旧账户，你可以了解过去的资金的得与失（谷物，奴隶贸易，威士忌酒的运营等）以及这些资金是付给了谁以及为了什么款项而支付。
N43: 500 | O43: 在这方面上几乎所有知识的获取，已经没有任何成长的必要了，再获取的知识也不过是一些鸡毛蒜皮的小事
O45: 如果你发现了难以理解的翻译、不完整的显示、或是其他各种问题请联系作者（在更新说明页有联系方式）
B64: 技能可选规则
B68: 专业技能：可以转移的技能优势
B70: 艺术和手艺 | O70: 语言
B72: 当一名角色的某些类似的技能与学问的成功率 提升到50%以上的时候： | H72: 当一名角色的某些类似的技能与学问的成功率 提升到90%以上的时候： | O72: 当一名角色将一种非母语语言的成功率 提升到了50%以上的时候： | U72: 当一名角色将一种非母语语言的成功率 提升到了90%以上的时候：
B75: 其他所有类似技能都会提升10% 但是不能超过50% | H75: 其他所有类似技能又会提升10% 但是不能超过90% | O75: 其他所有同语系的语言都会提升10% 但是不能超过50% | U75: 其他所有同语系的语言都会提升10% 但是不能超过90%
B77: 例如：作画成功率上升到50%的时候 书法、伪造、技术制图之类的的成功率都会提升10% 但假如技术制图的成功率是70%，那么它将则不会成长 | O77: 例如：德语成功率上升到50%的时候 在印欧语系内的英语、法语、意大利语、西班牙等的成功率都会提升10% 但假如英语的成功率是70%，那么英语则不会成长
B81: 格斗、生存、驾驶、社交类、治疗类、维修类、科学、神话等 只要是KP认为有关联的技能都可以运用此规则
N82: 这是一张展示世纪界语系的地图（来自维基百科2018）
B84: 当然这属于一个可选规则，kp也可以不选择此规则（看看我们的KP是善良还是邪恶呢~）
B85: 另外，上述的10%是直接在现有值里增长10点，不是现有的成功率乘以0.1
B94: 可选规则：给技能等级安个保险
B96: 如果你担心原版规则的职业技能最高可以达到90%这点会影响游戏的话。 你可以要求PL在车卡的时候不能将技能的成功率点到XX%以上。 当然兴趣技能也可以运用此规则。
B102: 例如：KP在跑团之前放公告或提醒大家“这次跑团的技能上限是70/60” 这里的70/60，就是职业技能成功率最高70% 兴趣技能成功率最高可以达到60%
B113: 游戏系统少见规则
B117: 幕间成长：90%或更多的技能值 | G117: 对抗检定平手 | L117: 超越人体极限：多调查员协作检定 | U117: 调查员幕间成长（超越100）
B119: 于幕间成长中： 若一位调查员有技能达到了 90%或更高，为他的当前SAN值增加 2D6 。 这一奖励表示经过磨练从精通一项技能中获得的自信。 | G119: 若在同属性或同技能的对抗中双方的成功等级相同： 技能（或属性）更高的一方获胜 若仍然相同则双方重新再骰一次 对抗不能孤注一掷 | L119: 调查员们只是人类，所以物理上存在能力的极限。 当对手拥有90或更高的属性时难度等级将为极难。 超过100+的技能和属性对于调查员来说是无法对抗的。比如一个人类不可能在力量方面上对抗一个力量220的黑山羊幼崽。 | U119: 除了意志和体型，人类的属性最大值都被定为了99，但是技能和属性不一样。 技能不仅能够更加精进更加熟练，而且用的越多越容易更熟练，而且还可以超越时代的熟练。 当你获得了99点的技能，不要担心ta会就此止步。 在幕间成长投出大于95的数字就可以为技能增加1D10的成功率，哪怕这个技能的成功率已经10000了也可以成长
L124: 但是人类之所以是人类就是因为他们能做到不可能的事情
...

Sheet 附表
AJ1: 自定义职业属性
B2: 移动力计算 | S2: 自定义职业
A3: 护甲表减值 是否开启 | B3: 护甲表减值 | C3: 年龄减值 | D3: 力量-体型 | E3: =G14-I14 -> -25 | G3: 技能雷达表 | H3: 值 | I3: 总数 | J3: 百分比 | N3: 伤害加值与体格 | S3: 属性名称 | T3: shiyong | U3: 使用倍数 | W3: 显示 | X3: 查看之后 | Y3: 是否为空 | Z3: 计算 | AA3: 出
D4: 敏捷-体型 | E4: =J14-I14 -> 15 | G4: 调查 | H4: 交涉 | I4: 战斗 | J4: 特技 | K4: 支援 | L4: 学问 | N4: 力量+体型 | S4: ="力量×"&U4 -> 力量×2 | T4: =职业列表!J15 -> √ | U4: =职业列表!K15 -> 2 | W4: =IF(U10>0,S10,"") -> 教育×2 | Y4: =IF(W4="",1,0) -> 0 | Z4: =G14*U4 -> 60 | AA4: =IF(Y5+Y6+Y7+Y8+Y9+Y10+Y11+Y12=8,"",IF(U10=0,"","+")) -> + | AH4: =IF(U4=0,"",G14*U4) -> 60 | AJ4: =IF(U4=0,"",G14*U4) -> 60
A5: =IF(人物卡!AI12="开",1,IF(人物卡!AI12="关",0)) -> 0 | B5: =IF(人物卡!AN12=0,"0",VLOOKUP(人物卡!AN12,'防具表 载具表'!B2:I101,3,FALSE)) | C5: =IF(人物卡!E4<40,0,INT((人物卡!E4/10)-3)) -> 0 | D5: 力量大小 | E5: =IF(E3>0,"1",IF(E3=0,"0",IF(E3<0,"-1"))) -> -1 | G5: =AVERAGE(人物卡!AA7+人物卡!R17+人物卡!R18+人物卡!R19+人物卡!R20+人物卡!R26+人物卡!R28+人物卡!R47+人物卡!R48+人物卡!R49+人物卡!AN18+人物卡!AN19+人物卡!AN23+人物卡!AN25+人物卡!AN29+人物卡!AN30+人物卡!AN36+人物卡!AN41+人物卡!AN45-122) -> 235 | H5: =AVERAGE(人物卡!AA5+人物卡!R18+人物卡!R19+人物卡!R24+人物卡!R27+人物卡!R29+人物卡!R34+人物卡!R45+人物卡!R47+人物卡!R48+人物卡!R49+人物卡!R50+人物卡!AN17+人物卡!AN27+人物卡!AN29+人物卡!AN30+人物卡!AN36+人物卡!AN41+人物卡!AN45-111-人物卡!J50) -> 325 | I5: =AVERAGE((人物卡!U3+人物卡!U7)/2+人物卡!U5+人物卡!AA3+人物卡!R30+人物卡!R35+人物卡!R36+人物卡!R37+人物卡!R39+人物卡!R40+人物卡!R41+人物卡!R45+人物卡!R46+人物卡!AN19+人物卡!AN26+人物卡!AN30+人物卡!AN31+人物卡!AN36+人物卡!AN37+人物卡!AN40+人物卡!AN42+人物卡!AN44+人物卡!AN46+人物卡!AN47-189-人物卡!J30) -> 382.5 | J5: =AVERAGE(人物卡!AA3+人物卡!R20+人物卡!R21+人物卡!R22+人物卡!R23+人物卡!R25+人物卡!R29+人物卡!R31+人物卡!R32+人物卡!R46+人物卡!AN20+人物卡!AN21+人物卡!AN22+人物卡!AN24+人物卡!AN26+人物卡!AN28+人物卡!AN31+人物卡!AN35+人物卡!AN37+人物卡!AN38+人物卡!AN39+人物卡!AN40+人物卡!AN41+人物卡!AN42+人物卡!AN43+人物卡!AN44+人物卡!AN46+人物卡!AN47-219) -> 180 | K5: =AVERAGE(人物卡!R43+人物卡!AN22+人物卡!AN29+人物卡!R31+人物卡!AN28+人物卡!AN31+人物卡!AN24+人物卡!R27+人物卡!R18+人物卡!AN42+人物卡!AN46+人物卡!AN47-76) -> 20 | L5: =AVERAGE(人物卡!AG5+人物卡!AA7+人物卡!R17+人物卡!R18+人物卡!R26+人物卡!R28+人物卡!R33+人物卡!R44+人物卡!R47+人物卡!R48+人物卡!R49+人物卡!R50-人物卡!J50+人物卡!AN17+人物卡!AN18+人物卡!AN22+人物卡!AN23+人物卡!AN25+人物卡!AN29+人物卡!AN30+人物卡!AN32+人物卡!AN33+人物卡!AN34+人物卡!AN45-76) -> 185 | N5: =G14+I14 -> 85 | S5: ="敏捷×"&U5 -> 敏捷×0 | T5: =职业列表!J16 -> × | U5: =职业列表!K16 -> 0 | W5: =IF(U4>0,S4,"") -> 力量×2 | X5: =IF(Y5=0,IF(AB6=1,"或",IF(AB7+AB8=1,"+","")),"") -> 或 | Y5: =IF(W5="",1,0) -> 0 | Z5: =J14*U5 -> 0 | AA5: =IF(Y6+Y7+Y8+Y9+Y10+Y11+Y12=7,"",X5) -> 或 | AB5: =W4&AA4&W5&AA5&W6&AA6&W7&AA7&W8&AA8&W9&AA9&W10&AA10&W11&AA11&W12 -> 教育×2+力量×2或体质×2 | AF5: =SUM(AF6:AF10) -> 210 | AH5: =IF(U5=0,"",J14*U5) | AJ5: =IF(U5=0,"",J14*U5)
B6: 检测是否为数字 | C6: 最终年龄减值 | D6: 敏捷大小 | E6: =IF(E4>0,"1",IF(E4=0,"0",IF(E4<0,"-1"))) -> 1 | J6: =G5+H5+I5+J5+K5+L5 -> 1327.5 | N6: 非八十整数体格 | O6: 减485后八十的倍数 | P6: 最终体格出目 | S6: ="体质×"&U6 -> 体质×2 | T6: =职业列表!J17 -> √ | U6: =职业列表!K17 -> 2 | W6: =IF(U5>0,S5,"") | X6: =IF(Y6=0,IF(AB6=1,"或",IF(AB7+AB8=1,"+","")),"") | Y6: =IF(W6="",1,0) -> 1 | Z6: =H14*U6 -> 100 | AA6: =IF(Y7+Y8+Y9+Y10+Y11+Y12=6,"",X6) | AB6: =IF(AC6=职业列表!I25,1,0) -> 1 | AC6: 教育+其他属性点数中的最大值(官方) | AF6: =IF(AB6=1,AI10+MAX(AH4:AH12),0) -> 210 | AH6: =IF(U6=0,"",H14*U6) -> 100 | AJ6: =IF(U6=0,"",H14*U6) -> 100
B7: =ISNUMBER(B5) -> FALSE | C7: =IF(ISBLANK(人物卡!E4),0,IF(人物卡!E4>=0,C5,0)) -> 0 | D7: 总值 | E7: =E6+E5 -> 0 | G7: 调查 | H7: 交涉 | I7: 战斗 | J7: 特技 | K7: 支援 | L7: 学问 | N7: =IF(N5<=1,"0",IF(N5<=64,"-2",IF(N5<=84,"-1",IF(N5<=124,"0",IF(N5<=164,"1",IF(N5<=204,"2",IF(N5<=284,"3",IF(N5>284,"4","0")))))))) -> 0 | O7: =INT((N5-285)/80) -> -3 | P7: =IF(O7>=0,O7+N7,N7) -> 0 | S7: ="体型×"&U7 -> 体型×0 | T7: =职业列表!J18 -> × | U7: =职业列表!K18 -> 0 | W7: =IF(U6>0,S6,"") -> 体质×2 | X7: =IF(Y7=0,IF(AB6=1,"或",IF(AB7+AB8=1,"+","")),"") -> 或 | Y7: =IF(W7="",1,0) -> 0 | Z7: =I14*U7 -> 0 | AA7: =IF(Y8+Y9+Y10+Y11+Y12=5,"",X7) | AB7: =IF(AC7=职业列表!I25,1,0) -> 0 | AC7: 教育+其他属性点数中的最小值 | AF7: =IF(AB7=1,AI10+MIN(AH4:AH12),0) -> 0 | AH7: =IF(U7=0,"",I14*U7) | AJ7: =IF(U7=0,"",I14*U7)
B8: 护甲表最终减值 | C8: =IF(B7=FALSE,"0",IF(A5=1,B5,0)) -> 0 | D8: 属性最终值 | E8: =IF(E7=2,"1",IF(E7=-2,"-1",0)) -> 0 | G8: =G5/J6 -> 0.17702448 | H8: =H5/J6 -> 0.24482109 | I8: =I5/J6 -> 0.28813559 | J8: =J5/J6 -> 0.13559322 | K8: =K5/J6 -> 0.015065913 | L8: =L5/J6 -> 0.1393597 | N8: 小于1D6的话 | O8: 超过1d6的话 | P8: 最终伤害加值出目 | S8: ="外貌×"&U8 -> 外貌×0 | T8: =职业列表!J19 -> × | U8: =职业列表!K19 -> 0 | W8: =IF(U7>0,S7,"") | X8: =IF(Y8=0,IF(AB6=1,"或",IF(AB7+AB8=1,"+","")),"") | Y8: =IF(W8="",1,0) -> 1 | Z8: =K14*U8 -> 0 | AA8: =IF(Y9+Y10+Y11+Y12=4,"",X8) | AB8: =IF(AC8=职业列表!I25,1,0) -> 0 | AC8: 最高的属性点+其他属性的最大值 | AF8: =IF(AB8=1,MAX(AJ4:AJ12)+LARGE(AJ4:AJ12,2),0) -> 0 | AH8: =IF(U8=0,"",K14*U8) | AJ8: =IF(U8=0,"",K14*U8)
B9: 最终补正值 | C9: =E8-C8-C7 -> 0 | N9: =IF(P7="-2","-2",IF(P7="-1","-1",IF(P7="0","0",IF(P7="1","+1D4",IF(P7=2,"+1D6",IF(P7>2,"D6",0)))))) -> 0 | O9: =IF(N9="D6",P7-1,"0") -> 0 | P9: =IF(N9="D6",O10,N9) -> 0 | S9: ="智力×"&U9 -> 智力×0 | T9: =职业列表!J20 -> × | U9: =职业列表!K20 -> 0 | W9: =IF(U8>0,S8,"") | X9: =IF(Y9=0,IF(AB6=1,"或",IF(AB7+AB8=1,"+","")),"") | Y9: =IF(W9="",1,0) -> 1 | Z9: =L14*U9 -> 0 | AA9: =IF(Y10+Y11+Y12=3,"",X9) | AB9: =IF(AC9=职业列表!I25,1,0) -> 0 | AC9: 最高的属性点+其他属性的最小值 | AF9: =IF(AB9=1,MAX(AJ4:AJ12)+MIN(AJ4:AJ12),0) -> 0 | AH9: =IF(U9=0,"",L14*U9) | AJ9: =IF(U9=0,"",L14*U9)
B10: 格斗射击基础成功率 | O10: ="+"&O9&"D6" -> +0D6 | S10: ="教育×"&U10 -> 教育×2 | T10: =职业列表!J21 -> √ | U10: =职业列表!K21 -> 2 | W10: =IF(U9>0,S9,"") | X10: =IF(Y10=0,IF(AB6=1,"或",IF(AB7+AB8=1,"+","")),"") | Y10: =IF(W10="",1,0) -> 1 | Z10: =N14*U10 -> 110 | AA10: =IF(Y11+Y12=2,"",X10) | AB10: =IF(AC10=职业列表!I25,1,0) -> 0 | AC10: 选择属性点数中的所有值相加 | AF10: =IF(AB10=1,SUM(AJ4:AJ12),0) -> 0 | AH10: ="" | AI10: =IF(U10=0,0,N14*U10) -> 110 | AJ10: =IF(U10=0,"",N14*U10) -> 110
B11: 格斗1 | C11: =IF(人物卡!H36="鞭子","5",IF(人物卡!H36="电锯","10",IF(人物卡!H36="斧","15",IF(人物卡!H36="剑","20",IF(人物卡!H36="绞具","15",IF(人物卡!H36="链枷","10",IF(人物卡!H36="矛","20",IF(人物卡!H36=人物卡!AU27,人物卡!BA27,0)))))))) -> 0 | D11: 射击1 | E11: =IF(人物卡!H40="步枪/霰弹枪","25",IF(人物卡!H40="冲锋枪","15",IF(人物卡!H40="弓","15",IF(人物卡!H40="喷射器","10",IF(人物卡!H40="机枪","10",IF(人物卡!H40="重武器","10",IF(人物卡!H40=人物卡!AU27,人物卡!BA27,0))))))) -> 0 | S11: ="意志×"&U11 -> 意志×0 | T11: =职业列表!J22 -> × | U11: =职业列表!K22 -> 0 | W11: =IF(U11>0,S11,"") | X11: =IF(Y11=0,IF(AB6=1,"或",IF(AB7+AB8=1,"+","")),"") | Y11: =IF(W11="",1,0) -> 1 | Z11: =M14*U11 -> 0 | AA11: =IF(Y12=1,"",X11) | AH11: =IF(U11=0,"",M14*U11) | AJ11: =IF(U11=0,"",M14*U11)
